<?xml version="1.0" ?>
<!-- =================================================================================== -->
<!-- |    This document was autogenerated by xacro from sawyer2_with_pisa_hand.urdf.xacro | -->
<!-- |    EDITING THIS FILE BY HAND IS NOT RECOMMENDED                                 | -->
<!-- =================================================================================== -->
<!-- =================================================================================== -->
<!-- |    This document was autogenerated by xacro from ./urdf.xacro                   | -->
<!-- |    EDITING THIS FILE BY HAND IS NOT RECOMMENDED                                 | -->
<!-- =================================================================================== -->
<robot name="sawyer" xmlns:xacro="http://www.ros.org/wiki/xacro">
  <material name="black">
    <color rgba="0 0 0 1"/>
  </material>
  <material name="darkgray">
    <color rgba="0.2 0.2 0.2 1"/>
  </material>
  <material name="darkred">
    <color rgba="0.5 0.1 0.1 1"/>
  </material>
  <material name="sawyer_red">
    <color rgba="0.5 0.1 0.1 1"/>
  </material>
  <material name="sawyer_gray">
    <color rgba="0.75294 0.75294 0.75294 1"/>
  </material>
  <link name="base">
    <inertial>
      <origin rpy="0 0 0" xyz="-0.1 0 0.07"/>
      <!--Increase mass from 5 Kg original to provide a stable base to carry the
          arm.-->
      <mass value=".0"/>
      <inertia ixx="0.05" ixy="0" ixz="0" iyy="0.06" iyz="0" izz="0.03"/>
    </inertial>
  </link>
  <link name="torso">
    <visual>
      <origin rpy="0 0 0" xyz="0 0 0"/>
      <geometry>
        <box size="0 0 0"/>
      </geometry>
      <material name="darkgray">
        <color rgba="0.2 0.2 0.2 1"/>
      </material>
    </visual>
    <inertial>
      <origin rpy="0 0 0" xyz="0 0 0"/>
      <mass value="0.0001"/>
      <inertia ixx="1e-08" ixy="0" ixz="0" iyy="1e-08" iyz="0" izz="1e-08"/>
    </inertial>
  </link>
  <link name="pedestal">
    <visual>
      <origin rpy="1.5708 0 -1.5708" xyz="0.26 0.345 -0.91488"/>
      <geometry>
        <mesh filename="meshes/sawyer_pv/pedestal.DAE"/>
      </geometry>
      <material name="darkgray"/>
    </visual>
    <collision>
      <origin rpy="0 0 0" xyz="0 0 -0.3"/>
      <geometry>
        <cylinder length="0.62" radius="0.18"/>
      </geometry>
    </collision>
    <inertial>
      <origin rpy="0 0 0" xyz="0 0 0"/>
      <mass value="60.864"/>
      <inertia ixx="5.0636" ixy="0.0010342" ixz="0.802" iyy="6.0869" iyz="0.0010531" izz="4.9619"/>
    </inertial>
  </link>
  <!--
  <link name="controller_box">
    <collision>
      <origin rpy="0 0 0" xyz="-0.325 0 -0.38"/>
      <geometry>
        <box size="0.22 0.4 0.53"/>
      </geometry>
    </collision>
  </link>
  <joint name="controller_box_fixed" type="fixed">
    <origin rpy="0 0 0" xyz="0 0 0"/>
    <parent link="base"/>
    <child link="controller_box"/>
  </joint>
  <link name="pedestal_feet">
    <collision>
      <origin rpy="0 0 0" xyz="-0.1225 0 -0.758"/>
      <geometry>
        <box size="0.77 0.7 0.31"/>
      </geometry>
    </collision>
  </link>
  <joint name="pedestal_feet_fixed" type="fixed">
    <origin rpy="0 0 0" xyz="0 0 0"/>
    <parent link="base"/>
    <child link="pedestal_feet"/>
  </joint>
  -->
  <joint name="torso_t0" type="fixed">
    <origin rpy="0 0 0" xyz="0 0 0"/>
    <parent link="base"/>
    <child link="torso"/>
  </joint>
  <joint name="pedestal_fixed" type="fixed">
    <origin rpy="0 0 0" xyz="0 0 0"/>
    <parent link="base"/>
    <child link="pedestal"/>
  </joint>
  <joint name="right_arm_mount" type="fixed">
    <origin rpy="0 0 0" xyz="0 0 0"/>
    <parent link="base"/>
    <child link="right_arm_base_link"/>
  </joint>
  <link name="right_arm_base_link">
    <inertial>
      <origin rpy="0 0 0" xyz="-0.0006241 -2.8025e-05 0.065404"/>
      <mass value="2.0687"/>
      <inertia ixx="0.0067599" ixy="-4.2024e-05" ixz="-6.1904e-07" iyy="0.0067877" iyz="1.5888e-05" izz="0.0074031"/>
    </inertial>
    <visual>
      <origin rpy="0 0 0" xyz="0 0 0"/>
      <geometry>
        <mesh filename="meshes/sawyer_pv/base.DAE"/>
      </geometry>
      <material name="sawyer_red"/>
    </visual>
    <collision>
      <origin rpy="0 0 0" xyz="0 0 0.12"/>
      <geometry>
        <cylinder length="0.24" radius="0.08"/>
      </geometry>
    </collision>
  </link>
  <link name="right_l0">
    <inertial>
      <origin rpy="0 0 0" xyz="0.024366 0.010969 0.14363"/>
      <mass value="5.3213"/>
      <inertia ixx="0.053314" ixy="0.0047093" ixz="0.011734" iyy="0.057902" iyz="0.0080179" izz="0.023659"/>
    </inertial>
    <visual>
      <origin rpy="0 0 0" xyz="0 0 0"/>
      <geometry>
        <mesh filename="meshes/sawyer_mp3/l0.DAE"/>
      </geometry>
      <material name="sawyer_red"/>
    </visual>
    <collision>
      <origin rpy="0 0 0" xyz="0.081 0 0.237"/>
      <geometry>
        <sphere radius="0.07"/>
      </geometry>
    </collision>
  </link>
  <joint name="right_j0" type="revolute">
    <origin rpy="0 0 0" xyz="0 0 0.08"/>
    <parent link="right_arm_base_link"/>
    <child link="right_l0"/>
    <axis xyz="0 0 1"/>
    <limit effort="80" lower="-3.0503" upper="3.0503" velocity="1.74"/>
  </joint>
  <link name="head">
    <inertial>
      <origin rpy="0 0 0" xyz="0.0053207 -2.6549e-05 0.1021"/>
      <mass value="1.5795"/>
      <inertia ixx="0.011833" ixy="-4.4669e-06" ixz="4.9425e-05" iyy="0.0082709" iyz="4.2124e-07" izz="0.0049661"/>
    </inertial>
    <visual>
      <origin rpy="0 0 0" xyz="0 0 0"/>
      <geometry>
        <mesh filename="meshes/sawyer_pv/head.STL"/>
      </geometry>
      <material name="sawyer_red"/>
    </visual>
    <collision>
      <origin rpy="0 0 0" xyz="0 0 0.08"/>
      <geometry>
        <sphere radius="0.18"/>
      </geometry>
    </collision>
  </link>
  <joint name="head_pan" type="revolute">
    <origin rpy="0 0 0" xyz="0 0 0.2965"/>
    <parent link="right_l0"/>
    <child link="head"/>
    <axis xyz="0 0 1"/>
    <limit effort="8" lower="-5.1477" upper="0.9559" velocity="1.8"/>
  </joint>
  <link name="right_torso_itb">
    <inertial>
      <origin rpy="0 0 0" xyz="0 0 0"/>
      <mass value="0.0001"/>
      <inertia ixx="1e-08" ixy="0" ixz="0" iyy="1e-08" iyz="0" izz="1e-08"/>
    </inertial>
  </link>
  <joint name="right_torso_itb" type="fixed">
    <origin rpy="0 -1.5708 0" xyz="-0.055 0 0.22"/>
    <parent link="right_l0"/>
    <child link="right_torso_itb"/>
    <axis xyz="0 0 1"/>
  </joint>
  <link name="right_l1">
    <inertial>
      <origin rpy="0 0 0" xyz="-0.0030849 -0.026811 0.092521"/>
      <mass value="4.505"/>
      <inertia ixx="0.022398" ixy="-0.00023986" ixz="-0.00029362" iyy="0.014613" iyz="-0.0060875" izz="0.017295"/>
    </inertial>
    <visual>
      <origin rpy="0 0 0" xyz="0 0 0"/>
      <geometry>
        <mesh filename="meshes/sawyer_mp3/l1.DAE"/>
      </geometry>
      <material name="sawyer_red"/>
    </visual>
    <collision>
      <origin rpy="0 0 0" xyz="0 0 0.1225"/>
      <geometry>
        <sphere radius="0.07"/>
      </geometry>
    </collision>
  </link>
  <joint name="right_j1" type="revolute">
    <origin rpy="-1.5708 1.5708 0" xyz="0.081 0.05 0.237"/>
    <parent link="right_l0"/>
    <child link="right_l1"/>
    <axis xyz="0 0 1"/>
    <limit effort="80" lower="-3.8183" upper="2.2824" velocity="1.328"/>
  </joint>
  <link name="right_l2">
    <inertial>
      <origin rpy="0 0 0" xyz="-0.00016232 -0.015346 0.13445"/>
      <mass value="1.7251"/>
      <inertia ixx="0.025176" ixy="4.3031e-06" ixz="1.4564e-05" iyy="0.024982" iyz="-0.0033928" izz="0.0033798"/>
    </inertial>
    <visual>
      <origin rpy="0 0 0" xyz="0 0 0"/>
      <geometry>
        <mesh filename="meshes/sawyer_pv/l2.DAE"/>
      </geometry>
      <material name="sawyer_red"/>
    </visual>
    <collision>
      <origin rpy="0 0 0" xyz="0 0 0.14"/>
      <geometry>
        <cylinder length="0.35" radius="0.06"/>
      </geometry>
    </collision>
  </link>
  <joint name="right_j2" type="revolute">
    <origin rpy="1.5708 0 0" xyz="0 -0.14 0.1425"/>
    <parent link="right_l1"/>
    <child link="right_l2"/>
    <axis xyz="0 0 1"/>
    <limit effort="40" lower="-3.0514" upper="3.0514" velocity="1.957"/>
  </joint>
  <link name="right_l3">
    <inertial>
      <origin rpy="0 0 0" xyz="-0.0046678 -0.028394 -0.083127"/>
      <mass value="2.4743"/>
      <inertia ixx="0.0099549" ixy="-1.7675e-05" ixz="0.00027521" iyy="0.0064248" iyz="0.0030853" izz="0.0067746"/>
    </inertial>
    <visual>
      <origin rpy="0 0 0" xyz="0 0 0"/>
      <geometry>
        <mesh filename="meshes/sawyer_pv/l3.DAE"/>
      </geometry>
      <material name="sawyer_red"/>
    </visual>
    <collision>
      <origin rpy="0 0 0" xyz="0 -0.01 -0.12"/>
      <geometry>
        <sphere radius="0.06"/>
      </geometry>
    </collision>
  </link>
  <joint name="right_j3" type="revolute">
    <origin rpy="-1.5708 0 0" xyz="0 -0.042 0.26"/>
    <parent link="right_l2"/>
    <child link="right_l3"/>
    <axis xyz="0 0 1"/>
    <limit effort="40" lower="-3.0514" upper="3.0514" velocity="1.957"/>
  </joint>
  <link name="right_l4">
    <inertial>
      <origin rpy="0 0 0" xyz="-0.0027794 0.0076558 0.13273"/>
      <mass value="1.0433"/>
      <inertia ixx="0.012913" ixy="2.573e-05" ixz="0.00017705" iyy="0.012939" iyz="0.0011152" izz="0.0012405"/>
    </inertial>
    <visual>
      <origin rpy="0 0 0" xyz="0 0 0"/>
      <geometry>
        <mesh filename="meshes/sawyer_pv/l4.DAE"/>
      </geometry>
      <material name="sawyer_red"/>
    </visual>
    <collision>
      <origin rpy="0 0 0" xyz="0 0 0.14"/>
      <geometry>
        <cylinder length="0.36" radius="0.045"/>
      </geometry>
    </collision>
  </link>
  <joint name="right_j4" type="revolute">
    <origin rpy="1.5708 0 0" xyz="0 -0.125 -0.1265"/>
    <parent link="right_l3"/>
    <child link="right_l4"/>
    <axis xyz="0 0 1"/>
    <limit effort="9" lower="-2.9842" upper="2.9842" velocity="3.485"/>
  </joint>
  <link name="right_arm_itb">
    <inertial>
      <origin rpy="0 0 0" xyz="0 0 0"/>
      <mass value="0.0001"/>
      <inertia ixx="1e-08" ixy="0" ixz="0" iyy="1e-08" iyz="0" izz="1e-08"/>
    </inertial>
  </link>
  <joint name="right_arm_itb" type="fixed">
    <origin rpy="0 -1.5708 0" xyz="-0.055 0 0.075"/>
    <parent link="right_l4"/>
    <child link="right_arm_itb"/>
    <axis xyz="0 0 1"/>
  </joint>
  <link name="right_l5">
    <inertial>
      <origin rpy="0 0 0" xyz="0.0062067 -0.024291 0.075564"/>
      <mass value="1.5343"/>
      <inertia ixx="0.0046072" ixy="0.00012002" ixz="5.3065e-05" iyy="0.0028725" iyz="-0.0011886" izz="0.003101"/>
    </inertial>
    <visual>
      <origin rpy="0 0 0" xyz="0 0 0"/>
      <geometry>
        <mesh filename="meshes/sawyer_pv/l5.STL"/>
      </geometry>
      <material name="sawyer_red"/>
    </visual>
    <collision>
      <origin rpy="0 0 0" xyz="0.01 0 0.09"/>
      <geometry>
        <sphere radius="0.06"/>
      </geometry>
    </collision>
  </link>
  <joint name="right_j5" type="revolute">
    <origin rpy="-1.5708 0 0" xyz="0 0.031 0.275"/>
    <parent link="right_l4"/>
    <child link="right_l5"/>
    <axis xyz="0 0 1"/>
    <limit effort="9" lower="-2.9842" upper="2.9842" velocity="3.485"/>
  </joint>
  <link name="right_hand_camera"/>
  <joint name="right_hand_camera" type="fixed">
    <origin rpy="0 1.5708 0" xyz="0.039552 -0.033 0.0695"/>
    <parent link="right_l5"/>
    <child link="right_hand_camera"/>
    <axis xyz="0 0 0"/>
  </joint>
  <link name="right_wrist"/>
  <joint name="right_wrist" type="fixed">
    <origin rpy="1.5708 0 0" xyz="0 0 0.10541"/>
    <parent link="right_l5"/>
    <child link="right_wrist"/>
    <axis xyz="0 0 0"/>
  </joint>
  <link name="right_l6">
    <inertial>
      <origin rpy="0 0 0" xyz="-8.0726e-06 0.0085838 -0.0049566"/>
      <mass value="0.3292"/>
      <inertia ixx="0.00031105" ixy="1.4771e-06" ixz="-3.7074e-07" iyy="0.00021549" iyz="-8.4533e-06" izz="0.00035976"/>
    </inertial>
    <visual>
      <origin rpy="0 0 0" xyz="0 0 0"/>
      <geometry>
        <mesh filename="meshes/sawyer_mp1/l6.STL"/>
      </geometry>
      <material name="sawyer_red"/>
    </visual>
    <collision>
      <origin rpy="0 0 0" xyz="0 0 -0.005"/>
      <geometry>
        <cylinder length="0.05" radius="0.065"/>
      </geometry>
    </collision>
  </link>
  <joint name="right_j6" type="revolute">
    <origin rpy="-1.5708 -0.17453 3.1416" xyz="0 -0.11 0.1053"/>
    <parent link="right_l5"/>
    <child link="right_l6"/>
    <axis xyz="0 0 1"/>
    <limit effort="9" lower="-4.7104" upper="4.7104" velocity="4.545"/>
  </joint>
  <link name="right_hand">
    <collision>
      <origin rpy="0 0 0" xyz="0 0 0"/>
      <geometry>
        <cylinder length="0" radius="0"/>
      </geometry>
    </collision>
    <inertial>
      <origin rpy="0 0 0" xyz="1e-08 1e-08 1e-08"/>
      <mass value="1e-08"/>
      <inertia ixx="1e-08" ixy="1e-08" ixz="1e-08" iyy="1e-08" iyz="1e-08" izz="1e-08"/>
    </inertial>
  </link>
  <joint name="right_hand" type="fixed">
    <origin rpy="0 0 1.5708" xyz="0 0 0.0245"/>
    <axis xyz="0 0 1"/>
    <parent link="right_l6"/>
    <child link="right_hand"/>
  </joint>
  <link name="screen">
    <visual>
      <origin rpy="0 0 0" xyz="0 0 0"/>
      <geometry>
        <box size="0.24 0.14 0.002"/>
      </geometry>
      <material name="darkgray"/>
    </visual>
    <collision>
      <origin rpy="0 0 0" xyz="0 0 0"/>
      <geometry>
        <sphere radius="0.001"/>
      </geometry>
    </collision>
    <inertial>
      <origin rpy="0 0 0" xyz="0 0 0"/>
      <mass value="0.0001"/>
      <inertia ixx="1e-08" ixy="0" ixz="0" iyy="1e-08" iyz="0" izz="1e-08"/>
    </inertial>
  </link>
  <joint name="display_joint" type="fixed">
    <origin rpy="1.5708 0 1.5708" xyz="0.03 0 0.105"/>
    <parent link="head"/>
    <child link="screen"/>
  </joint>
  <link name="head_camera"/>
  <joint name="head_camera" type="fixed">
    <origin rpy="-2.1293 0 -1.5708" xyz="0.022803 0 0.21657"/>
    <parent link="head"/>
    <child link="head_camera"/>
    <axis xyz="0 0 0"/>
  </joint>
  <material name="SoftHand/LightGrey">
    <color rgba="0.7 0.7 0.7 1.0"/>
  </material>
  <material name="SoftHand/DarkGrey">
    <color rgba="0.4 0.4 0.4 1.0"/>
  </material>
  <material name="SoftHand/Black">
    <color rgba="0.0 0.0 0.0 1.0"/>
  </material>
  <material name="SoftHand/DarkGolden">
    <color rgba="0.4 0.4 0.3 1.0"/>
  </material>
  <material name="SoftHand/Blue">
    <color rgba="0.0 0.0 0.8 0.9"/>
  </material>
  <material name="SoftHand/LightBlue">
    <color rgba="0.0 0.4 1.0 0.5"/>
  </material>
  <!-- <xacro:insert_block name="gazebo_friction_properties"/> -->
  <!-- <xacro:insert_block name="gazebo_other_properties"/> -->
  <!-- NOTE: inertia values are approximated using meshlab and only using the significant elements -->
  <!-- from http://answers.ros.org/question/11350/is-there-any-way-to-calculate-inertial-property-of-a-robot-to-simulate-it-in-gazebo/s
    One general rule of thumb I use for checking my inertia tensors is: If total mass of the rigid body is m, and the dimension of the corresponding body is d, then check to see if ixx, iyy, izz are near m*(d/2)^2.

    This is by no means correct, but a sanity check to make sure the moment of inertia are the right order of magnitudes, so the model behaves somewhat physically realistically.
    -->
  <!-- PACMAN VERION ALREADY INCLUDES THE COUPLER, CLAMP AND BASE -->
  <joint name="right_hand_soft_hand_kuka_coupler_joint" type="fixed">
    <origin rpy="0 0 0" xyz="0 0 0"/>
    <parent link="right_hand"/>
    <child link="soft_hand_kuka_coupler_bottom"/>
  </joint>
  <link name="soft_hand_kuka_coupler_bottom">
    <visual>
      <origin rpy="0 0 0" xyz="0 0 0.0115"/>
      <geometry>
        <!-- mesh filename="package://soft_hand_description/meshes/accesories/kuka_coupler.stl"/-->
        <cylinder length="0.023" radius="0.033"/>
      </geometry>
      <material name="SoftHand/Blue"/>
    </visual>
    <collision>
      <origin rpy="0 0 0" xyz="0 0 0.031"/>
      <geometry>
        <cylinder length="0.023" radius="0.033"/>
      </geometry>
    </collision>
  </link>
  <joint name="right_hand_soft_hand_kuka_coupler_base_joint" type="fixed">
    <origin rpy="0 0 0" xyz="0 0 0.023"/>
    <parent link="soft_hand_kuka_coupler_bottom"/>
    <child link="soft_hand_kuka_coupler"/>
  </joint>
  <link name="soft_hand_kuka_coupler"/>
  <joint name="soft_hand_kuka_coupler_soft_hand_clamp_joint" type="fixed">
    <origin rpy="0 0 0" xyz="0 0 0.01"/>
    <parent link="soft_hand_kuka_coupler"/>
    <child link="soft_hand_clamp"/>
  </joint>
  <link name="soft_hand_clamp">
    <visual>
      <origin rpy="0 0 0" xyz="0 0 0"/>
      <geometry>
        <mesh filename="package://soft_hand_description/meshes/accesories/clamp.stl"/>
      </geometry>
      <material name="SoftHand/Blue"/>
    </visual>
    <collision>
      <origin rpy="0 0 0" xyz="0 0 0"/>
      <geometry>
        <box size="0.066 0.0725 0.0256"/>
      </geometry>
    </collision>
  </link>
  <joint name="soft_hand_clamp_soft_hand_softhand_base_joint" type="fixed">
    <origin rpy="0 0 0" xyz="0 0 0.004"/>
    <parent link="soft_hand_clamp"/>
    <child link="soft_hand_softhand_base"/>
  </joint>
  <link name="soft_hand_softhand_base">
    <visual>
      <origin rpy="0 0 0" xyz="0 0 0"/>
      <geometry>
        <mesh filename="package://soft_hand_description/meshes/accesories/softhand_base_right.stl"/>
      </geometry>
      <material name="SoftHand/Blue"/>
    </visual>
    <collision>
      <origin rpy="0 0 0" xyz="0 0 0.031"/>
      <geometry>
        <box size="0.066 0.066 0.062"/>
      </geometry>
    </collision>
  </link>
  <!-- PALM -->
  <joint name="soft_hand_palm_joint" type="fixed">
    <origin rpy="0 0 0" xyz="0.002 0.00695 0.0535"/>
    <parent link="soft_hand_softhand_base"/>
    <child link="soft_hand_palm_link"/>
  </joint>
  <link name="soft_hand_palm_link">
    <inertial>
      <origin xyz="-0.004568758 -0.006808116 0.027653328"/>
      <mass value="2.28"/>
      <inertia ixx="1.6302" ixy="0.0228" ixz="0.0228" iyy="0.9462" iyz="0.0456" izz="1.1058"/>
    </inertial>
    <visual>
      <geometry>
        <mesh filename="package://soft_hand_description/meshes/palm_right.stl" scale=" .001 .001 .001"/>
      </geometry>
      <material name="SoftHand/DarkGrey"/>
    </visual>
    <collision>
      <geometry>
        <mesh filename="package://soft_hand_description/meshes/palm_right_collision.stl" scale=" .001 .001 .001"/>
      </geometry>
    </collision>
  </link>
  <!-- MOTOR JOINT -->
  <joint name="soft_hand_synergy_joint" type="revolute">
    <parent link="soft_hand_palm_link"/>
    <child link="soft_hand_invisible_wire_link"/>
    <axis xyz="0 0 1"/>
    <limit effort="100" lower="0.0" upper="1.0" velocity="100000"/>
    <dynamics damping="0.0" friction="0.0"/>
  </joint>
  <link name="soft_hand_invisible_wire_link">
    <inertial>
      <origin xyz="0 0 0"/>
      <mass value="0.1"/>
      <inertia ixx="0.001" ixy="0.0" ixz="0.0" iyy="0.001" iyz="0.0" izz="0.001"/>
    </inertial>
  </link>
  <!-- KNUCKLE -->
  <joint name="soft_hand_thumb_abd_joint" type="revolute">
    <origin rpy="0.0 -0.38397275793662144 1.5707963267948966" xyz="0.00566972 0.0296160 0.0553140"/>
    <parent link="soft_hand_palm_link"/>
    <child link="soft_hand_thumb_knuckle_link"/>
    <axis xyz="0 0 -1"/>
    <limit effort="100" lower="0.0" upper="1.57079632679" velocity="100"/>
    <dynamics damping="0.0" friction="0.0"/>
    <mimic joint="soft_hand_synergy_joint" multiplier="2.04203522483"/>
  </joint>
  <link name="soft_hand_thumb_knuckle_link">
    <inertial>
      <origin xyz="0.013608098 -0.000532174 -0.000216691"/>
      <mass value="0.09"/>
      <inertia ixx="0.00315" ixy="0.00027" ixz="-0.00054" iyy="0.009" iyz="0.00018" izz="0.009"/>
    </inertial>
    <visual>
      <geometry>
        <mesh filename="package://soft_hand_description/meshes/thumb_knuckle_right.stl" scale=" .001 .001 .001"/>
      </geometry>
      <material name="SoftHand/DarkGrey"/>
    </visual>
    <collision>
      <geometry>
        <mesh filename="package://soft_hand_description/meshes/thumb_knuckle_right_collision.stl" scale=" .001 .001 .001"/>
      </geometry>
    </collision>
  </link>
  <!-- PROXIMAL PHALANGE -->
  <joint name="soft_hand_thumb_inner_joint" type="revolute">
    <!-- <origin xyz="0.022500000 -0.003300000 0.0" rpy="0.42662757656587236 0.0 0.18131960430075023" /> -->
    <origin rpy="0.42662757656587236 0.0 0.0" xyz="0.022500000 -0.003300000 0.0"/>
    <parent link="soft_hand_thumb_knuckle_link"/>
    <child link="soft_hand_thumb_fake_link1"/>
    <axis xyz="0 -1 0"/>
    <limit effort="100" lower="0.0" upper="0.785398163397" velocity="100"/>
    <dynamics damping="0.0" friction="0.0"/>
    <mimic joint="soft_hand_synergy_joint" multiplier="1.02101761242"/>
  </joint>
  <link name="soft_hand_thumb_fake_link1">
    <inertial>
      <origin xyz="0 0 0"/>
      <mass value="0.1"/>
      <inertia ixx="0.001" ixy="0.0" ixz="0.0" iyy="0.001" iyz="0.0" izz="0.001"/>
    </inertial>
  </link>
  <joint name="soft_hand_thumb_inner_joint_mimic" type="revolute">
    <origin rpy="0 0 0" xyz="0.013 0 0"/>
    <parent link="soft_hand_thumb_fake_link1"/>
    <child link="soft_hand_thumb_proximal_link"/>
    <axis xyz="0 -1 0"/>
    <limit effort="100" lower="0.0" upper="0.785398163397" velocity="100"/>
    <dynamics damping="0.0" friction="0.0"/>
    <mimic joint="soft_hand_synergy_joint" multiplier="1.02101761242"/>
  </joint>
  <link name="soft_hand_thumb_proximal_link">
    <inertial>
      <origin xyz="0.005074337 -4.524e-06 -0.000262953"/>
      <mass value="0.05"/>
      <inertia ixx="0.00175" ixy="0.0" ixz="0.0001" iyy="0.00275" iyz="0.0" izz="0.00275"/>
    </inertial>
    <visual>
      <geometry>
        <mesh filename="package://soft_hand_description/meshes/phalanx.stl" scale=" .001 .001 .001"/>
      </geometry>
      <material name="SoftHand/DarkGrey"/>
    </visual>
    <collision>
      <geometry>
        <mesh filename="package://soft_hand_description/meshes/phalanx_collision.stl" scale=" .001 .001 .001"/>
      </geometry>
    </collision>
  </link>
  <!-- DISTAL PHALANGE -->
  <joint name="soft_hand_thumb_outer_joint" type="revolute">
    <origin rpy="0 0 0" xyz="0.009 0 0.0"/>
    <parent link="soft_hand_thumb_proximal_link"/>
    <child link="soft_hand_thumb_fake_link3"/>
    <axis xyz="0 -1 0"/>
    <limit effort="100" lower="0.0" upper="0.785398163397" velocity="100"/>
    <dynamics damping="0.0" friction="0.0"/>
    <mimic joint="soft_hand_synergy_joint" multiplier="0.785398163397"/>
  </joint>
  <link name="soft_hand_thumb_fake_link3">
    <inertial>
      <origin xyz="0 0 0"/>
      <mass value="0.1"/>
      <inertia ixx="0.001" ixy="0.0" ixz="0.0" iyy="0.001" iyz="0.0" izz="0.001"/>
    </inertial>
  </link>
  <joint name="soft_hand_thumb_outer_joint_mimic" type="revolute">
    <origin rpy="0 0 0" xyz="0.013 0 0"/>
    <parent link="soft_hand_thumb_fake_link3"/>
    <child link="soft_hand_thumb_distal_link"/>
    <axis xyz="0 -1 0"/>
    <limit effort="100" lower="0.0" upper="0.785398163397" velocity="100"/>
    <dynamics damping="0.0" friction="0.0"/>
    <mimic joint="soft_hand_synergy_joint" multiplier="0.785398163397"/>
  </joint>
  <link name="soft_hand_thumb_distal_link">
    <inertial>
      <origin xyz="0.009849094 5.6e-07 0.000820286"/>
      <mass value="0.1"/>
      <inertia ixx="0.0035" ixy="0.0" ixz="0.0002" iyy="0.008" iyz="0.0" izz="0.0076"/>
    </inertial>
    <visual>
      <geometry>
        <mesh filename="package://soft_hand_description/meshes/fingertip.stl" scale=" .001 .001 .001"/>
      </geometry>
      <material name="SoftHand/DarkGrey"/>
    </visual>
    <collision>
      <geometry>
        <mesh filename="package://soft_hand_description/meshes/fingertip_collision.stl" scale=" .001 .001 .001"/>
      </geometry>
    </collision>
  </link>
  <!-- KNUCKLE -->
  <joint name="soft_hand_index_abd_joint" type="revolute">
    <origin rpy="1.5707963267948966 -1.4835299330931884 1.5707963267948966" xyz="-0.0033 0.0195 0.0936994"/>
    <parent link="soft_hand_palm_link"/>
    <child link="soft_hand_index_knuckle_link"/>
    <axis xyz="0 0 1"/>
    <limit effort="100" lower="-0.523598775598" upper="0.523598775598" velocity="100"/>
    <dynamics damping="0.0" friction="0.0"/>
    <mimic joint="soft_hand_synergy_joint" multiplier="-0.2"/>
  </joint>
  <link name="soft_hand_index_knuckle_link">
    <inertial>
      <origin xyz="0.001285644 -9.58e-07 0.000425011"/>
      <mass value="0.09"/>
      <inertia ixx="0.00405" ixy="0.0" ixz="0.00045" iyy="0.0081" iyz="0.0" izz="0.0063"/>
    </inertial>
    <visual>
      <geometry>
        <mesh filename="package://soft_hand_description/meshes/knuckle.stl" scale=" .001 .001 .001"/>
      </geometry>
      <material name="SoftHand/DarkGrey"/>
    </visual>
    <collision>
      <geometry>
        <mesh filename="package://soft_hand_description/meshes/knuckle_collision.stl" scale=" .001 .001 .001"/>
      </geometry>
    </collision>
  </link>
  <!-- PROXIMAL PHALANGE -->
  <joint name="soft_hand_index_inner_joint" type="revolute">
    <origin rpy="0 0 0" xyz="0.009 0 0"/>
    <parent link="soft_hand_index_knuckle_link"/>
    <child link="soft_hand_index_fake_link1"/>
    <axis xyz="0 -1 0"/>
    <limit effort="100" lower="0.0" upper="0.785398163397" velocity="100"/>
    <dynamics damping="0.0" friction="0.0"/>
    <mimic joint="soft_hand_synergy_joint" multiplier="0.785398163397"/>
  </joint>
  <link name="soft_hand_index_fake_link1">
    <inertial>
      <origin xyz="0 0 0"/>
      <mass value="0.1"/>
      <inertia ixx="0.001" ixy="0.0" ixz="0.0" iyy="0.001" iyz="0.0" izz="0.001"/>
    </inertial>
  </link>
  <joint name="soft_hand_index_inner_joint_mimic" type="revolute">
    <origin rpy="0 0 0" xyz="0.013 0 0"/>
    <parent link="soft_hand_index_fake_link1"/>
    <child link="soft_hand_index_proximal_link"/>
    <axis xyz="0 -1 0"/>
    <limit effort="100" lower="0.0" upper="0.785398163397" velocity="100"/>
    <dynamics damping="0.0" friction="0.0"/>
    <mimic joint="soft_hand_synergy_joint" multiplier="0.785398163397"/>
  </joint>
  <link name="soft_hand_index_proximal_link">
    <inertial>
      <origin xyz="0.005074337 -4.524e-06 -0.000262953"/>
      <mass value="0.05"/>
      <inertia ixx="0.00175" ixy="0.0" ixz="0.0001" iyy="0.00275" iyz="0.0" izz="0.00275"/>
    </inertial>
    <visual>
      <geometry>
        <mesh filename="package://soft_hand_description/meshes/phalanx.stl" scale=" .001 .001 .001"/>
      </geometry>
      <material name="SoftHand/DarkGrey"/>
    </visual>
    <collision>
      <geometry>
        <mesh filename="package://soft_hand_description/meshes/phalanx_collision.stl" scale=" .001 .001 .001"/>
      </geometry>
    </collision>
  </link>
  <!-- MIDDLE PHALANGE -->
  <joint name="soft_hand_index_middle_joint" type="revolute">
    <origin rpy="0 0 0" xyz="0.009 0 0"/>
    <parent link="soft_hand_index_proximal_link"/>
    <child link="soft_hand_index_fake_link2"/>
    <axis xyz="0 -1 0"/>
    <limit effort="100" lower="0.0" upper="0.785398163397" velocity="100"/>
    <dynamics damping="0.0" friction="0.0"/>
    <mimic joint="soft_hand_synergy_joint" multiplier="0.785398163397"/>
  </joint>
  <link name="soft_hand_index_fake_link2">
    <inertial>
      <origin xyz="0 0 0"/>
      <mass value="0.1"/>
      <inertia ixx="0.001" ixy="0.0" ixz="0.0" iyy="0.001" iyz="0.0" izz="0.001"/>
    </inertial>
  </link>
  <joint name="soft_hand_index_middle_joint_mimic" type="revolute">
    <origin rpy="0 0 0" xyz="0.013 0 0"/>
    <parent link="soft_hand_index_fake_link2"/>
    <child link="soft_hand_index_middle_link"/>
    <axis xyz="0 -1 0"/>
    <limit effort="100" lower="0.0" upper="0.785398163397" velocity="100"/>
    <dynamics damping="0.0" friction="0.0"/>
    <mimic joint="soft_hand_synergy_joint" multiplier="0.785398163397"/>
  </joint>
  <link name="soft_hand_index_middle_link">
    <inertial>
      <origin xyz="0.005074337 -4.524e-06 -0.000262953"/>
      <mass value="0.05"/>
      <inertia ixx="0.00175" ixy="0.0" ixz="0.0001" iyy="0.00275" iyz="0.0" izz="0.00275"/>
    </inertial>
    <visual>
      <geometry>
        <mesh filename="package://soft_hand_description/meshes/phalanx.stl" scale=" .001 .001 .001"/>
      </geometry>
      <material name="SoftHand/DarkGrey"/>
    </visual>
    <collision>
      <geometry>
        <mesh filename="package://soft_hand_description/meshes/phalanx_collision.stl" scale=" .001 .001 .001"/>
      </geometry>
    </collision>
  </link>
  <!-- DISTAL PHALANGE -->
  <joint name="soft_hand_index_outer_joint" type="revolute">
    <origin rpy="0 0 0" xyz="0.009 0 0"/>
    <parent link="soft_hand_index_middle_link"/>
    <child link="soft_hand_index_fake_link3"/>
    <axis xyz="0 -1 0"/>
    <limit effort="100" lower="0.0" upper="0.785398163397" velocity="100"/>
    <dynamics damping="0.0" friction="0.0"/>
    <mimic joint="soft_hand_synergy_joint" multiplier="0.785398163397"/>
  </joint>
  <link name="soft_hand_index_fake_link3">
    <inertial>
      <origin xyz="0 0 0"/>
      <mass value="0.1"/>
      <inertia ixx="0.001" ixy="0.0" ixz="0.0" iyy="0.001" iyz="0.0" izz="0.001"/>
    </inertial>
  </link>
  <joint name="soft_hand_index_outer_joint_mimic" type="revolute">
    <origin rpy="0 0 0" xyz="0.013 0 0"/>
    <parent link="soft_hand_index_fake_link3"/>
    <child link="soft_hand_index_distal_link"/>
    <axis xyz="0 -1 0"/>
    <limit effort="100" lower="0.0" upper="0.785398163397" velocity="100"/>
    <dynamics damping="0.0" friction="0.0"/>
    <mimic joint="soft_hand_synergy_joint" multiplier="0.785398163397"/>
  </joint>
  <link name="soft_hand_index_distal_link">
    <inertial>
      <origin xyz="0.009849094 5.6e-07 0.000820286"/>
      <mass value="0.1"/>
      <inertia ixx="0.0035" ixy="0.0" ixz="0.0002" iyy="0.008" iyz="0.0" izz="0.0076"/>
    </inertial>
    <visual>
      <geometry>
        <mesh filename="package://soft_hand_description/meshes/fingertip.stl" scale=" .001 .001 .001"/>
      </geometry>
      <material name="SoftHand/DarkGrey"/>
    </visual>
    <collision>
      <geometry>
        <mesh filename="package://soft_hand_description/meshes/fingertip_collision.stl" scale=" .001 .001 .001"/>
      </geometry>
    </collision>
  </link>
  <!-- KNUCKLE -->
  <joint name="soft_hand_middle_abd_joint" type="revolute">
    <origin rpy="3.141592 -1.5707963267948966 0.0" xyz="-0.003300000 0.0 0.100699"/>
    <parent link="soft_hand_palm_link"/>
    <child link="soft_hand_middle_knuckle_link"/>
    <axis xyz="0 0 1"/>
    <limit effort="100" lower="-0.523598775598" upper="0.523598775598" velocity="100"/>
    <dynamics damping="0.0" friction="0.0"/>
    <mimic joint="soft_hand_synergy_joint" multiplier="0.0"/>
  </joint>
  <link name="soft_hand_middle_knuckle_link">
    <inertial>
      <origin xyz="0.001285644 -9.58e-07 0.000425011"/>
      <mass value="0.09"/>
      <inertia ixx="0.00405" ixy="0.0" ixz="0.00045" iyy="0.0081" iyz="0.0" izz="0.0063"/>
    </inertial>
    <visual>
      <geometry>
        <mesh filename="package://soft_hand_description/meshes/knuckle.stl" scale=" .001 .001 .001"/>
      </geometry>
      <material name="SoftHand/DarkGrey"/>
    </visual>
    <collision>
      <geometry>
        <mesh filename="package://soft_hand_description/meshes/knuckle_collision.stl" scale=" .001 .001 .001"/>
      </geometry>
    </collision>
  </link>
  <!-- PROXIMAL PHALANGE -->
  <joint name="soft_hand_middle_inner_joint" type="revolute">
    <origin rpy="0 0 0" xyz="0.009 0 0"/>
    <parent link="soft_hand_middle_knuckle_link"/>
    <child link="soft_hand_middle_fake_link1"/>
    <axis xyz="0 -1 0"/>
    <limit effort="100" lower="0.0" upper="0.785398163397" velocity="100"/>
    <dynamics damping="0.0" friction="0.0"/>
    <mimic joint="soft_hand_synergy_joint" multiplier="0.785398163397"/>
  </joint>
  <link name="soft_hand_middle_fake_link1">
    <inertial>
      <origin xyz="0 0 0"/>
      <mass value="0.1"/>
      <inertia ixx="0.001" ixy="0.0" ixz="0.0" iyy="0.001" iyz="0.0" izz="0.001"/>
    </inertial>
  </link>
  <joint name="soft_hand_middle_inner_joint_mimic" type="revolute">
    <origin rpy="0 0 0" xyz="0.013 0 0"/>
    <parent link="soft_hand_middle_fake_link1"/>
    <child link="soft_hand_middle_proximal_link"/>
    <axis xyz="0 -1 0"/>
    <limit effort="100" lower="0.0" upper="0.785398163397" velocity="100"/>
    <dynamics damping="0.0" friction="0.0"/>
    <mimic joint="soft_hand_synergy_joint" multiplier="0.785398163397"/>
  </joint>
  <link name="soft_hand_middle_proximal_link">
    <inertial>
      <origin xyz="0.005074337 -4.524e-06 -0.000262953"/>
      <mass value="0.05"/>
      <inertia ixx="0.00175" ixy="0.0" ixz="0.0001" iyy="0.00275" iyz="0.0" izz="0.00275"/>
    </inertial>
    <visual>
      <geometry>
        <mesh filename="package://soft_hand_description/meshes/phalanx.stl" scale=" .001 .001 .001"/>
      </geometry>
      <material name="SoftHand/DarkGrey"/>
    </visual>
    <collision>
      <geometry>
        <mesh filename="package://soft_hand_description/meshes/phalanx_collision.stl" scale=" .001 .001 .001"/>
      </geometry>
    </collision>
  </link>
  <!-- MIDDLE PHALANGE -->
  <joint name="soft_hand_middle_middle_joint" type="revolute">
    <origin rpy="0 0 0" xyz="0.009 0 0"/>
    <parent link="soft_hand_middle_proximal_link"/>
    <child link="soft_hand_middle_fake_link2"/>
    <axis xyz="0 -1 0"/>
    <limit effort="100" lower="0.0" upper="0.785398163397" velocity="100"/>
    <dynamics damping="0.0" friction="0.0"/>
    <mimic joint="soft_hand_synergy_joint" multiplier="0.785398163397"/>
  </joint>
  <link name="soft_hand_middle_fake_link2">
    <inertial>
      <origin xyz="0 0 0"/>
      <mass value="0.1"/>
      <inertia ixx="0.001" ixy="0.0" ixz="0.0" iyy="0.001" iyz="0.0" izz="0.001"/>
    </inertial>
  </link>
  <joint name="soft_hand_middle_middle_joint_mimic" type="revolute">
    <origin rpy="0 0 0" xyz="0.013 0 0"/>
    <parent link="soft_hand_middle_fake_link2"/>
    <child link="soft_hand_middle_middle_link"/>
    <axis xyz="0 -1 0"/>
    <limit effort="100" lower="0.0" upper="0.785398163397" velocity="100"/>
    <dynamics damping="0.0" friction="0.0"/>
    <mimic joint="soft_hand_synergy_joint" multiplier="0.785398163397"/>
  </joint>
  <link name="soft_hand_middle_middle_link">
    <inertial>
      <origin xyz="0.005074337 -4.524e-06 -0.000262953"/>
      <mass value="0.05"/>
      <inertia ixx="0.00175" ixy="0.0" ixz="0.0001" iyy="0.00275" iyz="0.0" izz="0.00275"/>
    </inertial>
    <visual>
      <geometry>
        <mesh filename="package://soft_hand_description/meshes/phalanx.stl" scale=" .001 .001 .001"/>
      </geometry>
      <material name="SoftHand/DarkGrey"/>
    </visual>
    <collision>
      <geometry>
        <mesh filename="package://soft_hand_description/meshes/phalanx_collision.stl" scale=" .001 .001 .001"/>
      </geometry>
    </collision>
  </link>
  <!-- DISTAL PHALANGE -->
  <joint name="soft_hand_middle_outer_joint" type="revolute">
    <origin rpy="0 0 0" xyz="0.009 0 0"/>
    <parent link="soft_hand_middle_middle_link"/>
    <child link="soft_hand_middle_fake_link3"/>
    <axis xyz="0 -1 0"/>
    <limit effort="100" lower="0.0" upper="0.785398163397" velocity="100"/>
    <dynamics damping="0.0" friction="0.0"/>
    <mimic joint="soft_hand_synergy_joint" multiplier="0.785398163397"/>
  </joint>
  <link name="soft_hand_middle_fake_link3">
    <inertial>
      <origin xyz="0 0 0"/>
      <mass value="0.1"/>
      <inertia ixx="0.001" ixy="0.0" ixz="0.0" iyy="0.001" iyz="0.0" izz="0.001"/>
    </inertial>
  </link>
  <joint name="soft_hand_middle_outer_joint_mimic" type="revolute">
    <origin rpy="0 0 0" xyz="0.013 0 0"/>
    <parent link="soft_hand_middle_fake_link3"/>
    <child link="soft_hand_middle_distal_link"/>
    <axis xyz="0 -1 0"/>
    <limit effort="100" lower="0.0" upper="0.785398163397" velocity="100"/>
    <dynamics damping="0.0" friction="0.0"/>
    <mimic joint="soft_hand_synergy_joint" multiplier="0.785398163397"/>
  </joint>
  <link name="soft_hand_middle_distal_link">
    <inertial>
      <origin xyz="0.009849094 5.6e-07 0.000820286"/>
      <mass value="0.1"/>
      <inertia ixx="0.0035" ixy="0.0" ixz="0.0002" iyy="0.008" iyz="0.0" izz="0.0076"/>
    </inertial>
    <visual>
      <geometry>
        <mesh filename="package://soft_hand_description/meshes/fingertip.stl" scale=" .001 .001 .001"/>
      </geometry>
      <material name="SoftHand/DarkGrey"/>
    </visual>
    <collision>
      <geometry>
        <mesh filename="package://soft_hand_description/meshes/fingertip_collision.stl" scale=" .001 .001 .001"/>
      </geometry>
    </collision>
  </link>
  <!-- KNUCKLE -->
  <joint name="soft_hand_ring_abd_joint" type="revolute">
    <origin rpy="-1.5707963267948966 -1.5184364298870514 -1.5707963267948966 " xyz="-0.0033 -0.0195 0.0936994"/>
    <parent link="soft_hand_palm_link"/>
    <child link="soft_hand_ring_knuckle_link"/>
    <axis xyz="0 0 1"/>
    <limit effort="100" lower="-0.523598775598" upper="0.523598775598" velocity="100"/>
    <dynamics damping="0.0" friction="0.0"/>
    <mimic joint="soft_hand_synergy_joint" multiplier="0.2"/>
  </joint>
  <link name="soft_hand_ring_knuckle_link">
    <inertial>
      <origin xyz="0.001285644 -9.58e-07 0.000425011"/>
      <mass value="0.09"/>
      <inertia ixx="0.00405" ixy="0.0" ixz="0.00045" iyy="0.0081" iyz="0.0" izz="0.0063"/>
    </inertial>
    <visual>
      <geometry>
        <mesh filename="package://soft_hand_description/meshes/knuckle.stl" scale=" .001 .001 .001"/>
      </geometry>
      <material name="SoftHand/DarkGrey"/>
    </visual>
    <collision>
      <geometry>
        <mesh filename="package://soft_hand_description/meshes/knuckle_collision.stl" scale=" .001 .001 .001"/>
      </geometry>
    </collision>
  </link>
  <!-- PROXIMAL PHALANGE -->
  <joint name="soft_hand_ring_inner_joint" type="revolute">
    <origin rpy="0 0 0" xyz="0.009 0 0"/>
    <parent link="soft_hand_ring_knuckle_link"/>
    <child link="soft_hand_ring_fake_link1"/>
    <axis xyz="0 -1 0"/>
    <limit effort="100" lower="0.0" upper="0.785398163397" velocity="100"/>
    <dynamics damping="0.0" friction="0.0"/>
    <mimic joint="soft_hand_synergy_joint" multiplier="0.785398163397"/>
  </joint>
  <link name="soft_hand_ring_fake_link1">
    <inertial>
      <origin xyz="0 0 0"/>
      <mass value="0.1"/>
      <inertia ixx="0.001" ixy="0.0" ixz="0.0" iyy="0.001" iyz="0.0" izz="0.001"/>
    </inertial>
  </link>
  <joint name="soft_hand_ring_inner_joint_mimic" type="revolute">
    <origin rpy="0 0 0" xyz="0.013 0 0"/>
    <parent link="soft_hand_ring_fake_link1"/>
    <child link="soft_hand_ring_proximal_link"/>
    <axis xyz="0 -1 0"/>
    <limit effort="100" lower="0.0" upper="0.785398163397" velocity="100"/>
    <dynamics damping="0.0" friction="0.0"/>
    <mimic joint="soft_hand_synergy_joint" multiplier="0.785398163397"/>
  </joint>
  <link name="soft_hand_ring_proximal_link">
    <inertial>
      <origin xyz="0.005074337 -4.524e-06 -0.000262953"/>
      <mass value="0.05"/>
      <inertia ixx="0.00175" ixy="0.0" ixz="0.0001" iyy="0.00275" iyz="0.0" izz="0.00275"/>
    </inertial>
    <visual>
      <geometry>
        <mesh filename="package://soft_hand_description/meshes/phalanx.stl" scale=" .001 .001 .001"/>
      </geometry>
      <material name="SoftHand/DarkGrey"/>
    </visual>
    <collision>
      <geometry>
        <mesh filename="package://soft_hand_description/meshes/phalanx_collision.stl" scale=" .001 .001 .001"/>
      </geometry>
    </collision>
  </link>
  <!-- MIDDLE PHALANGE -->
  <joint name="soft_hand_ring_middle_joint" type="revolute">
    <origin rpy="0 0 0" xyz="0.009 0 0"/>
    <parent link="soft_hand_ring_proximal_link"/>
    <child link="soft_hand_ring_fake_link2"/>
    <axis xyz="0 -1 0"/>
    <limit effort="100" lower="0.0" upper="0.785398163397" velocity="100"/>
    <dynamics damping="0.0" friction="0.0"/>
    <mimic joint="soft_hand_synergy_joint" multiplier="0.785398163397"/>
  </joint>
  <link name="soft_hand_ring_fake_link2">
    <inertial>
      <origin xyz="0 0 0"/>
      <mass value="0.1"/>
      <inertia ixx="0.001" ixy="0.0" ixz="0.0" iyy="0.001" iyz="0.0" izz="0.001"/>
    </inertial>
  </link>
  <joint name="soft_hand_ring_middle_joint_mimic" type="revolute">
    <origin rpy="0 0 0" xyz="0.013 0 0"/>
    <parent link="soft_hand_ring_fake_link2"/>
    <child link="soft_hand_ring_middle_link"/>
    <axis xyz="0 -1 0"/>
    <limit effort="100" lower="0.0" upper="0.785398163397" velocity="100"/>
    <dynamics damping="0.0" friction="0.0"/>
    <mimic joint="soft_hand_synergy_joint" multiplier="0.785398163397"/>
  </joint>
  <link name="soft_hand_ring_middle_link">
    <inertial>
      <origin xyz="0.005074337 -4.524e-06 -0.000262953"/>
      <mass value="0.05"/>
      <inertia ixx="0.00175" ixy="0.0" ixz="0.0001" iyy="0.00275" iyz="0.0" izz="0.00275"/>
    </inertial>
    <visual>
      <geometry>
        <mesh filename="package://soft_hand_description/meshes/phalanx.stl" scale=" .001 .001 .001"/>
      </geometry>
      <material name="SoftHand/DarkGrey"/>
    </visual>
    <collision>
      <geometry>
        <mesh filename="package://soft_hand_description/meshes/phalanx_collision.stl" scale=" .001 .001 .001"/>
      </geometry>
    </collision>
  </link>
  <!-- DISTAL PHALANGE -->
  <joint name="soft_hand_ring_outer_joint" type="revolute">
    <origin rpy="0 0 0" xyz="0.009 0 0"/>
    <parent link="soft_hand_ring_middle_link"/>
    <child link="soft_hand_ring_fake_link3"/>
    <axis xyz="0 -1 0"/>
    <limit effort="100" lower="0.0" upper="0.785398163397" velocity="100"/>
    <dynamics damping="0.0" friction="0.0"/>
    <mimic joint="soft_hand_synergy_joint" multiplier="0.785398163397"/>
  </joint>
  <link name="soft_hand_ring_fake_link3">
    <inertial>
      <origin xyz="0 0 0"/>
      <mass value="0.1"/>
      <inertia ixx="0.001" ixy="0.0" ixz="0.0" iyy="0.001" iyz="0.0" izz="0.001"/>
    </inertial>
  </link>
  <joint name="soft_hand_ring_outer_joint_mimic" type="revolute">
    <origin rpy="0 0 0" xyz="0.013 0 0"/>
    <parent link="soft_hand_ring_fake_link3"/>
    <child link="soft_hand_ring_distal_link"/>
    <axis xyz="0 -1 0"/>
    <limit effort="100" lower="0.0" upper="0.785398163397" velocity="100"/>
    <dynamics damping="0.0" friction="0.0"/>
    <mimic joint="soft_hand_synergy_joint" multiplier="0.785398163397"/>
  </joint>
  <link name="soft_hand_ring_distal_link">
    <inertial>
      <origin xyz="0.009849094 5.6e-07 0.000820286"/>
      <mass value="0.1"/>
      <inertia ixx="0.0035" ixy="0.0" ixz="0.0002" iyy="0.008" iyz="0.0" izz="0.0076"/>
    </inertial>
    <visual>
      <geometry>
        <mesh filename="package://soft_hand_description/meshes/fingertip.stl" scale=" .001 .001 .001"/>
      </geometry>
      <material name="SoftHand/DarkGrey"/>
    </visual>
    <collision>
      <geometry>
        <mesh filename="package://soft_hand_description/meshes/fingertip_collision.stl" scale=" .001 .001 .001"/>
      </geometry>
    </collision>
  </link>
  <!-- KNUCKLE -->
  <joint name="soft_hand_little_abd_joint" type="revolute">
    <origin rpy="-1.5707963267948966 -1.4835299330931884 -1.5707963267948966" xyz="-0.0033 -0.039 0.0836994"/>
    <parent link="soft_hand_palm_link"/>
    <child link="soft_hand_little_knuckle_link"/>
    <axis xyz="0 0 1"/>
    <limit effort="100" lower="-0.523598775598" upper="0.523598775598" velocity="100"/>
    <dynamics damping="0.0" friction="0.0"/>
    <mimic joint="soft_hand_synergy_joint" multiplier="0.4"/>
  </joint>
  <link name="soft_hand_little_knuckle_link">
    <inertial>
      <origin xyz="0.001285644 -9.58e-07 0.000425011"/>
      <mass value="0.09"/>
      <inertia ixx="0.00405" ixy="0.0" ixz="0.00045" iyy="0.0081" iyz="0.0" izz="0.0063"/>
    </inertial>
    <visual>
      <geometry>
        <mesh filename="package://soft_hand_description/meshes/knuckle.stl" scale=" .001 .001 .001"/>
      </geometry>
      <material name="SoftHand/DarkGrey"/>
    </visual>
    <collision>
      <geometry>
        <mesh filename="package://soft_hand_description/meshes/knuckle_collision.stl" scale=" .001 .001 .001"/>
      </geometry>
    </collision>
  </link>
  <!-- PROXIMAL PHALANGE -->
  <joint name="soft_hand_little_inner_joint" type="revolute">
    <origin rpy="0 0 0" xyz="0.009 0 0"/>
    <parent link="soft_hand_little_knuckle_link"/>
    <child link="soft_hand_little_fake_link1"/>
    <axis xyz="0 -1 0"/>
    <limit effort="100" lower="0.0" upper="0.785398163397" velocity="100"/>
    <dynamics damping="0.0" friction="0.0"/>
    <mimic joint="soft_hand_synergy_joint" multiplier="0.785398163397"/>
  </joint>
  <link name="soft_hand_little_fake_link1">
    <inertial>
      <origin xyz="0 0 0"/>
      <mass value="0.1"/>
      <inertia ixx="0.001" ixy="0.0" ixz="0.0" iyy="0.001" iyz="0.0" izz="0.001"/>
    </inertial>
  </link>
  <joint name="soft_hand_little_inner_joint_mimic" type="revolute">
    <origin rpy="0 0 0" xyz="0.013 0 0"/>
    <parent link="soft_hand_little_fake_link1"/>
    <child link="soft_hand_little_proximal_link"/>
    <axis xyz="0 -1 0"/>
    <limit effort="100" lower="0.0" upper="0.785398163397" velocity="100"/>
    <dynamics damping="0.0" friction="0.0"/>
    <mimic joint="soft_hand_synergy_joint" multiplier="0.785398163397"/>
  </joint>
  <link name="soft_hand_little_proximal_link">
    <inertial>
      <origin xyz="0.005074337 -4.524e-06 -0.000262953"/>
      <mass value="0.05"/>
      <inertia ixx="0.00175" ixy="0.0" ixz="0.0001" iyy="0.00275" iyz="0.0" izz="0.00275"/>
    </inertial>
    <visual>
      <geometry>
        <mesh filename="package://soft_hand_description/meshes/phalanx.stl" scale=" .001 .001 .001"/>
      </geometry>
      <material name="SoftHand/DarkGrey"/>
    </visual>
    <collision>
      <geometry>
        <mesh filename="package://soft_hand_description/meshes/phalanx_collision.stl" scale=" .001 .001 .001"/>
      </geometry>
    </collision>
  </link>
  <!-- MIDDLE PHALANGE -->
  <joint name="soft_hand_little_middle_joint" type="revolute">
    <origin rpy="0 0 0" xyz="0.009 0 0"/>
    <parent link="soft_hand_little_proximal_link"/>
    <child link="soft_hand_little_fake_link2"/>
    <axis xyz="0 -1 0"/>
    <limit effort="100" lower="0.0" upper="0.785398163397" velocity="100"/>
    <dynamics damping="0.0" friction="0.0"/>
    <mimic joint="soft_hand_synergy_joint" multiplier="0.785398163397"/>
  </joint>
  <link name="soft_hand_little_fake_link2">
    <inertial>
      <origin xyz="0 0 0"/>
      <mass value="0.1"/>
      <inertia ixx="0.001" ixy="0.0" ixz="0.0" iyy="0.001" iyz="0.0" izz="0.001"/>
    </inertial>
  </link>
  <joint name="soft_hand_little_middle_joint_mimic" type="revolute">
    <origin rpy="0 0 0" xyz="0.013 0 0"/>
    <parent link="soft_hand_little_fake_link2"/>
    <child link="soft_hand_little_middle_link"/>
    <axis xyz="0 -1 0"/>
    <limit effort="100" lower="0.0" upper="0.785398163397" velocity="100"/>
    <dynamics damping="0.0" friction="0.0"/>
    <mimic joint="soft_hand_synergy_joint" multiplier="0.785398163397"/>
  </joint>
  <link name="soft_hand_little_middle_link">
    <inertial>
      <origin xyz="0.005074337 -4.524e-06 -0.000262953"/>
      <mass value="0.05"/>
      <inertia ixx="0.00175" ixy="0.0" ixz="0.0001" iyy="0.00275" iyz="0.0" izz="0.00275"/>
    </inertial>
    <visual>
      <geometry>
        <mesh filename="package://soft_hand_description/meshes/phalanx.stl" scale=" .001 .001 .001"/>
      </geometry>
      <material name="SoftHand/DarkGrey"/>
    </visual>
    <collision>
      <geometry>
        <mesh filename="package://soft_hand_description/meshes/phalanx_collision.stl" scale=" .001 .001 .001"/>
      </geometry>
    </collision>
  </link>
  <!-- DISTAL PHALANGE -->
  <joint name="soft_hand_little_outer_joint" type="revolute">
    <origin rpy="0 0 0" xyz="0.009 0 0"/>
    <parent link="soft_hand_little_middle_link"/>
    <child link="soft_hand_little_fake_link3"/>
    <axis xyz="0 -1 0"/>
    <limit effort="100" lower="0.0" upper="0.785398163397" velocity="100"/>
    <dynamics damping="0.0" friction="0.0"/>
    <mimic joint="soft_hand_synergy_joint" multiplier="0.785398163397"/>
  </joint>
  <link name="soft_hand_little_fake_link3">
    <inertial>
      <origin xyz="0 0 0"/>
      <mass value="0.1"/>
      <inertia ixx="0.001" ixy="0.0" ixz="0.0" iyy="0.001" iyz="0.0" izz="0.001"/>
    </inertial>
  </link>
  <joint name="soft_hand_little_outer_joint_mimic" type="revolute">
    <origin rpy="0 0 0" xyz="0.013 0 0"/>
    <parent link="soft_hand_little_fake_link3"/>
    <child link="soft_hand_little_distal_link"/>
    <axis xyz="0 -1 0"/>
    <limit effort="100" lower="0.0" upper="0.785398163397" velocity="100"/>
    <dynamics damping="0.0" friction="0.0"/>
    <mimic joint="soft_hand_synergy_joint" multiplier="0.785398163397"/>
  </joint>
  <link name="soft_hand_little_distal_link">
    <inertial>
      <origin xyz="0.009849094 5.6e-07 0.000820286"/>
      <mass value="0.1"/>
      <inertia ixx="0.0035" ixy="0.0" ixz="0.0002" iyy="0.008" iyz="0.0" izz="0.0076"/>
    </inertial>
    <visual>
      <geometry>
        <mesh filename="package://soft_hand_description/meshes/fingertip.stl" scale=" .001 .001 .001"/>
      </geometry>
      <material name="SoftHand/DarkGrey"/>
    </visual>
    <collision>
      <geometry>
        <mesh filename="package://soft_hand_description/meshes/fingertip_collision.stl" scale=" .001 .001 .001"/>
      </geometry>
    </collision>
  </link>
  <!--
  <transmission name="soft_hand_thumb_abd_trans">
    <robotNamespace>soft_hand</robotNamespace>
    <type>transmission_interface/SimpleTransmission</type>
    <joint name="soft_hand_thumb_abd_joint">
      <hardwareInterface>EffortJointInterface</hardwareInterface>
    </joint>
    <actuator name="soft_hand_thumb_abd_motor">
      <mechanicalReduction>1.0</mechanicalReduction>
    </actuator>
  </transmission>
  <transmission name="soft_hand_thumb_inner_trans">
    <robotNamespace>soft_hand</robotNamespace>
    <type>transmission_interface/SimpleTransmission</type>
    <joint name="soft_hand_thumb_inner_joint">
      <hardwareInterface>EffortJointInterface</hardwareInterface>
    </joint>
    <actuator name="soft_hand_thumb_inner_motor">
      <mechanicalReduction>1.0</mechanicalReduction>
    </actuator>
  </transmission>
  <transmission name="soft_hand_thumb_inner_mimic_trans">
    <robotNamespace>soft_hand</robotNamespace>
    <type>transmission_interface/SimpleTransmission</type>
    <joint name="soft_hand_thumb_inner_joint_mimic">
      <hardwareInterface>EffortJointInterface</hardwareInterface>
    </joint>
    <actuator name="soft_hand_thumb_inner_motor">
      <mechanicalReduction>1.0</mechanicalReduction>
    </actuator>
  </transmission>
  <transmission name="soft_hand_thumb_outer_trans">
    <robotNamespace>soft_hand</robotNamespace>
    <type>transmission_interface/SimpleTransmission</type>
    <joint name="soft_hand_thumb_outer_joint">
      <hardwareInterface>EffortJointInterface</hardwareInterface>
    </joint>
    <actuator name="soft_hand_thumb_outer_motor">
      <mechanicalReduction>1.0</mechanicalReduction>
    </actuator>
  </transmission>
  <transmission name="soft_hand_thumb_outer_mimic_trans">
    <robotNamespace>soft_hand</robotNamespace>
    <type>transmission_interface/SimpleTransmission</type>
    <joint name="soft_hand_thumb_outer_joint_mimic">
      <hardwareInterface>EffortJointInterface</hardwareInterface>
    </joint>
    <actuator name="soft_hand_thumb_outer_motor">
      <mechanicalReduction>1.0</mechanicalReduction>
    </actuator>
  </transmission>
  <transmission name="soft_hand_index_abd_trans">
    <robotNamespace>soft_hand</robotNamespace>
    <type>transmission_interface/SimpleTransmission</type>
    <joint name="soft_hand_index_abd_joint">
      <hardwareInterface>EffortJointInterface</hardwareInterface>
    </joint>
    <actuator name="soft_hand_index_abd_motor">
      <mechanicalReduction>1.0</mechanicalReduction>
    </actuator>
  </transmission>
  <transmission name="soft_hand_index_inner_trans">
    <robotNamespace>soft_hand</robotNamespace>
    <type>transmission_interface/SimpleTransmission</type>
    <joint name="soft_hand_index_inner_joint">
      <hardwareInterface>EffortJointInterface</hardwareInterface>
    </joint>
    <actuator name="soft_hand_index_inner_motor">
      <mechanicalReduction>1.0</mechanicalReduction>
    </actuator>
  </transmission>
  <transmission name="soft_hand_index_inner_mimic_trans">
    <robotNamespace>soft_hand</robotNamespace>
    <type>transmission_interface/SimpleTransmission</type>
    <joint name="soft_hand_index_inner_joint_mimic">
      <hardwareInterface>EffortJointInterface</hardwareInterface>
    </joint>
    <actuator name="soft_hand_index_inner_motor">
      <mechanicalReduction>1.0</mechanicalReduction>
    </actuator>
  </transmission>
  <transmission name="soft_hand_index_middle_trans">
    <robotNamespace>soft_hand</robotNamespace>
    <type>transmission_interface/SimpleTransmission</type>
    <joint name="soft_hand_index_middle_joint">
      <hardwareInterface>EffortJointInterface</hardwareInterface>
    </joint>
    <actuator name="soft_hand_index_middle_motor">
      <mechanicalReduction>1.0</mechanicalReduction>
    </actuator>
  </transmission>
  <transmission name="soft_hand_index_middle_mimic_trans">
    <robotNamespace>soft_hand</robotNamespace>
    <type>transmission_interface/SimpleTransmission</type>
    <joint name="soft_hand_index_middle_joint_mimic">
      <hardwareInterface>EffortJointInterface</hardwareInterface>
    </joint>
    <actuator name="soft_hand_index_middle_motor">
      <mechanicalReduction>1.0</mechanicalReduction>
    </actuator>
  </transmission>
  <transmission name="soft_hand_index_outer_trans">
    <robotNamespace>soft_hand</robotNamespace>
    <type>transmission_interface/SimpleTransmission</type>
    <joint name="soft_hand_index_outer_joint">
      <hardwareInterface>EffortJointInterface</hardwareInterface>
    </joint>
    <actuator name="soft_hand_index_outer_motor">
      <mechanicalReduction>1.0</mechanicalReduction>
    </actuator>
  </transmission>
  <transmission name="soft_hand_index_outer_mimic_trans">
    <robotNamespace>soft_hand</robotNamespace>
    <type>transmission_interface/SimpleTransmission</type>
    <joint name="soft_hand_index_outer_joint_mimic">
      <hardwareInterface>EffortJointInterface</hardwareInterface>
    </joint>
    <actuator name="soft_hand_index_outer_motor">
      <mechanicalReduction>1.0</mechanicalReduction>
    </actuator>
  </transmission>
  <transmission name="soft_hand_middle_abd_trans">
    <robotNamespace>soft_hand</robotNamespace>
    <type>transmission_interface/SimpleTransmission</type>
    <joint name="soft_hand_middle_abd_joint">
      <hardwareInterface>EffortJointInterface</hardwareInterface>
    </joint>
    <actuator name="soft_hand_middle_abd_motor">
      <mechanicalReduction>1.0</mechanicalReduction>
    </actuator>
  </transmission>
  <transmission name="soft_hand_middle_inner_trans">
    <robotNamespace>soft_hand</robotNamespace>
    <type>transmission_interface/SimpleTransmission</type>
    <joint name="soft_hand_middle_inner_joint">
      <hardwareInterface>EffortJointInterface</hardwareInterface>
    </joint>
    <actuator name="soft_hand_middle_inner_motor">
      <mechanicalReduction>1.0</mechanicalReduction>
    </actuator>
  </transmission>
  <transmission name="soft_hand_middle_inner_mimic_trans">
    <robotNamespace>soft_hand</robotNamespace>
    <type>transmission_interface/SimpleTransmission</type>
    <joint name="soft_hand_middle_inner_joint_mimic">
      <hardwareInterface>EffortJointInterface</hardwareInterface>
    </joint>
    <actuator name="soft_hand_middle_inner_motor">
      <mechanicalReduction>1.0</mechanicalReduction>
    </actuator>
  </transmission>
  <transmission name="soft_hand_middle_middle_trans">
    <robotNamespace>soft_hand</robotNamespace>
    <type>transmission_interface/SimpleTransmission</type>
    <joint name="soft_hand_middle_middle_joint">
      <hardwareInterface>EffortJointInterface</hardwareInterface>
    </joint>
    <actuator name="soft_hand_middle_middle_motor">
      <mechanicalReduction>1.0</mechanicalReduction>
    </actuator>
  </transmission>
  <transmission name="soft_hand_middle_middle_mimic_trans">
    <robotNamespace>soft_hand</robotNamespace>
    <type>transmission_interface/SimpleTransmission</type>
    <joint name="soft_hand_middle_middle_joint_mimic">
      <hardwareInterface>EffortJointInterface</hardwareInterface>
    </joint>
    <actuator name="soft_hand_middle_middle_motor">
      <mechanicalReduction>1.0</mechanicalReduction>
    </actuator>
  </transmission>
  <transmission name="soft_hand_middle_outer_trans">
    <robotNamespace>soft_hand</robotNamespace>
    <type>transmission_interface/SimpleTransmission</type>
    <joint name="soft_hand_middle_outer_joint">
      <hardwareInterface>EffortJointInterface</hardwareInterface>
    </joint>
    <actuator name="soft_hand_middle_outer_motor">
      <mechanicalReduction>1.0</mechanicalReduction>
    </actuator>
  </transmission>
  <transmission name="soft_hand_middle_outer_mimic_trans">
    <robotNamespace>soft_hand</robotNamespace>
    <type>transmission_interface/SimpleTransmission</type>
    <joint name="soft_hand_middle_outer_joint_mimic">
      <hardwareInterface>EffortJointInterface</hardwareInterface>
    </joint>
    <actuator name="soft_hand_middle_outer_motor">
      <mechanicalReduction>1.0</mechanicalReduction>
    </actuator>
  </transmission>
  <transmission name="soft_hand_ring_abd_trans">
    <robotNamespace>soft_hand</robotNamespace>
    <type>transmission_interface/SimpleTransmission</type>
    <joint name="soft_hand_ring_abd_joint">
      <hardwareInterface>EffortJointInterface</hardwareInterface>
    </joint>
    <actuator name="soft_hand_ring_abd_motor">
      <mechanicalReduction>1.0</mechanicalReduction>
    </actuator>
  </transmission>
  <transmission name="soft_hand_ring_inner_trans">
    <robotNamespace>soft_hand</robotNamespace>
    <type>transmission_interface/SimpleTransmission</type>
    <joint name="soft_hand_ring_inner_joint">
      <hardwareInterface>EffortJointInterface</hardwareInterface>
    </joint>
    <actuator name="soft_hand_ring_inner_motor">
      <mechanicalReduction>1.0</mechanicalReduction>
    </actuator>
  </transmission>
  <transmission name="soft_hand_ring_inner_mimic_trans">
    <robotNamespace>soft_hand</robotNamespace>
    <type>transmission_interface/SimpleTransmission</type>
    <joint name="soft_hand_ring_inner_joint_mimic">
      <hardwareInterface>EffortJointInterface</hardwareInterface>
    </joint>
    <actuator name="soft_hand_ring_inner_motor">
      <mechanicalReduction>1.0</mechanicalReduction>
    </actuator>
  </transmission>
  <transmission name="soft_hand_ring_middle_trans">
    <robotNamespace>soft_hand</robotNamespace>
    <type>transmission_interface/SimpleTransmission</type>
    <joint name="soft_hand_ring_middle_joint">
      <hardwareInterface>EffortJointInterface</hardwareInterface>
    </joint>
    <actuator name="soft_hand_ring_middle_motor">
      <mechanicalReduction>1.0</mechanicalReduction>
    </actuator>
  </transmission>
  <transmission name="soft_hand_ring_middle_mimic_trans">
    <robotNamespace>soft_hand</robotNamespace>
    <type>transmission_interface/SimpleTransmission</type>
    <joint name="soft_hand_ring_middle_joint_mimic">
      <hardwareInterface>EffortJointInterface</hardwareInterface>
    </joint>
    <actuator name="soft_hand_ring_middle_motor">
      <mechanicalReduction>1.0</mechanicalReduction>
    </actuator>
  </transmission>
  <transmission name="soft_hand_ring_outer_trans">
    <robotNamespace>soft_hand</robotNamespace>
    <type>transmission_interface/SimpleTransmission</type>
    <joint name="soft_hand_ring_outer_joint">
      <hardwareInterface>EffortJointInterface</hardwareInterface>
    </joint>
    <actuator name="soft_hand_ring_outer_motor">
      <mechanicalReduction>1.0</mechanicalReduction>
    </actuator>
  </transmission>
  <transmission name="soft_hand_ring_outer_mimic_trans">
    <robotNamespace>soft_hand</robotNamespace>
    <type>transmission_interface/SimpleTransmission</type>
    <joint name="soft_hand_ring_outer_joint_mimic">
      <hardwareInterface>EffortJointInterface</hardwareInterface>
    </joint>
    <actuator name="soft_hand_ring_outer_motor">
      <mechanicalReduction>1.0</mechanicalReduction>
    </actuator>
  </transmission>
  <transmission name="soft_hand_little_abd_trans">
    <robotNamespace>soft_hand</robotNamespace>
    <type>transmission_interface/SimpleTransmission</type>
    <joint name="soft_hand_little_abd_joint">
      <hardwareInterface>EffortJointInterface</hardwareInterface>
    </joint>
    <actuator name="soft_hand_little_abd_motor">
      <mechanicalReduction>1.0</mechanicalReduction>
    </actuator>
  </transmission>
  <transmission name="soft_hand_little_inner_trans">
    <robotNamespace>soft_hand</robotNamespace>
    <type>transmission_interface/SimpleTransmission</type>
    <joint name="soft_hand_little_inner_joint">
      <hardwareInterface>EffortJointInterface</hardwareInterface>
    </joint>
    <actuator name="soft_hand_little_inner_motor">
      <mechanicalReduction>1.0</mechanicalReduction>
    </actuator>
  </transmission>
  <transmission name="soft_hand_little_inner_mimic_trans">
    <robotNamespace>soft_hand</robotNamespace>
    <type>transmission_interface/SimpleTransmission</type>
    <joint name="soft_hand_little_inner_joint_mimic">
      <hardwareInterface>EffortJointInterface</hardwareInterface>
    </joint>
    <actuator name="soft_hand_little_inner_motor">
      <mechanicalReduction>1.0</mechanicalReduction>
    </actuator>
  </transmission>
  <transmission name="soft_hand_little_middle_trans">
    <robotNamespace>soft_hand</robotNamespace>
    <type>transmission_interface/SimpleTransmission</type>
    <joint name="soft_hand_little_middle_joint">
      <hardwareInterface>EffortJointInterface</hardwareInterface>
    </joint>
    <actuator name="soft_hand_little_middle_motor">
      <mechanicalReduction>1.0</mechanicalReduction>
    </actuator>
  </transmission>
  <transmission name="soft_hand_little_middle_mimic_trans">
    <robotNamespace>soft_hand</robotNamespace>
    <type>transmission_interface/SimpleTransmission</type>
    <joint name="soft_hand_little_middle_joint_mimic">
      <hardwareInterface>EffortJointInterface</hardwareInterface>
    </joint>
    <actuator name="soft_hand_little_middle_motor">
      <mechanicalReduction>1.0</mechanicalReduction>
    </actuator>
  </transmission>
  <transmission name="soft_hand_little_outer_trans">
    <robotNamespace>soft_hand</robotNamespace>
    <type>transmission_interface/SimpleTransmission</type>
    <joint name="soft_hand_little_outer_joint">
      <hardwareInterface>EffortJointInterface</hardwareInterface>
    </joint>
    <actuator name="soft_hand_little_outer_motor">
      <mechanicalReduction>1.0</mechanicalReduction>
    </actuator>
  </transmission>
  <transmission name="soft_hand_little_outer_mimic_trans">
    <robotNamespace>soft_hand</robotNamespace>
    <type>transmission_interface/SimpleTransmission</type>
    <joint name="soft_hand_little_outer_joint_mimic">
      <hardwareInterface>EffortJointInterface</hardwareInterface>
    </joint>
    <actuator name="soft_hand_little_outer_motor">
      <mechanicalReduction>1.0</mechanicalReduction>
    </actuator>
  </transmission>
  -->
  <gazebo>
    <plugin filename="libgazebo_ros_control.so" name="gazebo_ros_control">
      <robotNamespace>soft_hand</robotNamespace>
    </plugin>
  </gazebo>
  <!-- LINKS -->
  <gazebo reference="soft_hand_palm_link">
    <sensor name="soft_hand_palm_link_contact" type="contact">
      <!-- the gazebo contact sensor -->
      <always_on>1</always_on>
      <update_rate>1000.0</update_rate>
      <contact>
        <collision>soft_hand_palm_link_collision</collision>
        <topic>soft_hand_palm_link_collision</topic>
      </contact>
      <!-- to publish a ros message with contact information -->
      <plugin filename="libgazebo_ros_bumper.so" name="soft_hand_palm_link_gazebo_ros_bumper_plugin">
        <alwaysOn>true</alwaysOn>
        <frameName>soft_hand_palm_link</frameName>
        <updateRate>100.0</updateRate>
        <bumperTopicName>/contacts/soft_hand_palm_link</bumperTopicName>
      </plugin>
    </sensor>
    <gravity>true</gravity>
    <mu1>500.0</mu1>
    <mu2>500.0</mu2>
    <kp>1000000.0</kp>
    <kd>100.0</kd>
    <!-- <fdir1>string</fdir1> -->
    <!-- <dampingFactor>double</dampingFactor> -->
    <!-- <maxVel>double</maxVel> -->
    <!-- <minDepth>double</minDepth> -->
    <!-- <maxContacts>int</maxContacts> -->
  </gazebo>
  <gazebo reference="soft_hand_thumb_knuckle_link">
    <sensor name="soft_hand_thumb_knuckle_link_contact" type="contact">
      <!-- the gazebo contact sensor -->
      <always_on>1</always_on>
      <update_rate>1000.0</update_rate>
      <contact>
        <collision>soft_hand_thumb_knuckle_link_collision</collision>
        <topic>soft_hand_thumb_knuckle_link_collision</topic>
      </contact>
      <!-- to publish a ros message with contact information -->
      <plugin filename="libgazebo_ros_bumper.so" name="soft_hand_thumb_knuckle_link_gazebo_ros_bumper_plugin">
        <alwaysOn>true</alwaysOn>
        <frameName>soft_hand_thumb_knuckle_link</frameName>
        <updateRate>100.0</updateRate>
        <bumperTopicName>/contacts/soft_hand_thumb_knuckle_link</bumperTopicName>
      </plugin>
    </sensor>
    <gravity>true</gravity>
    <mu1>500.0</mu1>
    <mu2>500.0</mu2>
    <kp>1000000.0</kp>
    <kd>100.0</kd>
    <!-- <fdir1>string</fdir1> -->
    <!-- <dampingFactor>double</dampingFactor> -->
    <!-- <maxVel>double</maxVel> -->
    <!-- <minDepth>double</minDepth> -->
    <!-- <maxContacts>int</maxContacts> -->
  </gazebo>
  <gazebo reference="soft_hand_thumb_proximal_link">
    <sensor name="soft_hand_thumb_proximal_link_contact" type="contact">
      <!-- the gazebo contact sensor -->
      <always_on>1</always_on>
      <update_rate>1000.0</update_rate>
      <contact>
        <collision>soft_hand_thumb_proximal_link_collision</collision>
        <topic>soft_hand_thumb_proximal_link_collision</topic>
      </contact>
      <!-- to publish a ros message with contact information -->
      <plugin filename="libgazebo_ros_bumper.so" name="soft_hand_thumb_proximal_link_gazebo_ros_bumper_plugin">
        <alwaysOn>true</alwaysOn>
        <frameName>soft_hand_thumb_proximal_link</frameName>
        <updateRate>100.0</updateRate>
        <bumperTopicName>/contacts/soft_hand_thumb_proximal_link</bumperTopicName>
      </plugin>
    </sensor>
    <gravity>true</gravity>
    <mu1>500.0</mu1>
    <mu2>500.0</mu2>
    <kp>1000000.0</kp>
    <kd>100.0</kd>
    <!-- <fdir1>string</fdir1> -->
    <!-- <dampingFactor>double</dampingFactor> -->
    <!-- <maxVel>double</maxVel> -->
    <!-- <minDepth>double</minDepth> -->
    <!-- <maxContacts>int</maxContacts> -->
  </gazebo>
  <gazebo reference="soft_hand_thumb_distal_link">
    <sensor name="soft_hand_thumb_distal_link_contact" type="contact">
      <!-- the gazebo contact sensor -->
      <always_on>1</always_on>
      <update_rate>1000.0</update_rate>
      <contact>
        <collision>soft_hand_thumb_distal_link_collision</collision>
        <topic>soft_hand_thumb_distal_link_collision</topic>
      </contact>
      <!-- to publish a ros message with contact information -->
      <plugin filename="libgazebo_ros_bumper.so" name="soft_hand_thumb_distal_link_gazebo_ros_bumper_plugin">
        <alwaysOn>true</alwaysOn>
        <frameName>soft_hand_thumb_distal_link</frameName>
        <updateRate>100.0</updateRate>
        <bumperTopicName>/contacts/soft_hand_thumb_distal_link</bumperTopicName>
      </plugin>
    </sensor>
    <gravity>true</gravity>
    <mu1>500.0</mu1>
    <mu2>500.0</mu2>
    <kp>1000000.0</kp>
    <kd>100.0</kd>
    <!-- <fdir1>string</fdir1> -->
    <!-- <dampingFactor>double</dampingFactor> -->
    <!-- <maxVel>double</maxVel> -->
    <!-- <minDepth>double</minDepth> -->
    <!-- <maxContacts>int</maxContacts> -->
  </gazebo>
  <gazebo reference="soft_hand_index_knuckle_link">
    <sensor name="soft_hand_index_knuckle_link_contact" type="contact">
      <!-- the gazebo contact sensor -->
      <always_on>1</always_on>
      <update_rate>1000.0</update_rate>
      <contact>
        <collision>soft_hand_index_knuckle_link_collision</collision>
        <topic>soft_hand_index_knuckle_link_collision</topic>
      </contact>
      <!-- to publish a ros message with contact information -->
      <plugin filename="libgazebo_ros_bumper.so" name="soft_hand_index_knuckle_link_gazebo_ros_bumper_plugin">
        <alwaysOn>true</alwaysOn>
        <frameName>soft_hand_index_knuckle_link</frameName>
        <updateRate>100.0</updateRate>
        <bumperTopicName>/contacts/soft_hand_index_knuckle_link</bumperTopicName>
      </plugin>
    </sensor>
    <gravity>true</gravity>
    <mu1>500.0</mu1>
    <mu2>500.0</mu2>
    <kp>1000000.0</kp>
    <kd>100.0</kd>
    <!-- <fdir1>string</fdir1> -->
    <!-- <dampingFactor>double</dampingFactor> -->
    <!-- <maxVel>double</maxVel> -->
    <!-- <minDepth>double</minDepth> -->
    <!-- <maxContacts>int</maxContacts> -->
  </gazebo>
  <gazebo reference="soft_hand_index_proximal_link">
    <sensor name="soft_hand_index_proximal_link_contact" type="contact">
      <!-- the gazebo contact sensor -->
      <always_on>1</always_on>
      <update_rate>1000.0</update_rate>
      <contact>
        <collision>soft_hand_index_proximal_link_collision</collision>
        <topic>soft_hand_index_proximal_link_collision</topic>
      </contact>
      <!-- to publish a ros message with contact information -->
      <plugin filename="libgazebo_ros_bumper.so" name="soft_hand_index_proximal_link_gazebo_ros_bumper_plugin">
        <alwaysOn>true</alwaysOn>
        <frameName>soft_hand_index_proximal_link</frameName>
        <updateRate>100.0</updateRate>
        <bumperTopicName>/contacts/soft_hand_index_proximal_link</bumperTopicName>
      </plugin>
    </sensor>
    <gravity>true</gravity>
    <mu1>500.0</mu1>
    <mu2>500.0</mu2>
    <kp>1000000.0</kp>
    <kd>100.0</kd>
    <!-- <fdir1>string</fdir1> -->
    <!-- <dampingFactor>double</dampingFactor> -->
    <!-- <maxVel>double</maxVel> -->
    <!-- <minDepth>double</minDepth> -->
    <!-- <maxContacts>int</maxContacts> -->
  </gazebo>
  <gazebo reference="soft_hand_index_middle_link">
    <sensor name="soft_hand_index_middle_link_contact" type="contact">
      <!-- the gazebo contact sensor -->
      <always_on>1</always_on>
      <update_rate>1000.0</update_rate>
      <contact>
        <collision>soft_hand_index_middle_link_collision</collision>
        <topic>soft_hand_index_middle_link_collision</topic>
      </contact>
      <!-- to publish a ros message with contact information -->
      <plugin filename="libgazebo_ros_bumper.so" name="soft_hand_index_middle_link_gazebo_ros_bumper_plugin">
        <alwaysOn>true</alwaysOn>
        <frameName>soft_hand_index_middle_link</frameName>
        <updateRate>100.0</updateRate>
        <bumperTopicName>/contacts/soft_hand_index_middle_link</bumperTopicName>
      </plugin>
    </sensor>
    <gravity>true</gravity>
    <mu1>500.0</mu1>
    <mu2>500.0</mu2>
    <kp>1000000.0</kp>
    <kd>100.0</kd>
    <!-- <fdir1>string</fdir1> -->
    <!-- <dampingFactor>double</dampingFactor> -->
    <!-- <maxVel>double</maxVel> -->
    <!-- <minDepth>double</minDepth> -->
    <!-- <maxContacts>int</maxContacts> -->
  </gazebo>
  <gazebo reference="soft_hand_index_distal_link">
    <sensor name="soft_hand_index_distal_link_contact" type="contact">
      <!-- the gazebo contact sensor -->
      <always_on>1</always_on>
      <update_rate>1000.0</update_rate>
      <contact>
        <collision>soft_hand_index_distal_link_collision</collision>
        <topic>soft_hand_index_distal_link_collision</topic>
      </contact>
      <!-- to publish a ros message with contact information -->
      <plugin filename="libgazebo_ros_bumper.so" name="soft_hand_index_distal_link_gazebo_ros_bumper_plugin">
        <alwaysOn>true</alwaysOn>
        <frameName>soft_hand_index_distal_link</frameName>
        <updateRate>100.0</updateRate>
        <bumperTopicName>/contacts/soft_hand_index_distal_link</bumperTopicName>
      </plugin>
    </sensor>
    <gravity>true</gravity>
    <mu1>500.0</mu1>
    <mu2>500.0</mu2>
    <kp>1000000.0</kp>
    <kd>100.0</kd>
    <!-- <fdir1>string</fdir1> -->
    <!-- <dampingFactor>double</dampingFactor> -->
    <!-- <maxVel>double</maxVel> -->
    <!-- <minDepth>double</minDepth> -->
    <!-- <maxContacts>int</maxContacts> -->
  </gazebo>
  <gazebo reference="soft_hand_middle_knuckle_link">
    <sensor name="soft_hand_middle_knuckle_link_contact" type="contact">
      <!-- the gazebo contact sensor -->
      <always_on>1</always_on>
      <update_rate>1000.0</update_rate>
      <contact>
        <collision>soft_hand_middle_knuckle_link_collision</collision>
        <topic>soft_hand_middle_knuckle_link_collision</topic>
      </contact>
      <!-- to publish a ros message with contact information -->
      <plugin filename="libgazebo_ros_bumper.so" name="soft_hand_middle_knuckle_link_gazebo_ros_bumper_plugin">
        <alwaysOn>true</alwaysOn>
        <frameName>soft_hand_middle_knuckle_link</frameName>
        <updateRate>100.0</updateRate>
        <bumperTopicName>/contacts/soft_hand_middle_knuckle_link</bumperTopicName>
      </plugin>
    </sensor>
    <gravity>true</gravity>
    <mu1>500.0</mu1>
    <mu2>500.0</mu2>
    <kp>1000000.0</kp>
    <kd>100.0</kd>
    <!-- <fdir1>string</fdir1> -->
    <!-- <dampingFactor>double</dampingFactor> -->
    <!-- <maxVel>double</maxVel> -->
    <!-- <minDepth>double</minDepth> -->
    <!-- <maxContacts>int</maxContacts> -->
  </gazebo>
  <gazebo reference="soft_hand_middle_proximal_link">
    <sensor name="soft_hand_middle_proximal_link_contact" type="contact">
      <!-- the gazebo contact sensor -->
      <always_on>1</always_on>
      <update_rate>1000.0</update_rate>
      <contact>
        <collision>soft_hand_middle_proximal_link_collision</collision>
        <topic>soft_hand_middle_proximal_link_collision</topic>
      </contact>
      <!-- to publish a ros message with contact information -->
      <plugin filename="libgazebo_ros_bumper.so" name="soft_hand_middle_proximal_link_gazebo_ros_bumper_plugin">
        <alwaysOn>true</alwaysOn>
        <frameName>soft_hand_middle_proximal_link</frameName>
        <updateRate>100.0</updateRate>
        <bumperTopicName>/contacts/soft_hand_middle_proximal_link</bumperTopicName>
      </plugin>
    </sensor>
    <gravity>true</gravity>
    <mu1>500.0</mu1>
    <mu2>500.0</mu2>
    <kp>1000000.0</kp>
    <kd>100.0</kd>
    <!-- <fdir1>string</fdir1> -->
    <!-- <dampingFactor>double</dampingFactor> -->
    <!-- <maxVel>double</maxVel> -->
    <!-- <minDepth>double</minDepth> -->
    <!-- <maxContacts>int</maxContacts> -->
  </gazebo>
  <gazebo reference="soft_hand_middle_middle_link">
    <sensor name="soft_hand_middle_middle_link_contact" type="contact">
      <!-- the gazebo contact sensor -->
      <always_on>1</always_on>
      <update_rate>1000.0</update_rate>
      <contact>
        <collision>soft_hand_middle_middle_link_collision</collision>
        <topic>soft_hand_middle_middle_link_collision</topic>
      </contact>
      <!-- to publish a ros message with contact information -->
      <plugin filename="libgazebo_ros_bumper.so" name="soft_hand_middle_middle_link_gazebo_ros_bumper_plugin">
        <alwaysOn>true</alwaysOn>
        <frameName>soft_hand_middle_middle_link</frameName>
        <updateRate>100.0</updateRate>
        <bumperTopicName>/contacts/soft_hand_middle_middle_link</bumperTopicName>
      </plugin>
    </sensor>
    <gravity>true</gravity>
    <mu1>500.0</mu1>
    <mu2>500.0</mu2>
    <kp>1000000.0</kp>
    <kd>100.0</kd>
    <!-- <fdir1>string</fdir1> -->
    <!-- <dampingFactor>double</dampingFactor> -->
    <!-- <maxVel>double</maxVel> -->
    <!-- <minDepth>double</minDepth> -->
    <!-- <maxContacts>int</maxContacts> -->
  </gazebo>
  <gazebo reference="soft_hand_middle_distal_link">
    <sensor name="soft_hand_middle_distal_link_contact" type="contact">
      <!-- the gazebo contact sensor -->
      <always_on>1</always_on>
      <update_rate>1000.0</update_rate>
      <contact>
        <collision>soft_hand_middle_distal_link_collision</collision>
        <topic>soft_hand_middle_distal_link_collision</topic>
      </contact>
      <!-- to publish a ros message with contact information -->
      <plugin filename="libgazebo_ros_bumper.so" name="soft_hand_middle_distal_link_gazebo_ros_bumper_plugin">
        <alwaysOn>true</alwaysOn>
        <frameName>soft_hand_middle_distal_link</frameName>
        <updateRate>100.0</updateRate>
        <bumperTopicName>/contacts/soft_hand_middle_distal_link</bumperTopicName>
      </plugin>
    </sensor>
    <gravity>true</gravity>
    <mu1>500.0</mu1>
    <mu2>500.0</mu2>
    <kp>1000000.0</kp>
    <kd>100.0</kd>
    <!-- <fdir1>string</fdir1> -->
    <!-- <dampingFactor>double</dampingFactor> -->
    <!-- <maxVel>double</maxVel> -->
    <!-- <minDepth>double</minDepth> -->
    <!-- <maxContacts>int</maxContacts> -->
  </gazebo>
  <gazebo reference="soft_hand_ring_knuckle_link">
    <sensor name="soft_hand_ring_knuckle_link_contact" type="contact">
      <!-- the gazebo contact sensor -->
      <always_on>1</always_on>
      <update_rate>1000.0</update_rate>
      <contact>
        <collision>soft_hand_ring_knuckle_link_collision</collision>
        <topic>soft_hand_ring_knuckle_link_collision</topic>
      </contact>
      <!-- to publish a ros message with contact information -->
      <plugin filename="libgazebo_ros_bumper.so" name="soft_hand_ring_knuckle_link_gazebo_ros_bumper_plugin">
        <alwaysOn>true</alwaysOn>
        <frameName>soft_hand_ring_knuckle_link</frameName>
        <updateRate>100.0</updateRate>
        <bumperTopicName>/contacts/soft_hand_ring_knuckle_link</bumperTopicName>
      </plugin>
    </sensor>
    <gravity>true</gravity>
    <mu1>500.0</mu1>
    <mu2>500.0</mu2>
    <kp>1000000.0</kp>
    <kd>100.0</kd>
    <!-- <fdir1>string</fdir1> -->
    <!-- <dampingFactor>double</dampingFactor> -->
    <!-- <maxVel>double</maxVel> -->
    <!-- <minDepth>double</minDepth> -->
    <!-- <maxContacts>int</maxContacts> -->
  </gazebo>
  <gazebo reference="soft_hand_ring_proximal_link">
    <sensor name="soft_hand_ring_proximal_link_contact" type="contact">
      <!-- the gazebo contact sensor -->
      <always_on>1</always_on>
      <update_rate>1000.0</update_rate>
      <contact>
        <collision>soft_hand_ring_proximal_link_collision</collision>
        <topic>soft_hand_ring_proximal_link_collision</topic>
      </contact>
      <!-- to publish a ros message with contact information -->
      <plugin filename="libgazebo_ros_bumper.so" name="soft_hand_ring_proximal_link_gazebo_ros_bumper_plugin">
        <alwaysOn>true</alwaysOn>
        <frameName>soft_hand_ring_proximal_link</frameName>
        <updateRate>100.0</updateRate>
        <bumperTopicName>/contacts/soft_hand_ring_proximal_link</bumperTopicName>
      </plugin>
    </sensor>
    <gravity>true</gravity>
    <mu1>500.0</mu1>
    <mu2>500.0</mu2>
    <kp>1000000.0</kp>
    <kd>100.0</kd>
    <!-- <fdir1>string</fdir1> -->
    <!-- <dampingFactor>double</dampingFactor> -->
    <!-- <maxVel>double</maxVel> -->
    <!-- <minDepth>double</minDepth> -->
    <!-- <maxContacts>int</maxContacts> -->
  </gazebo>
  <gazebo reference="soft_hand_ring_middle_link">
    <sensor name="soft_hand_ring_middle_link_contact" type="contact">
      <!-- the gazebo contact sensor -->
      <always_on>1</always_on>
      <update_rate>1000.0</update_rate>
      <contact>
        <collision>soft_hand_ring_middle_link_collision</collision>
        <topic>soft_hand_ring_middle_link_collision</topic>
      </contact>
      <!-- to publish a ros message with contact information -->
      <plugin filename="libgazebo_ros_bumper.so" name="soft_hand_ring_middle_link_gazebo_ros_bumper_plugin">
        <alwaysOn>true</alwaysOn>
        <frameName>soft_hand_ring_middle_link</frameName>
        <updateRate>100.0</updateRate>
        <bumperTopicName>/contacts/soft_hand_ring_middle_link</bumperTopicName>
      </plugin>
    </sensor>
    <gravity>true</gravity>
    <mu1>500.0</mu1>
    <mu2>500.0</mu2>
    <kp>1000000.0</kp>
    <kd>100.0</kd>
    <!-- <fdir1>string</fdir1> -->
    <!-- <dampingFactor>double</dampingFactor> -->
    <!-- <maxVel>double</maxVel> -->
    <!-- <minDepth>double</minDepth> -->
    <!-- <maxContacts>int</maxContacts> -->
  </gazebo>
  <gazebo reference="soft_hand_ring_distal_link">
    <sensor name="soft_hand_ring_distal_link_contact" type="contact">
      <!-- the gazebo contact sensor -->
      <always_on>1</always_on>
      <update_rate>1000.0</update_rate>
      <contact>
        <collision>soft_hand_ring_distal_link_collision</collision>
        <topic>soft_hand_ring_distal_link_collision</topic>
      </contact>
      <!-- to publish a ros message with contact information -->
      <plugin filename="libgazebo_ros_bumper.so" name="soft_hand_ring_distal_link_gazebo_ros_bumper_plugin">
        <alwaysOn>true</alwaysOn>
        <frameName>soft_hand_ring_distal_link</frameName>
        <updateRate>100.0</updateRate>
        <bumperTopicName>/contacts/soft_hand_ring_distal_link</bumperTopicName>
      </plugin>
    </sensor>
    <gravity>true</gravity>
    <mu1>500.0</mu1>
    <mu2>500.0</mu2>
    <kp>1000000.0</kp>
    <kd>100.0</kd>
    <!-- <fdir1>string</fdir1> -->
    <!-- <dampingFactor>double</dampingFactor> -->
    <!-- <maxVel>double</maxVel> -->
    <!-- <minDepth>double</minDepth> -->
    <!-- <maxContacts>int</maxContacts> -->
  </gazebo>
  <gazebo reference="soft_hand_little_knuckle_link">
    <sensor name="soft_hand_little_knuckle_link_contact" type="contact">
      <!-- the gazebo contact sensor -->
      <always_on>1</always_on>
      <update_rate>1000.0</update_rate>
      <contact>
        <collision>soft_hand_little_knuckle_link_collision</collision>
        <topic>soft_hand_little_knuckle_link_collision</topic>
      </contact>
      <!-- to publish a ros message with contact information -->
      <plugin filename="libgazebo_ros_bumper.so" name="soft_hand_little_knuckle_link_gazebo_ros_bumper_plugin">
        <alwaysOn>true</alwaysOn>
        <frameName>soft_hand_little_knuckle_link</frameName>
        <updateRate>100.0</updateRate>
        <bumperTopicName>/contacts/soft_hand_little_knuckle_link</bumperTopicName>
      </plugin>
    </sensor>
    <gravity>true</gravity>
    <mu1>500.0</mu1>
    <mu2>500.0</mu2>
    <kp>1000000.0</kp>
    <kd>100.0</kd>
    <!-- <fdir1>string</fdir1> -->
    <!-- <dampingFactor>double</dampingFactor> -->
    <!-- <maxVel>double</maxVel> -->
    <!-- <minDepth>double</minDepth> -->
    <!-- <maxContacts>int</maxContacts> -->
  </gazebo>
  <gazebo reference="soft_hand_little_proximal_link">
    <sensor name="soft_hand_little_proximal_link_contact" type="contact">
      <!-- the gazebo contact sensor -->
      <always_on>1</always_on>
      <update_rate>1000.0</update_rate>
      <contact>
        <collision>soft_hand_little_proximal_link_collision</collision>
        <topic>soft_hand_little_proximal_link_collision</topic>
      </contact>
      <!-- to publish a ros message with contact information -->
      <plugin filename="libgazebo_ros_bumper.so" name="soft_hand_little_proximal_link_gazebo_ros_bumper_plugin">
        <alwaysOn>true</alwaysOn>
        <frameName>soft_hand_little_proximal_link</frameName>
        <updateRate>100.0</updateRate>
        <bumperTopicName>/contacts/soft_hand_little_proximal_link</bumperTopicName>
      </plugin>
    </sensor>
    <gravity>true</gravity>
    <mu1>500.0</mu1>
    <mu2>500.0</mu2>
    <kp>1000000.0</kp>
    <kd>100.0</kd>
    <!-- <fdir1>string</fdir1> -->
    <!-- <dampingFactor>double</dampingFactor> -->
    <!-- <maxVel>double</maxVel> -->
    <!-- <minDepth>double</minDepth> -->
    <!-- <maxContacts>int</maxContacts> -->
  </gazebo>
  <gazebo reference="soft_hand_little_middle_link">
    <sensor name="soft_hand_little_middle_link_contact" type="contact">
      <!-- the gazebo contact sensor -->
      <always_on>1</always_on>
      <update_rate>1000.0</update_rate>
      <contact>
        <collision>soft_hand_little_middle_link_collision</collision>
        <topic>soft_hand_little_middle_link_collision</topic>
      </contact>
      <!-- to publish a ros message with contact information -->
      <plugin filename="libgazebo_ros_bumper.so" name="soft_hand_little_middle_link_gazebo_ros_bumper_plugin">
        <alwaysOn>true</alwaysOn>
        <frameName>soft_hand_little_middle_link</frameName>
        <updateRate>100.0</updateRate>
        <bumperTopicName>/contacts/soft_hand_little_middle_link</bumperTopicName>
      </plugin>
    </sensor>
    <gravity>true</gravity>
    <mu1>500.0</mu1>
    <mu2>500.0</mu2>
    <kp>1000000.0</kp>
    <kd>100.0</kd>
    <!-- <fdir1>string</fdir1> -->
    <!-- <dampingFactor>double</dampingFactor> -->
    <!-- <maxVel>double</maxVel> -->
    <!-- <minDepth>double</minDepth> -->
    <!-- <maxContacts>int</maxContacts> -->
  </gazebo>
  <gazebo reference="soft_hand_little_distal_link">
    <sensor name="soft_hand_little_distal_link_contact" type="contact">
      <!-- the gazebo contact sensor -->
      <always_on>1</always_on>
      <update_rate>1000.0</update_rate>
      <contact>
        <collision>soft_hand_little_distal_link_collision</collision>
        <topic>soft_hand_little_distal_link_collision</topic>
      </contact>
      <!-- to publish a ros message with contact information -->
      <plugin filename="libgazebo_ros_bumper.so" name="soft_hand_little_distal_link_gazebo_ros_bumper_plugin">
        <alwaysOn>true</alwaysOn>
        <frameName>soft_hand_little_distal_link</frameName>
        <updateRate>100.0</updateRate>
        <bumperTopicName>/contacts/soft_hand_little_distal_link</bumperTopicName>
      </plugin>
    </sensor>
    <gravity>true</gravity>
    <mu1>500.0</mu1>
    <mu2>500.0</mu2>
    <kp>1000000.0</kp>
    <kd>100.0</kd>
    <!-- <fdir1>string</fdir1> -->
    <!-- <dampingFactor>double</dampingFactor> -->
    <!-- <maxVel>double</maxVel> -->
    <!-- <minDepth>double</minDepth> -->
    <!-- <maxContacts>int</maxContacts> -->
  </gazebo>
  <!-- JOINTS -->
  <gazebo reference="soft_hand_thumb_abd_joint">
    <provideFeedback>True</provideFeedback>
    <!--
		<kp> </kp>
		<kd> 1.0 </kd>
		<stopCfm> </stopCfm>
		<stopErp> </stopErp>
		<cfmDamping> </cfmDamping>
		<fudgeFactor> </fudgeFactor>
		-->
  </gazebo>
  <gazebo reference="soft_hand_thumb_inner_joint">
    <provideFeedback>True</provideFeedback>
    <!--
		<kp> </kp>
		<kd> 1.0 </kd>
		<stopCfm> </stopCfm>
		<stopErp> </stopErp>
		<cfmDamping> </cfmDamping>
		<fudgeFactor> </fudgeFactor>
		-->
  </gazebo>
  <gazebo reference="soft_hand_thumb_outer_joint">
    <provideFeedback>True</provideFeedback>
    <!--
		<kp> </kp>
		<kd> 1.0 </kd>
		<stopCfm> </stopCfm>
		<stopErp> </stopErp>
		<cfmDamping> </cfmDamping>
		<fudgeFactor> </fudgeFactor>
		-->
  </gazebo>
  <gazebo reference="soft_hand_index_abd_joint">
    <provideFeedback>True</provideFeedback>
    <!--
		<kp> </kp>
		<kd> 1.0 </kd>
		<stopCfm> </stopCfm>
		<stopErp> </stopErp>
		<cfmDamping> </cfmDamping>
		<fudgeFactor> </fudgeFactor>
		-->
  </gazebo>
  <gazebo reference="soft_hand_index_inner_joint">
    <provideFeedback>True</provideFeedback>
    <!--
		<kp> </kp>
		<kd> 1.0 </kd>
		<stopCfm> </stopCfm>
		<stopErp> </stopErp>
		<cfmDamping> </cfmDamping>
		<fudgeFactor> </fudgeFactor>
		-->
  </gazebo>
  <gazebo reference="soft_hand_index_middle_joint">
    <provideFeedback>True</provideFeedback>
    <!--
		<kp> </kp>
		<kd> 1.0 </kd>
		<stopCfm> </stopCfm>
		<stopErp> </stopErp>
		<cfmDamping> </cfmDamping>
		<fudgeFactor> </fudgeFactor>
		-->
  </gazebo>
  <gazebo reference="soft_hand_index_outer_joint">
    <provideFeedback>True</provideFeedback>
    <!--
		<kp> </kp>
		<kd> 1.0 </kd>
		<stopCfm> </stopCfm>
		<stopErp> </stopErp>
		<cfmDamping> </cfmDamping>
		<fudgeFactor> </fudgeFactor>
		-->
  </gazebo>
  <gazebo reference="soft_hand_middle_abd_joint">
    <provideFeedback>True</provideFeedback>
    <!--
		<kp> </kp>
		<kd> 1.0 </kd>
		<stopCfm> </stopCfm>
		<stopErp> </stopErp>
		<cfmDamping> </cfmDamping>
		<fudgeFactor> </fudgeFactor>
		-->
  </gazebo>
  <gazebo reference="soft_hand_middle_inner_joint">
    <provideFeedback>True</provideFeedback>
    <!--
		<kp> </kp>
		<kd> 1.0 </kd>
		<stopCfm> </stopCfm>
		<stopErp> </stopErp>
		<cfmDamping> </cfmDamping>
		<fudgeFactor> </fudgeFactor>
		-->
  </gazebo>
  <gazebo reference="soft_hand_middle_middle_joint">
    <provideFeedback>True</provideFeedback>
    <!--
		<kp> </kp>
		<kd> 1.0 </kd>
		<stopCfm> </stopCfm>
		<stopErp> </stopErp>
		<cfmDamping> </cfmDamping>
		<fudgeFactor> </fudgeFactor>
		-->
  </gazebo>
  <gazebo reference="soft_hand_middle_outer_joint">
    <provideFeedback>True</provideFeedback>
    <!--
		<kp> </kp>
		<kd> 1.0 </kd>
		<stopCfm> </stopCfm>
		<stopErp> </stopErp>
		<cfmDamping> </cfmDamping>
		<fudgeFactor> </fudgeFactor>
		-->
  </gazebo>
  <gazebo reference="soft_hand_ring_abd_joint">
    <provideFeedback>True</provideFeedback>
    <!--
		<kp> </kp>
		<kd> 1.0 </kd>
		<stopCfm> </stopCfm>
		<stopErp> </stopErp>
		<cfmDamping> </cfmDamping>
		<fudgeFactor> </fudgeFactor>
		-->
  </gazebo>
  <gazebo reference="soft_hand_ring_inner_joint">
    <provideFeedback>True</provideFeedback>
    <!--
		<kp> </kp>
		<kd> 1.0 </kd>
		<stopCfm> </stopCfm>
		<stopErp> </stopErp>
		<cfmDamping> </cfmDamping>
		<fudgeFactor> </fudgeFactor>
		-->
  </gazebo>
  <gazebo reference="soft_hand_ring_middle_joint">
    <provideFeedback>True</provideFeedback>
    <!--
		<kp> </kp>
		<kd> 1.0 </kd>
		<stopCfm> </stopCfm>
		<stopErp> </stopErp>
		<cfmDamping> </cfmDamping>
		<fudgeFactor> </fudgeFactor>
		-->
  </gazebo>
  <gazebo reference="soft_hand_ring_outer_joint">
    <provideFeedback>True</provideFeedback>
    <!--
		<kp> </kp>
		<kd> 1.0 </kd>
		<stopCfm> </stopCfm>
		<stopErp> </stopErp>
		<cfmDamping> </cfmDamping>
		<fudgeFactor> </fudgeFactor>
		-->
  </gazebo>
  <gazebo reference="soft_hand_little_abd_joint">
    <provideFeedback>True</provideFeedback>
    <!--
		<kp> </kp>
		<kd> 1.0 </kd>
		<stopCfm> </stopCfm>
		<stopErp> </stopErp>
		<cfmDamping> </cfmDamping>
		<fudgeFactor> </fudgeFactor>
		-->
  </gazebo>
  <gazebo reference="soft_hand_little_inner_joint">
    <provideFeedback>True</provideFeedback>
    <!--
		<kp> </kp>
		<kd> 1.0 </kd>
		<stopCfm> </stopCfm>
		<stopErp> </stopErp>
		<cfmDamping> </cfmDamping>
		<fudgeFactor> </fudgeFactor>
		-->
  </gazebo>
  <gazebo reference="soft_hand_little_middle_joint">
    <provideFeedback>True</provideFeedback>
    <!--
		<kp> </kp>
		<kd> 1.0 </kd>
		<stopCfm> </stopCfm>
		<stopErp> </stopErp>
		<cfmDamping> </cfmDamping>
		<fudgeFactor> </fudgeFactor>
		-->
  </gazebo>
  <gazebo reference="soft_hand_little_outer_joint">
    <provideFeedback>True</provideFeedback>
    <!--
		<kp> </kp>
		<kd> 1.0 </kd>
		<stopCfm> </stopCfm>
		<stopErp> </stopErp>
		<cfmDamping> </cfmDamping>
		<fudgeFactor> </fudgeFactor>
		-->
  </gazebo>
  <!-- mimic joints -->
  <gazebo reference="soft_hand_thumb_inner_joint_mimic">
    <provideFeedback>True</provideFeedback>
    <!--
		<kp> </kp>
		<kd> 1.0 </kd>
		<stopCfm> </stopCfm>
		<stopErp> </stopErp>
		<cfmDamping> </cfmDamping>
		<fudgeFactor> </fudgeFactor>
		-->
  </gazebo>
  <gazebo reference="soft_hand_thumb_outer_joint_mimic">
    <provideFeedback>True</provideFeedback>
    <!--
		<kp> </kp>
		<kd> 1.0 </kd>
		<stopCfm> </stopCfm>
		<stopErp> </stopErp>
		<cfmDamping> </cfmDamping>
		<fudgeFactor> </fudgeFactor>
		-->
  </gazebo>
  <gazebo reference="soft_hand_index_inner_joint_mimic">
    <provideFeedback>True</provideFeedback>
    <!--
		<kp> </kp>
		<kd> 1.0 </kd>
		<stopCfm> </stopCfm>
		<stopErp> </stopErp>
		<cfmDamping> </cfmDamping>
		<fudgeFactor> </fudgeFactor>
		-->
  </gazebo>
  <gazebo reference="soft_hand_index_middle_joint_mimic">
    <provideFeedback>True</provideFeedback>
    <!--
		<kp> </kp>
		<kd> 1.0 </kd>
		<stopCfm> </stopCfm>
		<stopErp> </stopErp>
		<cfmDamping> </cfmDamping>
		<fudgeFactor> </fudgeFactor>
		-->
  </gazebo>
  <gazebo reference="soft_hand_index_outer_joint_mimic">
    <provideFeedback>True</provideFeedback>
    <!--
		<kp> </kp>
		<kd> 1.0 </kd>
		<stopCfm> </stopCfm>
		<stopErp> </stopErp>
		<cfmDamping> </cfmDamping>
		<fudgeFactor> </fudgeFactor>
		-->
  </gazebo>
  <gazebo reference="soft_hand_middle_inner_joint_mimic">
    <provideFeedback>True</provideFeedback>
    <!--
		<kp> </kp>
		<kd> 1.0 </kd>
		<stopCfm> </stopCfm>
		<stopErp> </stopErp>
		<cfmDamping> </cfmDamping>
		<fudgeFactor> </fudgeFactor>
		-->
  </gazebo>
  <gazebo reference="soft_hand_middle_middle_joint_mimic">
    <provideFeedback>True</provideFeedback>
    <!--
		<kp> </kp>
		<kd> 1.0 </kd>
		<stopCfm> </stopCfm>
		<stopErp> </stopErp>
		<cfmDamping> </cfmDamping>
		<fudgeFactor> </fudgeFactor>
		-->
  </gazebo>
  <gazebo reference="soft_hand_middle_outer_joint_mimic">
    <provideFeedback>True</provideFeedback>
    <!--
		<kp> </kp>
		<kd> 1.0 </kd>
		<stopCfm> </stopCfm>
		<stopErp> </stopErp>
		<cfmDamping> </cfmDamping>
		<fudgeFactor> </fudgeFactor>
		-->
  </gazebo>
  <gazebo reference="soft_hand_ring_inner_joint_mimic">
    <provideFeedback>True</provideFeedback>
    <!--
		<kp> </kp>
		<kd> 1.0 </kd>
		<stopCfm> </stopCfm>
		<stopErp> </stopErp>
		<cfmDamping> </cfmDamping>
		<fudgeFactor> </fudgeFactor>
		-->
  </gazebo>
  <gazebo reference="soft_hand_ring_middle_joint_mimic">
    <provideFeedback>True</provideFeedback>
    <!--
		<kp> </kp>
		<kd> 1.0 </kd>
		<stopCfm> </stopCfm>
		<stopErp> </stopErp>
		<cfmDamping> </cfmDamping>
		<fudgeFactor> </fudgeFactor>
		-->
  </gazebo>
  <gazebo reference="soft_hand_ring_outer_joint_mimic">
    <provideFeedback>True</provideFeedback>
    <!--
		<kp> </kp>
		<kd> 1.0 </kd>
		<stopCfm> </stopCfm>
		<stopErp> </stopErp>
		<cfmDamping> </cfmDamping>
		<fudgeFactor> </fudgeFactor>
		-->
  </gazebo>
  <gazebo reference="soft_hand_little_inner_joint_mimic">
    <provideFeedback>True</provideFeedback>
    <!--
		<kp> </kp>
		<kd> 1.0 </kd>
		<stopCfm> </stopCfm>
		<stopErp> </stopErp>
		<cfmDamping> </cfmDamping>
		<fudgeFactor> </fudgeFactor>
		-->
  </gazebo>
  <gazebo reference="soft_hand_little_middle_joint_mimic">
    <provideFeedback>True</provideFeedback>
    <!--
		<kp> </kp>
		<kd> 1.0 </kd>
		<stopCfm> </stopCfm>
		<stopErp> </stopErp>
		<cfmDamping> </cfmDamping>
		<fudgeFactor> </fudgeFactor>
		-->
  </gazebo>
  <gazebo reference="soft_hand_little_outer_joint_mimic">
    <provideFeedback>True</provideFeedback>
    <!--
		<kp> </kp>
		<kd> 1.0 </kd>
		<stopCfm> </stopCfm>
		<stopErp> </stopErp>
		<cfmDamping> </cfmDamping>
		<fudgeFactor> </fudgeFactor>
		-->
  </gazebo>
</robot>

