<?xml version="1.0" ?>
<!-- =================================================================================== -->
<!-- |    This document was autogenerated by xacro from hit2.urdf.xacro                | -->
<!-- |    EDITING THIS FILE BY HAND IS NOT RECOMMENDED                                 | -->
<!-- =================================================================================== -->
<!-- robot name="lwr" xmlns:controller="http://playerstage.sourceforge.net/gazebo/xmlschema/#controller" xmlns:interface="http://playerstage.sourceforge.net/gazebo/xmlschema/#interface" xmlns:sensor="http://playerstage.sourceforge.net/gazebo/xmlschema/#sensor" xmlns:xacro="http://ros.org/wiki/xacro" -->
<robot name="dlr_hand">
  <material name="DLR/LightGrey">
    <color rgba="0.7 0.7 0.7 1.0"/>
  </material>
  <material name="DLR/DarkGrey">
    <color rgba="0.4 0.4 0.4 1.0"/>
  </material>
  <material name="DLR/Black">
    <color rgba="0.0 0.0 0.0 1.0"/>
  </material>
  <material name="DLR/DarkGolden">
    <color rgba="0.4 0.4 0.3 1.0"/>
  </material>
  <material name="DLR/Blue">
    <color rgba="0.0 0.0 0.8 1.0"/>
  </material>
  <link name="world_link">
    <inertial>
      <mass value="50.0"/>
      <com xyz="0 0 0"/>
      <inertia ixx="0.01" ixy="0.00" ixz="0.00" iyy="0.01" iyz="0.00" izz="0.01"/>
    </inertial>
    <visual>
      <origin rpy="0 0 0" xyz="0 0 0.0"/>
      <geometry>
        <box size="0.01 0.01 0.01"/>
      </geometry>
    </visual>
    <collision>
      <origin rpy="0 0 0" xyz="0 0 0.0"/>
      <geometry>
        <box size="0.01 0.01 0.01"/>
      </geometry>
    </collision>
  </link>
  <joint name="right_palm_joint" type="fixed">
    <origin rpy="0 0 0" xyz="0 0 0"/>
    <parent link="world_link"/>
    <child link="right_palm_link"/>
  </joint>
  <link name="right_palm_link">
    <inertial>
      <!-- PALM MASS AND INERTIA TO BE ESTIMATED!!!! -->
      <origin rpy="0 0 0" xyz="0 0 0"/>
      <mass value="1"/>
      <inertia ixx="0.01" ixy="0" ixz="0" iyy="0.01" iyz="0" izz="0.01"/>
    </inertial>
    <!-- also check whether is ok to leave at zero the origin -->
    <visual>
      <origin rpy="0 0 0" xyz="0 0 0"/>
      <geometry>
        <mesh filename="meshes/palm.stl"/>
      </geometry>
      <material name="DLR/LightGrey"/>
    </visual>
    <collision>
      <origin rpy="0 0 0" xyz="0 0 0"/>
      <geometry>
        <mesh filename="meshes/palm.stl"/>
      </geometry>
    </collision>
  </link>
  <joint name="right_thumb_abd_joint" type="revolute">
    <origin rpy="0.41136 -1.08366 0.225804" xyz="0.062569057 0.044544548 0.080044647"/>
    <parent link="right_palm_link"/>
    <!-- <child joint="${name}_inner_joint"/> -->
    <child link="right_thumb_abd_link"/>
    <axis xyz="0 0 1"/>
    <dynamics damping="1"/>
    <limit effort="100" lower="-0.349065850399" upper="0.349065850399" velocity="5"/>
    <!-- effort="100" velocity="5" -->
  </joint>
  <link name="right_thumb_abd_link">
    <inertial>
      <origin rpy="0 0 0" xyz="0 0 0"/>
      <mass value="0.5"/>
      <inertia ixx="0" ixy="0" ixz="0" iyy="0" iyz="0" izz="0"/>
    </inertial>
  </link>
  <joint name="right_thumb_inner_joint" type="revolute">
    <!-- coincident with abd_joint, rotated of 90 degrees along x -->
    <origin rpy="1.57079632679 0 0" xyz="0 0 0"/>
    <parent link="right_thumb_abd_link"/>
    <!-- <parent joint="${name}_abd_joint"/> -->
    <child link="right_thumb_proximal_link"/>
    <axis xyz="0 0 1"/>
    <dynamics damping="1"/>
    <limit effort="100" lower="0.10471975512" upper="0.10471975512" velocity="5"/>
    <!-- effort="100" velocity="5" -->
  </joint>
  <link name="right_thumb_proximal_link">
    <inertial>
      <origin rpy="0 0 0" xyz="0 0 0"/>
      <mass value="0.044370598"/>
      <!-- using inertia wrt ACS0 (joint frame) - to be changed if baricentrical is needed -->
      <inertia ixx="4.5592704e-06" ixy="9.0783105e-07" ixz="-9.399771e-07" iyy="4.9045259e-05" iyz="1.7052714e-08" izz="5.0524234e-05"/>
    </inertial>
    <visual>
      <origin rpy="0 0 0" xyz="0 0 0"/>
      <geometry>
        <mesh filename="meshes/proximal.stl"/>
      </geometry>
      <material name="DLR/LightGrey"/>
    </visual>
    <collision>
      <origin rpy="0 0 0" xyz="0 0 0"/>
      <geometry>
        <mesh filename="meshes/proximal.stl"/>
      </geometry>
    </collision>
  </link>
  <joint name="right_thumb_outer1_joint" type="revolute">
    <origin rpy="0 0 0" xyz="0.055 0 0"/>
    <parent link="right_thumb_proximal_link"/>
    <child link="right_thumb_medial_link"/>
    <axis xyz="0 0 1"/>
    <dynamics damping="1"/>
    <limit effort="100" lower="1.308996939" upper="1.308996939" velocity="5"/>
    <!-- effort="100" velocity="5" -->
  </joint>
  <link name="right_thumb_medial_link">
    <inertial>
      <origin rpy="0 0 0" xyz="0 0 0"/>
      <mass value="0.027110192"/>
      <!-- using inertia wrt ACS0 (joint frame) - to be changed if baricentrical is needed -->
      <inertia ixx="2.2900229e-06" ixy="4.0604622e-07" ixz="1.4362094e-07" iyy="4.2155489e-06" iyz="-4.3115648e-08" izz="4.4292927e-06"/>
    </inertial>
    <visual>
      <origin rpy="0 0 0" xyz="0 0 0"/>
      <geometry>
        <mesh filename="meshes/medial.stl"/>
      </geometry>
      <material name="DLR/LightGrey"/>
    </visual>
    <collision>
      <origin rpy="0 0 0" xyz="0 0 0"/>
      <geometry>
        <mesh filename="meshes/medial.stl"/>
      </geometry>
    </collision>
  </link>
  <joint name="right_thumb_outer2_joint" type="revolute">
    <origin rpy="0 0 -1.57079632679" xyz="0.025 0 0"/>
    <parent link="right_thumb_medial_link"/>
    <child link="right_thumb_distal_link"/>
    <axis xyz="0 0 1"/>
    <dynamics damping="1"/>
    <limit effort="100" lower="1.308996939" upper="1.308996939" velocity="5"/>
    <!-- effort="100" velocity="5" -->
  </joint>
  <link name="right_thumb_distal_link">
    <inertial>
      <origin rpy="0 0 0" xyz="0 0 0"/>
      <mass value="0.018179709"/>
      <!-- using inertia wrt ACS0 (joint frame) - to be changed if baricentrical is needed -->
      <inertia ixx="2.5867271e-06" ixy="1.5840536e-07" ixz="-7.8205885e-10" iyy="8.4596248e-07" iyz="-4.8358115e-09" izz="2.5838485e-06"/>
    </inertial>
    <visual>
      <origin rpy="0 0 0" xyz="0 0 0"/>
      <geometry>
        <mesh filename="meshes/distal.stl"/>
      </geometry>
      <material name="DLR/LightGrey"/>
    </visual>
    <collision>
      <origin rpy="0 0 0" xyz="0 0 0"/>
      <geometry>
        <mesh filename="meshes/distal.stl"/>
      </geometry>
    </collision>
  </link>
  <joint name="right_index_abd_joint" type="revolute">
    <origin rpy="3.05433 -1.57079632679 0" xyz="-0.002529881 0.036800135 0.108743545"/>
    <parent link="right_palm_link"/>
    <!-- <child joint="${name}_inner_joint"/> -->
    <child link="right_index_abd_link"/>
    <axis xyz="0 0 1"/>
    <dynamics damping="1"/>
    <limit effort="100" lower="-0.349065850399" upper="0.349065850399" velocity="5"/>
    <!-- effort="100" velocity="5" -->
  </joint>
  <link name="right_index_abd_link">
    <inertial>
      <origin rpy="0 0 0" xyz="0 0 0"/>
      <mass value="0.5"/>
      <inertia ixx="0" ixy="0" ixz="0" iyy="0" iyz="0" izz="0"/>
    </inertial>
  </link>
  <joint name="right_index_inner_joint" type="revolute">
    <!-- coincident with abd_joint, rotated of 90 degrees along x -->
    <origin rpy="1.57079632679 0 0" xyz="0 0 0"/>
    <parent link="right_index_abd_link"/>
    <!-- <parent joint="${name}_abd_joint"/> -->
    <child link="right_index_proximal_link"/>
    <axis xyz="0 0 1"/>
    <dynamics damping="1"/>
    <limit effort="100" lower="0.10471975512" upper="0.10471975512" velocity="5"/>
    <!-- effort="100" velocity="5" -->
  </joint>
  <link name="right_index_proximal_link">
    <inertial>
      <origin rpy="0 0 0" xyz="0 0 0"/>
      <mass value="0.044370598"/>
      <!-- using inertia wrt ACS0 (joint frame) - to be changed if baricentrical is needed -->
      <inertia ixx="4.5592704e-06" ixy="9.0783105e-07" ixz="-9.399771e-07" iyy="4.9045259e-05" iyz="1.7052714e-08" izz="5.0524234e-05"/>
    </inertial>
    <visual>
      <origin rpy="0 0 0" xyz="0 0 0"/>
      <geometry>
        <mesh filename="meshes/proximal.stl"/>
      </geometry>
      <material name="DLR/LightGrey"/>
    </visual>
    <collision>
      <origin rpy="0 0 0" xyz="0 0 0"/>
      <geometry>
        <mesh filename="meshes/proximal.stl"/>
      </geometry>
    </collision>
  </link>
  <joint name="right_index_outer1_joint" type="revolute">
    <origin rpy="0 0 0" xyz="0.055 0 0"/>
    <parent link="right_index_proximal_link"/>
    <child link="right_index_medial_link"/>
    <axis xyz="0 0 1"/>
    <dynamics damping="1"/>
    <limit effort="100" lower="1.308996939" upper="1.308996939" velocity="5"/>
    <!-- effort="100" velocity="5" -->
  </joint>
  <link name="right_index_medial_link">
    <inertial>
      <origin rpy="0 0 0" xyz="0 0 0"/>
      <mass value="0.027110192"/>
      <!-- using inertia wrt ACS0 (joint frame) - to be changed if baricentrical is needed -->
      <inertia ixx="2.2900229e-06" ixy="4.0604622e-07" ixz="1.4362094e-07" iyy="4.2155489e-06" iyz="-4.3115648e-08" izz="4.4292927e-06"/>
    </inertial>
    <visual>
      <origin rpy="0 0 0" xyz="0 0 0"/>
      <geometry>
        <mesh filename="meshes/medial.stl"/>
      </geometry>
      <material name="DLR/LightGrey"/>
    </visual>
    <collision>
      <origin rpy="0 0 0" xyz="0 0 0"/>
      <geometry>
        <mesh filename="meshes/medial.stl"/>
      </geometry>
    </collision>
  </link>
  <joint name="right_index_outer2_joint" type="revolute">
    <origin rpy="0 0 -1.57079632679" xyz="0.025 0 0"/>
    <parent link="right_index_medial_link"/>
    <child link="right_index_distal_link"/>
    <axis xyz="0 0 1"/>
    <dynamics damping="1"/>
    <limit effort="100" lower="1.308996939" upper="1.308996939" velocity="5"/>
    <!-- effort="100" velocity="5" -->
  </joint>
  <link name="right_index_distal_link">
    <inertial>
      <origin rpy="0 0 0" xyz="0 0 0"/>
      <mass value="0.018179709"/>
      <!-- using inertia wrt ACS0 (joint frame) - to be changed if baricentrical is needed -->
      <inertia ixx="2.5867271e-06" ixy="1.5840536e-07" ixz="-7.8205885e-10" iyy="8.4596248e-07" iyz="-4.8358115e-09" izz="2.5838485e-06"/>
    </inertial>
    <visual>
      <origin rpy="0 0 0" xyz="0 0 0"/>
      <geometry>
        <mesh filename="meshes/distal.stl"/>
      </geometry>
      <material name="DLR/LightGrey"/>
    </visual>
    <collision>
      <origin rpy="0 0 0" xyz="0 0 0"/>
      <geometry>
        <mesh filename="meshes/distal.stl"/>
      </geometry>
    </collision>
  </link>
  <joint name="right_middle_abd_joint" type="revolute">
    <origin rpy="3.14159265359 -1.57079632679 0" xyz="-0.0037 0.01 0.119043545"/>
    <parent link="right_palm_link"/>
    <!-- <child joint="${name}_inner_joint"/> -->
    <child link="right_middle_abd_link"/>
    <axis xyz="0 0 1"/>
    <dynamics damping="1"/>
    <limit effort="100" lower="-0.349065850399" upper="0.349065850399" velocity="5"/>
    <!-- effort="100" velocity="5" -->
  </joint>
  <link name="right_middle_abd_link">
    <inertial>
      <origin rpy="0 0 0" xyz="0 0 0"/>
      <mass value="0.5"/>
      <inertia ixx="0" ixy="0" ixz="0" iyy="0" iyz="0" izz="0"/>
    </inertial>
  </link>
  <joint name="right_middle_inner_joint" type="revolute">
    <!-- coincident with abd_joint, rotated of 90 degrees along x -->
    <origin rpy="1.57079632679 0 0" xyz="0 0 0"/>
    <parent link="right_middle_abd_link"/>
    <!-- <parent joint="${name}_abd_joint"/> -->
    <child link="right_middle_proximal_link"/>
    <axis xyz="0 0 1"/>
    <dynamics damping="1"/>
    <limit effort="100" lower="0.10471975512" upper="0.10471975512" velocity="5"/>
    <!-- effort="100" velocity="5" -->
  </joint>
  <link name="right_middle_proximal_link">
    <inertial>
      <origin rpy="0 0 0" xyz="0 0 0"/>
      <mass value="0.044370598"/>
      <!-- using inertia wrt ACS0 (joint frame) - to be changed if baricentrical is needed -->
      <inertia ixx="4.5592704e-06" ixy="9.0783105e-07" ixz="-9.399771e-07" iyy="4.9045259e-05" iyz="1.7052714e-08" izz="5.0524234e-05"/>
    </inertial>
    <visual>
      <origin rpy="0 0 0" xyz="0 0 0"/>
      <geometry>
        <mesh filename="meshes/proximal.stl"/>
      </geometry>
      <material name="DLR/LightGrey"/>
    </visual>
    <collision>
      <origin rpy="0 0 0" xyz="0 0 0"/>
      <geometry>
        <mesh filename="meshes/proximal.stl"/>
      </geometry>
    </collision>
  </link>
  <joint name="right_middle_outer1_joint" type="revolute">
    <origin rpy="0 0 0" xyz="0.055 0 0"/>
    <parent link="right_middle_proximal_link"/>
    <child link="right_middle_medial_link"/>
    <axis xyz="0 0 1"/>
    <dynamics damping="1"/>
    <limit effort="100" lower="1.308996939" upper="1.308996939" velocity="5"/>
    <!-- effort="100" velocity="5" -->
  </joint>
  <link name="right_middle_medial_link">
    <inertial>
      <origin rpy="0 0 0" xyz="0 0 0"/>
      <mass value="0.027110192"/>
      <!-- using inertia wrt ACS0 (joint frame) - to be changed if baricentrical is needed -->
      <inertia ixx="2.2900229e-06" ixy="4.0604622e-07" ixz="1.4362094e-07" iyy="4.2155489e-06" iyz="-4.3115648e-08" izz="4.4292927e-06"/>
    </inertial>
    <visual>
      <origin rpy="0 0 0" xyz="0 0 0"/>
      <geometry>
        <mesh filename="meshes/medial.stl"/>
      </geometry>
      <material name="DLR/LightGrey"/>
    </visual>
    <collision>
      <origin rpy="0 0 0" xyz="0 0 0"/>
      <geometry>
        <mesh filename="meshes/medial.stl"/>
      </geometry>
    </collision>
  </link>
  <joint name="right_middle_outer2_joint" type="revolute">
    <origin rpy="0 0 -1.57079632679" xyz="0.025 0 0"/>
    <parent link="right_middle_medial_link"/>
    <child link="right_middle_distal_link"/>
    <axis xyz="0 0 1"/>
    <dynamics damping="1"/>
    <limit effort="100" lower="1.308996939" upper="1.308996939" velocity="5"/>
    <!-- effort="100" velocity="5" -->
  </joint>
  <link name="right_middle_distal_link">
    <inertial>
      <origin rpy="0 0 0" xyz="0 0 0"/>
      <mass value="0.018179709"/>
      <!-- using inertia wrt ACS0 (joint frame) - to be changed if baricentrical is needed -->
      <inertia ixx="2.5867271e-06" ixy="1.5840536e-07" ixz="-7.8205885e-10" iyy="8.4596248e-07" iyz="-4.8358115e-09" izz="2.5838485e-06"/>
    </inertial>
    <visual>
      <origin rpy="0 0 0" xyz="0 0 0"/>
      <geometry>
        <mesh filename="meshes/distal.stl"/>
      </geometry>
      <material name="DLR/LightGrey"/>
    </visual>
    <collision>
      <origin rpy="0 0 0" xyz="0 0 0"/>
      <geometry>
        <mesh filename="meshes/distal.stl"/>
      </geometry>
    </collision>
  </link>
  <joint name="right_ring_abd_joint" type="revolute">
    <origin rpy="-3.05433 -1.57079632679 0" xyz="-0.002529881 -0.016800135 0.114043545"/>
    <parent link="right_palm_link"/>
    <!-- <child joint="${name}_inner_joint"/> -->
    <child link="right_ring_abd_link"/>
    <axis xyz="0 0 1"/>
    <dynamics damping="1"/>
    <limit effort="100" lower="-0.349065850399" upper="0.349065850399" velocity="5"/>
    <!-- effort="100" velocity="5" -->
  </joint>
  <link name="right_ring_abd_link">
    <inertial>
      <origin rpy="0 0 0" xyz="0 0 0"/>
      <mass value="0.5"/>
      <inertia ixx="0" ixy="0" ixz="0" iyy="0" iyz="0" izz="0"/>
    </inertial>
  </link>
  <joint name="right_ring_inner_joint" type="revolute">
    <!-- coincident with abd_joint, rotated of 90 degrees along x -->
    <origin rpy="1.57079632679 0 0" xyz="0 0 0"/>
    <parent link="right_ring_abd_link"/>
    <!-- <parent joint="${name}_abd_joint"/> -->
    <child link="right_ring_proximal_link"/>
    <axis xyz="0 0 1"/>
    <dynamics damping="1"/>
    <limit effort="100" lower="0.10471975512" upper="0.10471975512" velocity="5"/>
    <!-- effort="100" velocity="5" -->
  </joint>
  <link name="right_ring_proximal_link">
    <inertial>
      <origin rpy="0 0 0" xyz="0 0 0"/>
      <mass value="0.044370598"/>
      <!-- using inertia wrt ACS0 (joint frame) - to be changed if baricentrical is needed -->
      <inertia ixx="4.5592704e-06" ixy="9.0783105e-07" ixz="-9.399771e-07" iyy="4.9045259e-05" iyz="1.7052714e-08" izz="5.0524234e-05"/>
    </inertial>
    <visual>
      <origin rpy="0 0 0" xyz="0 0 0"/>
      <geometry>
        <mesh filename="meshes/proximal.stl"/>
      </geometry>
      <material name="DLR/LightGrey"/>
    </visual>
    <collision>
      <origin rpy="0 0 0" xyz="0 0 0"/>
      <geometry>
        <mesh filename="meshes/proximal.stl"/>
      </geometry>
    </collision>
  </link>
  <joint name="right_ring_outer1_joint" type="revolute">
    <origin rpy="0 0 0" xyz="0.055 0 0"/>
    <parent link="right_ring_proximal_link"/>
    <child link="right_ring_medial_link"/>
    <axis xyz="0 0 1"/>
    <dynamics damping="1"/>
    <limit effort="100" lower="1.308996939" upper="1.308996939" velocity="5"/>
    <!-- effort="100" velocity="5" -->
  </joint>
  <link name="right_ring_medial_link">
    <inertial>
      <origin rpy="0 0 0" xyz="0 0 0"/>
      <mass value="0.027110192"/>
      <!-- using inertia wrt ACS0 (joint frame) - to be changed if baricentrical is needed -->
      <inertia ixx="2.2900229e-06" ixy="4.0604622e-07" ixz="1.4362094e-07" iyy="4.2155489e-06" iyz="-4.3115648e-08" izz="4.4292927e-06"/>
    </inertial>
    <visual>
      <origin rpy="0 0 0" xyz="0 0 0"/>
      <geometry>
        <mesh filename="meshes/medial.stl"/>
      </geometry>
      <material name="DLR/LightGrey"/>
    </visual>
    <collision>
      <origin rpy="0 0 0" xyz="0 0 0"/>
      <geometry>
        <mesh filename="meshes/medial.stl"/>
      </geometry>
    </collision>
  </link>
  <joint name="right_ring_outer2_joint" type="revolute">
    <origin rpy="0 0 -1.57079632679" xyz="0.025 0 0"/>
    <parent link="right_ring_medial_link"/>
    <child link="right_ring_distal_link"/>
    <axis xyz="0 0 1"/>
    <dynamics damping="1"/>
    <limit effort="100" lower="1.308996939" upper="1.308996939" velocity="5"/>
    <!-- effort="100" velocity="5" -->
  </joint>
  <link name="right_ring_distal_link">
    <inertial>
      <origin rpy="0 0 0" xyz="0 0 0"/>
      <mass value="0.018179709"/>
      <!-- using inertia wrt ACS0 (joint frame) - to be changed if baricentrical is needed -->
      <inertia ixx="2.5867271e-06" ixy="1.5840536e-07" ixz="-7.8205885e-10" iyy="8.4596248e-07" iyz="-4.8358115e-09" izz="2.5838485e-06"/>
    </inertial>
    <visual>
      <origin rpy="0 0 0" xyz="0 0 0"/>
      <geometry>
        <mesh filename="meshes/distal.stl"/>
      </geometry>
      <material name="DLR/LightGrey"/>
    </visual>
    <collision>
      <origin rpy="0 0 0" xyz="0 0 0"/>
      <geometry>
        <mesh filename="meshes/distal.stl"/>
      </geometry>
    </collision>
  </link>
  <joint name="right_pinky_abd_joint" type="revolute">
    <origin rpy="-2.96706 -1.57079632679 0" xyz="0.000971571 -0.043396306 0.095043545"/>
    <parent link="right_palm_link"/>
    <!-- <child joint="${name}_inner_joint"/> -->
    <child link="right_pinky_abd_link"/>
    <axis xyz="0 0 1"/>
    <dynamics damping="1"/>
    <limit effort="100" lower="-0.349065850399" upper="0.349065850399" velocity="5"/>
    <!-- effort="100" velocity="5" -->
  </joint>
  <link name="right_pinky_abd_link">
    <inertial>
      <origin rpy="0 0 0" xyz="0 0 0"/>
      <mass value="0.5"/>
      <inertia ixx="0" ixy="0" ixz="0" iyy="0" iyz="0" izz="0"/>
    </inertial>
  </link>
  <joint name="right_pinky_inner_joint" type="revolute">
    <!-- coincident with abd_joint, rotated of 90 degrees along x -->
    <origin rpy="1.57079632679 0 0" xyz="0 0 0"/>
    <parent link="right_pinky_abd_link"/>
    <!-- <parent joint="${name}_abd_joint"/> -->
    <child link="right_pinky_proximal_link"/>
    <axis xyz="0 0 1"/>
    <dynamics damping="1"/>
    <limit effort="100" lower="0.10471975512" upper="0.10471975512" velocity="5"/>
    <!-- effort="100" velocity="5" -->
  </joint>
  <link name="right_pinky_proximal_link">
    <inertial>
      <origin rpy="0 0 0" xyz="0 0 0"/>
      <mass value="0.044370598"/>
      <!-- using inertia wrt ACS0 (joint frame) - to be changed if baricentrical is needed -->
      <inertia ixx="4.5592704e-06" ixy="9.0783105e-07" ixz="-9.399771e-07" iyy="4.9045259e-05" iyz="1.7052714e-08" izz="5.0524234e-05"/>
    </inertial>
    <visual>
      <origin rpy="0 0 0" xyz="0 0 0"/>
      <geometry>
        <mesh filename="meshes/proximal.stl"/>
      </geometry>
      <material name="DLR/LightGrey"/>
    </visual>
    <collision>
      <origin rpy="0 0 0" xyz="0 0 0"/>
      <geometry>
        <mesh filename="meshes/proximal.stl"/>
      </geometry>
    </collision>
  </link>
  <joint name="right_pinky_outer1_joint" type="revolute">
    <origin rpy="0 0 0" xyz="0.055 0 0"/>
    <parent link="right_pinky_proximal_link"/>
    <child link="right_pinky_medial_link"/>
    <axis xyz="0 0 1"/>
    <dynamics damping="1"/>
    <limit effort="100" lower="1.308996939" upper="1.308996939" velocity="5"/>
    <!-- effort="100" velocity="5" -->
  </joint>
  <link name="right_pinky_medial_link">
    <inertial>
      <origin rpy="0 0 0" xyz="0 0 0"/>
      <mass value="0.027110192"/>
      <!-- using inertia wrt ACS0 (joint frame) - to be changed if baricentrical is needed -->
      <inertia ixx="2.2900229e-06" ixy="4.0604622e-07" ixz="1.4362094e-07" iyy="4.2155489e-06" iyz="-4.3115648e-08" izz="4.4292927e-06"/>
    </inertial>
    <visual>
      <origin rpy="0 0 0" xyz="0 0 0"/>
      <geometry>
        <mesh filename="meshes/medial.stl"/>
      </geometry>
      <material name="DLR/LightGrey"/>
    </visual>
    <collision>
      <origin rpy="0 0 0" xyz="0 0 0"/>
      <geometry>
        <mesh filename="meshes/medial.stl"/>
      </geometry>
    </collision>
  </link>
  <joint name="right_pinky_outer2_joint" type="revolute">
    <origin rpy="0 0 -1.57079632679" xyz="0.025 0 0"/>
    <parent link="right_pinky_medial_link"/>
    <child link="right_pinky_distal_link"/>
    <axis xyz="0 0 1"/>
    <dynamics damping="1"/>
    <limit effort="100" lower="1.308996939" upper="1.308996939" velocity="5"/>
    <!-- effort="100" velocity="5" -->
  </joint>
  <link name="right_pinky_distal_link">
    <inertial>
      <origin rpy="0 0 0" xyz="0 0 0"/>
      <mass value="0.018179709"/>
      <!-- using inertia wrt ACS0 (joint frame) - to be changed if baricentrical is needed -->
      <inertia ixx="2.5867271e-06" ixy="1.5840536e-07" ixz="-7.8205885e-10" iyy="8.4596248e-07" iyz="-4.8358115e-09" izz="2.5838485e-06"/>
    </inertial>
    <visual>
      <origin rpy="0 0 0" xyz="0 0 0"/>
      <geometry>
        <mesh filename="meshes/distal.stl"/>
      </geometry>
      <material name="DLR/LightGrey"/>
    </visual>
    <collision>
      <origin rpy="0 0 0" xyz="0 0 0"/>
      <geometry>
        <mesh filename="meshes/distal.stl"/>
      </geometry>
    </collision>
  </link>
  <!--
  <transmission name="thumb_abd_trans" type="pr2_mechanism_model/SimpleTransmission">
    <actuator name="thumb_abd_motor"/>
    <joint name="thumb_abd_joint"/>
    <mechanicalReduction>1</mechanicalReduction>
  </transmission>
  <transmission name="thumb_inner_trans" type="pr2_mechanism_model/SimpleTransmission">
    <actuator name="thumb_inner_motor"/>
    <joint name="thumb_inner_joint"/>
    <mechanicalReduction>1</mechanicalReduction>
  </transmission>
  <transmission name="thumb_outer1_trans" type="pr2_mechanism_model/SimpleTransmission">
    <actuator name="thumb_outer1_motor"/>
    <joint name="thumb_outer1_joint"/>
    <mechanicalReduction>1</mechanicalReduction>
  </transmission>
  <transmission name="thumb_outer2_trans" type="pr2_mechanism_model/SimpleTransmission">
    <actuator name="thumb_outer2_motor"/>
    <joint name="thumb_outer2_joint"/>
    <mechanicalReduction>1</mechanicalReduction>
  </transmission>
  <transmission name="index_abd_trans" type="pr2_mechanism_model/SimpleTransmission">
    <actuator name="index_abd_motor"/>
    <joint name="index_abd_joint"/>
    <mechanicalReduction>1</mechanicalReduction>
  </transmission>
  <transmission name="index_inner_trans" type="pr2_mechanism_model/SimpleTransmission">
    <actuator name="index_inner_motor"/>
    <joint name="index_inner_joint"/>
    <mechanicalReduction>1</mechanicalReduction>
  </transmission>
  <transmission name="index_outer1_trans" type="pr2_mechanism_model/SimpleTransmission">
    <actuator name="index_outer1_motor"/>
    <joint name="index_outer1_joint"/>
    <mechanicalReduction>1</mechanicalReduction>
  </transmission>
  <transmission name="index_outer2_trans" type="pr2_mechanism_model/SimpleTransmission">
    <actuator name="index_outer2_motor"/>
    <joint name="index_outer2_joint"/>
    <mechanicalReduction>1</mechanicalReduction>
  </transmission>
  <transmission name="middle_abd_trans" type="pr2_mechanism_model/SimpleTransmission">
    <actuator name="middle_abd_motor"/>
    <joint name="middle_abd_joint"/>
    <mechanicalReduction>1</mechanicalReduction>
  </transmission>
  <transmission name="middle_inner_trans" type="pr2_mechanism_model/SimpleTransmission">
    <actuator name="middle_inner_motor"/>
    <joint name="middle_inner_joint"/>
    <mechanicalReduction>1</mechanicalReduction>
  </transmission>
  <transmission name="middle_outer1_trans" type="pr2_mechanism_model/SimpleTransmission">
    <actuator name="middle_outer1_motor"/>
    <joint name="middle_outer1_joint"/>
    <mechanicalReduction>1</mechanicalReduction>
  </transmission>
  <transmission name="middle_outer2_trans" type="pr2_mechanism_model/SimpleTransmission">
    <actuator name="middle_outer2_motor"/>
    <joint name="middle_outer2_joint"/>
    <mechanicalReduction>1</mechanicalReduction>
  </transmission>
  <transmission name="ring_abd_trans" type="pr2_mechanism_model/SimpleTransmission">
    <actuator name="ring_abd_motor"/>
    <joint name="ring_abd_joint"/>
    <mechanicalReduction>1</mechanicalReduction>
  </transmission>
  <transmission name="ring_inner_trans" type="pr2_mechanism_model/SimpleTransmission">
    <actuator name="ring_inner_motor"/>
    <joint name="ring_inner_joint"/>
    <mechanicalReduction>1</mechanicalReduction>
  </transmission>
  <transmission name="ring_outer1_trans" type="pr2_mechanism_model/SimpleTransmission">
    <actuator name="ring_outer1_motor"/>
    <joint name="ring_outer1_joint"/>
    <mechanicalReduction>1</mechanicalReduction>
  </transmission>
  <transmission name="ring_outer2_trans" type="pr2_mechanism_model/SimpleTransmission">
    <actuator name="ring_outer2_motor"/>
    <joint name="ring_outer2_joint"/>
    <mechanicalReduction>1</mechanicalReduction>
  </transmission>
  <transmission name="pinky_abd_trans" type="pr2_mechanism_model/SimpleTransmission">
    <actuator name="pinky_abd_motor"/>
    <joint name="pinky_abd_joint"/>
    <mechanicalReduction>1</mechanicalReduction>
  </transmission>
  <transmission name="pinky_inner_trans" type="pr2_mechanism_model/SimpleTransmission">
    <actuator name="pinky_inner_motor"/>
    <joint name="pinky_inner_joint"/>
    <mechanicalReduction>1</mechanicalReduction>
  </transmission>
  <transmission name="pinky_outer1_trans" type="pr2_mechanism_model/SimpleTransmission">
    <actuator name="pinky_outer1_motor"/>
    <joint name="pinky_outer1_joint"/>
    <mechanicalReduction>1</mechanicalReduction>
  </transmission>
  <transmission name="pinky_outer2_trans" type="pr2_mechanism_model/SimpleTransmission">
    <actuator name="pinky_outer2_motor"/>
    <joint name="pinky_outer2_joint"/>
    <mechanicalReduction>1</mechanicalReduction>
  </transmission>
-->
</robot>
