<robot name="robot">

    <link name="base_link">
        <visual>
            <geometry>
                <cylinder length="0.05" radius="0.8"/>
            </geometry>
            <material name="red">
                <color rgba="0.8 0 0 0.6"/>
            </material>
            <origin rpy="0 0 0" xyz="0. 0 0"/>
        </visual>
        <collision>
            <geometry>
                <cylinder length="0.05" radius="0.8"/>
            </geometry>
            <origin rpy="0 0 0" xyz="0. 0 0"/>
        </collision>
        <inertial>
            <mass value="1."/>
            <inertia ixx="0.1" ixy="0.0" ixz="0.0" iyy="0.1" iyz="0.0" izz="0.1"/>
        </inertial>
    </link>
    
    <link name="f1_link1">
        <visual>
            <geometry>
                <capsule length="0.2" radius="0.05"/>
            </geometry>
            <material name="red">
                <color rgba="0.8 0 0 1"/>
            </material>
            <origin rpy="0 0 0" xyz="0 0 0.1"/>
        </visual>
        <collision>
            <geometry>
                <capsule length="0.2" radius="0.05"/>
            </geometry>
            <origin rpy="0 0 0" xyz="0 0 0.1"/>
        </collision>
        <inertial>
            <mass value="1."/>
            <inertia ixx="1.0" ixy="0.0" ixz="0.0" iyy="1.0" iyz="0.0" izz="1.0"/>
        </inertial>
    </link>
    
    <link name="f1_link2">
        <visual>
            <geometry>
                <capsule length="0.5" radius="0.05"/>
            </geometry>
            <material name="green">
                <color rgba="0 0.8 0 1"/>
            </material>
            <origin rpy="0 0 0" xyz="0 0 0.25"/>
        </visual>
        <collision>
            <geometry>
                <capsule length="0.5" radius="0.05"/>
            </geometry>
            <origin rpy="0 0 0" xyz="0 0 0.25"/>
        </collision>
        <inertial>
            <mass value="1."/>
            <inertia ixx="1.0" ixy="0.0" ixz="0.0" iyy="1.0" iyz="0.0" izz="1.0"/>
        </inertial>
    </link>

    <link name="f1_link3">
        <visual>
            <geometry>
                <capsule length="0.5" radius="0.05"/>
            </geometry>
            <material name="blue">
                <color rgba="0 0 0.8 1"/>
            </material>
            <origin rpy="0 0 0" xyz="0 0 0.25"/>
        </visual>
        <collision>
            <geometry>
                <capsule length="0.5" radius="0.05"/>
            </geometry>
            <origin rpy="0 0 0" xyz="0 0 0.25"/>
        </collision>
        <inertial>
            <mass value="1."/>
            <inertia ixx="1.0" ixy="0.0" ixz="0.0" iyy="1.0" iyz="0.0" izz="1.0"/>
        </inertial>
    </link>

    <link name="f1_eePoint">
        <visual>
            <geometry>
                <!--<sphere  radius="0.054"/>-->
                <capsule length="0.08" radius="0.05"/>
            </geometry>
            <material name="grey">
                <color rgba="0.5 0.5 0.5 1"/>
            </material>
            <origin rpy="0 1.576, 0." xyz="0 0 0.0"/>
        </visual>
        <collision>
            <geometry>
                <!--<sphere radius="0.054"/>-->
                <capsule length="0.08" radius="0.05"/>
            </geometry>
            <origin rpy="0 1.576, 0." xyz="0 0 0.0"/>
        </collision>
        <inertial>
            <mass value="0.001"/>
            <inertia ixx="1.0" ixy="0.0" ixz="0.0" iyy="1.0" iyz="0.0" izz="1.0"/>
        </inertial>
    </link>

    <link name="f2_link1">
        <visual>
            <geometry>
                <capsule length="0.2" radius="0.05"/>
            </geometry>
            <material name="red">
                <color rgba="0.8 0 0 1"/>
            </material>
            <origin rpy="0 0 0" xyz="0 0 0.1"/>
        </visual>
        <collision>
            <geometry>
                <capsule length="0.2" radius="0.05"/>
            </geometry>
            <origin rpy="0 0 0" xyz="0 0 0.1"/>
        </collision>
        <inertial>
            <mass value="1."/>
            <inertia ixx="1.0" ixy="0.0" ixz="0.0" iyy="1.0" iyz="0.0" izz="1.0"/>
        </inertial>
    </link>
    
    <link name="f2_link2">
        <visual>
            <geometry>
                <capsule length="0.5" radius="0.05"/>
            </geometry>
            <material name="green">
                <color rgba="0 0.8 0 1"/>
            </material>
            <origin rpy="0 0 0" xyz="0 0 0.25"/>
        </visual>
        <collision>
            <geometry>
                <capsule length="0.5" radius="0.05"/>
            </geometry>
            <origin rpy="0 0 0" xyz="0 0 0.25"/>
        </collision>
        <inertial>
            <mass value="1."/>
            <inertia ixx="1.0" ixy="0.0" ixz="0.0" iyy="1.0" iyz="0.0" izz="1.0"/>
        </inertial>
    </link>

    <link name="f2_link3">
        <visual>
            <geometry>
                <capsule length="0.5" radius="0.05"/>
            </geometry>
            <material name="blue">
                <color rgba="0 0 0.8 1"/>
            </material>
            <origin rpy="0 0 0" xyz="0 0 0.25"/>
        </visual>
        <collision>
            <geometry>
                <capsule length="0.5" radius="0.05"/>
            </geometry>
            <origin rpy="0 0 0" xyz="0 0 0.25"/>
        </collision>
        <inertial>
            <mass value="1."/>
            <inertia ixx="1.0" ixy="0.0" ixz="0.0" iyy="1.0" iyz="0.0" izz="1.0"/>
        </inertial>
    </link>

    <link name="f2_eePoint">
        <visual>
            <geometry>
                <!--<sphere  radius="0.054"/>-->
                <capsule length="0.08" radius="0.05"/>
            </geometry>
            <material name="grey">
                <color rgba="0.5 0.5 0.5 1"/>
            </material>
            <origin rpy="0 1.576, 0." xyz="0 0 0.0"/>
        </visual>
        <collision>
            <geometry>
                <!--<sphere radius="0.054"/>-->
                <capsule length="0.08" radius="0.05"/>
            </geometry>
            <origin rpy="0 1.576, 0." xyz="0 0 0.0"/>
        </collision>
        <inertial>
            <mass value="0.001"/>
            <inertia ixx="1.0" ixy="0.0" ixz="0.0" iyy="1.0" iyz="0.0" izz="1.0"/>
        </inertial>
    </link>

    <link name="f3_link1">
        <visual>
            <geometry>
                <capsule length="0.2" radius="0.05"/>
            </geometry>
            <material name="red">
                <color rgba="0.8 0 0 1"/>
            </material>
            <origin rpy="0 0 0" xyz="0 0 0.1"/>
        </visual>
        <collision>
            <geometry>
                <capsule length="0.2" radius="0.05"/>
            </geometry>
            <origin rpy="0 0 0" xyz="0 0 0.1"/>
        </collision>
        <inertial>
            <mass value="1."/>
            <inertia ixx="1.0" ixy="0.0" ixz="0.0" iyy="1.0" iyz="0.0" izz="1.0"/>
        </inertial>
    </link>
    
    <link name="f3_link2">
        <visual>
            <geometry>
                <capsule length="0.5" radius="0.05"/>
            </geometry>
            <material name="green">
                <color rgba="0 0.8 0 1"/>
            </material>
            <origin rpy="0 0 0" xyz="0 0 0.25"/>
        </visual>
        <collision>
            <geometry>
                <capsule length="0.5" radius="0.05"/>
            </geometry>
            <origin rpy="0 0 0" xyz="0 0 0.25"/>
        </collision>
        <inertial>
            <mass value="1."/>
            <inertia ixx="1.0" ixy="0.0" ixz="0.0" iyy="1.0" iyz="0.0" izz="1.0"/>
        </inertial>
    </link>

    <link name="f3_link3">
        <visual>
            <geometry>
                <capsule length="0.5" radius="0.05"/>
            </geometry>
            <material name="blue">
                <color rgba="0 0 0.8 1"/>
            </material>
            <origin rpy="0 0 0" xyz="0 0 0.25"/>
        </visual>
        <collision>
            <geometry>
                <capsule length="0.5" radius="0.05"/>
            </geometry>
            <origin rpy="0 0 0" xyz="0 0 0.25"/>
        </collision>
        <inertial>
            <mass value="1."/>
            <inertia ixx="1.0" ixy="0.0" ixz="0.0" iyy="1.0" iyz="0.0" izz="1.0"/>
        </inertial>
    </link>

    <link name="f3_eePoint">
        <visual>
            <geometry>
                <!--<sphere  radius="0.054"/>-->
                <capsule length="0.08" radius="0.05"/>
            </geometry>
            <material name="grey">
                <color rgba="0.5 0.5 0.5 1"/>
            </material>
            <origin rpy="0 1.576, 0." xyz="0 0 0.0"/>
        </visual>
        <collision>
            <geometry>
                <!--<sphere radius="0.054"/>-->
                <capsule length="0.08" radius="0.05"/>
            </geometry>
            <origin rpy="0 1.576, 0." xyz="0 0 0.0"/>
        </collision>
        <inertial>
            <mass value="0.001"/>
            <inertia ixx="1.0" ixy="0.0" ixz="0.0" iyy="1.0" iyz="0.0" izz="1.0"/>
        </inertial>
    </link>

    <link name="f4_link1">
        <visual>
            <geometry>
                <capsule length="0.2" radius="0.05"/>
            </geometry>
            <material name="red">
                <color rgba="0.8 0 0 1"/>
            </material>
            <origin rpy="0 0 0" xyz="0 0 0.1"/>
        </visual>
        <collision>
            <geometry>
                <capsule length="0.2" radius="0.05"/>
            </geometry>
            <origin rpy="0 0 0" xyz="0 0 0.1"/>
        </collision>
        <inertial>
            <mass value="1."/>
            <inertia ixx="1.0" ixy="0.0" ixz="0.0" iyy="1.0" iyz="0.0" izz="1.0"/>
        </inertial>
    </link>
    
    <link name="f4_link2">
        <visual>
            <geometry>
                <capsule length="0.5" radius="0.05"/>
            </geometry>
            <material name="green">
                <color rgba="0 0.8 0 1"/>
            </material>
            <origin rpy="0 0 0" xyz="0 0 0.25"/>
        </visual>
        <collision>
            <geometry>
                <capsule length="0.5" radius="0.05"/>
            </geometry>
            <origin rpy="0 0 0" xyz="0 0 0.25"/>
        </collision>
        <inertial>
            <mass value="1."/>
            <inertia ixx="1.0" ixy="0.0" ixz="0.0" iyy="1.0" iyz="0.0" izz="1.0"/>
        </inertial>
    </link>

    <link name="f4_link3">
        <visual>
            <geometry>
                <capsule length="0.5" radius="0.05"/>
            </geometry>
            <material name="blue">
                <color rgba="0 0 0.8 1"/>
            </material>
            <origin rpy="0 0 0" xyz="0 0 0.25"/>
        </visual>
        <collision>
            <geometry>
                <capsule length="0.5" radius="0.05"/>
            </geometry>
            <origin rpy="0 0 0" xyz="0 0 0.25"/>
        </collision>
        <inertial>
            <mass value="1."/>
            <inertia ixx="1.0" ixy="0.0" ixz="0.0" iyy="1.0" iyz="0.0" izz="1.0"/>
        </inertial>
    </link>

    <link name="f4_eePoint">
        <visual>
            <geometry>
                <!--<sphere  radius="0.054"/>-->
                <capsule length="0.08" radius="0.05"/>
            </geometry>
            <material name="grey">
                <color rgba="0.5 0.5 0.5 1"/>
            </material>
            <origin rpy="0 1.576, 0." xyz="0 0 0.0"/>
        </visual>
        <collision>
            <geometry>
                <!--<sphere radius="0.054"/>-->
                <capsule length="0.08" radius="0.05"/>
            </geometry>
            <origin rpy="0 1.576, 0." xyz="0 0 0.0"/>
        </collision>
        <inertial>
            <mass value="0.001"/>
            <inertia ixx="1.0" ixy="0.0" ixz="0.0" iyy="1.0" iyz="0.0" izz="1.0"/>
        </inertial>
    </link>

    <joint name="f1_joint1" type="revolute">
        <parent link="base_link"/>
        <child link="f1_link1"/>
        <origin xyz="0.75 0 0." rpy="0 0 0" />
        <axis xyz = "1 0 0" />
        <dynamics damping="0.0" friction="0.0"/>
        <limit effort="300" velocity="1.0" lower="-0.84819" upper="0.84819" />
    </joint>

    <joint name="f1_joint2" type="revolute">
        <parent link="f1_link1"/>
        <child link="f1_link2"/>
        <origin xyz="0. 0 0.2" rpy="0 0 0" />
        <axis xyz = "0 1 0" />
        <dynamics damping="0.0" friction="0.0"/>
        <limit effort="300" velocity="1.0" lower="-1.576" upper="1.576" />
    </joint>

    <joint name="f1_joint3" type="revolute">
        <parent link="f1_link2"/>
        <child link="f1_link3"/>
        <origin xyz="0. 0 0.5" rpy="0 0 0" />
        <axis xyz = "0 1 0" />
        <dynamics damping="0.0" friction="0.0"/>
        <limit effort="300" velocity="1.0" lower="-2.97019" upper="2.900" />
    </joint>

    <joint name="f1_joint4" type="fixed">
        <parent link="f1_link3"/>
        <child link="f1_eePoint"/>
        <origin xyz="0. 0. 0.5"/>
    </joint>

    <joint name="f2_joint1" type="revolute">
        <parent link="base_link"/>
        <child link="f2_link1"/>
        <origin xyz="0 0.75 0" rpy="0 0 1.5707963267948966" />
        <axis xyz = "1 0 0" />
        <dynamics damping="0.0" friction="0.0"/>
        <limit effort="300" velocity="1.0" lower="-0.84819" upper="0.84819" />
    </joint>

    <joint name="f2_joint2" type="revolute">
        <parent link="f2_link1"/>
        <child link="f2_link2"/>
        <origin xyz="0 0 0.2" rpy="0 0 0" />
        <axis xyz = "0 1 0" />
        <dynamics damping="0.0" friction="0.0"/>
        <limit effort="300" velocity="1.0" lower="-1.21619" upper="1.21619" />
    </joint>

    <joint name="f2_joint3" type="revolute">
        <parent link="f2_link2"/>
        <child link="f2_link3"/>
        <origin xyz="0 0 0.5" rpy="0 0 0" />
        <axis xyz = "0 1 0" />
        <dynamics damping="0.0" friction="0.0"/>
        <limit effort="300" velocity="1.0" lower="-2.97019" upper="2.900" />
    </joint>

    <joint name="f2_joint4" type="fixed">
        <parent link="f2_link3"/>
        <child link="f2_eePoint"/>
        <origin xyz="0. 0. 0.5"/>
    </joint>

    <joint name="f3_joint1" type="revolute">
        <parent link="base_link"/>
        <child link="f3_link1"/>
        <origin xyz="-0.75 0 0" rpy="0 0 3.14159" />
        <axis xyz = "1 0 0" />
        <dynamics damping="0.0" friction="0.0"/>
        <limit effort="300" velocity="1.0" lower="-0.84819" upper="0.84819" />
    </joint>

    <joint name="f3_joint2" type="revolute">
        <parent link="f3_link1"/>
        <child link="f3_link2"/>
        <origin xyz="0 0 0.2" rpy="0 0 0" />
        <axis xyz = "0 1 0" />
        <dynamics damping="0.0" friction="0.0"/>
        <limit effort="300" velocity="1.0" lower="-1.21619" upper="1.21619" />
    </joint>

    <joint name="f3_joint3" type="revolute">
        <parent link="f3_link2"/>
        <child link="f3_link3"/>
        <origin xyz="0 0 0.5" rpy="0 0 0" />
        <axis xyz = "0 1 0" />
        <dynamics damping="0.0" friction="0.0"/>
        <limit effort="300" velocity="1.0" lower="-2.97019" upper="2.900" />
    </joint>

    <joint name="f3_joint4" type="fixed">
        <parent link="f3_link3"/>
        <child link="f3_eePoint"/>
        <origin xyz="0. 0. 0.5"/>
    </joint>

    <joint name="f4_joint1" type="revolute">
        <parent link="base_link"/>
        <child link="f4_link1"/>
        <origin xyz="0 -0.75 0" rpy="0 0 -1.5707963267948966" />
        <axis xyz = "1 0 0" />
        <dynamics damping="0.0" friction="0.0"/>
        <limit effort="300" velocity="1.0" lower="-0.84819" upper="0.84819" />
    </joint>

    <joint name="f4_joint2" type="revolute">
        <parent link="f4_link1"/>
        <child link="f4_link2"/>
        <origin xyz="0 0 0.2" rpy="0 0 0" />
        <axis xyz = "0 1 0" />
        <dynamics damping="0.0" friction="0.0"/>
        <limit effort="300" velocity="1.0" lower="-1.21619" upper="1.21619" />
    </joint>

    <joint name="f4_joint3" type="revolute">
        <parent link="f4_link2"/>
        <child link="f4_link3"/>
        <origin xyz="0 0 0.5" rpy="0 0 0" />
        <axis xyz = "0 1 0" />
        <dynamics damping="0.0" friction="0.0"/>
        <limit effort="300" velocity="1.0" lower="-2.97019" upper="2.900" />
    </joint>

    <joint name="f4_joint4" type="fixed">
        <parent link="f4_link3"/>
        <child link="f4_eePoint"/>
        <origin xyz="0. 0. 0.5"/>
    </joint>  

</robot>