<?xml version="1.0" ?>
<!-- =================================================================================== -->
<!-- |    This document was autogenerated by xacro from human_hand.urdf.xacro          | -->
<!-- |    EDITING THIS FILE BY HAND IS NOT RECOMMENDED                                 | -->
<!-- =================================================================================== -->
<robot name="human_hand">
  <!--
	    HUMAN HAND MODEL v 0.1
	    urdf derived from human Pisa SoftHand
	    author Guillaume Walck, Robert Haschke
	    meshes from GrabCAD, author Joerg Schmit
	    original CAD model available at: https://grabcad.com/library/human-left-hand/
	-->
  <material name="HumanHand/Skin">
    <color rgba="0.802 0.732 0.673 1.0"/>
  </material>
  <link name="glove_base"/>
  <!-- PALM -->
  <joint name="palm_joint" type="fixed">
    <origin rpy="0 0 0" xyz="0 0 0"/>
    <parent link="glove_base"/>
    <child link="palm_link"/>
  </joint>
  <link name="palm_link">
    <visual>
      <geometry>
        <mesh filename="meshes/palm.stl" scale=" 0.001 .001 .001"/>
      </geometry>
      <material name="HumanHand/Skin"/>
    </visual>
<!--     <collision>
      <origin rpy="0 0 0" xyz="0 0 0"/>
      <geometry>
        <mesh filename="meshes/palm.stl"/>
      </geometry>
    </collision> -->
  </link>
  <!-- THUMB AND FINGERS -->
  <!-- KNUCKLE -->
  <joint name="thumb_abduction_joint" type="revolute">
    <origin rpy="0.0 0.624 0" xyz="0.02475 -0.0125 0.0125"/>
    <parent link="palm_link"/>
    <child link="thumb_knuckle_link"/>
    <axis xyz="1 0 0"/>
    <limit effort="100" lower="0.0" upper="1.57079632679" velocity="100"/>
    <dynamics damping="0.0" friction="0.0"/>
  </joint>
  <link name="thumb_knuckle_link">
  </link>
  <!-- PROXIMAL PHALANGE -->
  <joint name="thumb_proximal_joint" type="revolute">
    <origin rpy="0 0 0" xyz="0 0 0"/>
    <parent link="thumb_knuckle_link"/>
    <child link="thumb_proximal_link"/>
    <axis xyz="0 -1 0"/>
    <limit effort="100" lower="0.0" upper="1.57079632679" velocity="100"/>
    <dynamics damping="0.0" friction="0.0"/>
  </joint>
  <link name="thumb_proximal_link">
    <visual>
      <geometry>
        <mesh filename="meshes/thumb_proximal.stl" scale="0.001 0.001 .001"/>
      </geometry>
      <material name="HumanHand/Skin"/>
    </visual>
<!--     <collision>
      <origin rpy="0 0 0" xyz="0 0 0"/>
      <geometry>
        <mesh filename="meshes/thumb_proximal.stl"/>
      </geometry>
    </collision> -->
  </link>
  <!-- MIDDLE PHALANGE -->
  <joint name="thumb_middle_joint" type="revolute">
    <origin rpy="0 0 0" xyz="0 0 0.05415"/>
    <parent link="thumb_proximal_link"/>
    <child link="thumb_middle_link"/>
    <axis xyz="0 -1 0"/>
    <limit effort="100" lower="0.0" upper="1.57079632679" velocity="100"/>
    <dynamics damping="0.0" friction="0.0"/>
  </joint>
  <link name="thumb_middle_link">
    <visual>
      <geometry>
        <mesh filename="meshes/thumb_middle.stl" scale="0.001 0.001 .001"/>
      </geometry>
      <material name="HumanHand/Skin"/>
    </visual>
<!--     <collision>
      <origin rpy="0 0 0" xyz="0 0 0"/>
      <geometry>
        <mesh filename="meshes/thumb_middle.stl"/>
      </geometry>
    </collision> -->
  </link>
  <!-- DISTAL PHALANGE -->
  <joint name="thumb_distal_joint" type="revolute">
    <origin rpy="0 0 0" xyz="0 0 0.03803"/>
    <parent link="thumb_middle_link"/>
    <child link="thumb_distal_link"/>
    <axis xyz="0 -1 0"/>
    <limit effort="100" lower="0.0" upper="1.57079632679" velocity="100"/>
    <dynamics damping="0.0" friction="0.0"/>
  </joint>
  <link name="thumb_distal_link">
    <visual>
      <geometry>
        <mesh filename="meshes/thumb_distal.stl" scale="0.001 0.001 .001"/>
      </geometry>
      <material name="HumanHand/Skin"/>
    </visual>
<!--     <collision>
      <origin rpy="0 0 0" xyz="0 0 0"/>
      <geometry>
        <mesh filename="meshes/thumb_distal.stl"/>
      </geometry>
    </collision> -->
  </link>
  <!-- KNUCKLE -->
  <joint name="index_abduction_joint" type="revolute">
    <origin rpy="0 0 0" xyz="0.02175 -0.002 0.099"/>
    <parent link="palm_link"/>
    <child link="index_knuckle_link"/>
    <axis xyz="0 -1 0"/>
    <limit effort="100" lower="-0.523598775598" upper="0.523598775598" velocity="100"/>
    <dynamics damping="0.0" friction="0.0"/>
  </joint>
  <link name="index_knuckle_link">
  </link>
  <!-- PROXIMAL PHALANGE -->
  <joint name="index_proximal_joint" type="revolute">
    <origin rpy="0 0 0" xyz="0 0 0"/>
    <parent link="index_knuckle_link"/>
    <child link="index_proximal_link"/>
    <axis xyz="1 0 0"/>
    <limit effort="100" lower="0.0" upper="1.57079632679" velocity="100"/>
    <dynamics damping="0.0" friction="0.0"/>
  </joint>
  <link name="index_proximal_link">
    <visual>
      <geometry>
        <mesh filename="meshes/index_proximal.stl" scale="0.001 0.001 .001"/>
      </geometry>
      <material name="HumanHand/Skin"/>
    </visual>
<!--     <collision>
      <origin rpy="0 0 0" xyz="0 0 0"/>
      <geometry>
        <mesh filename="meshes/index_proximal.stl"/>
      </geometry>
    </collision> -->
  </link>
  <!-- MIDDLE PHALANGE -->
  <joint name="index_middle_joint" type="revolute">
    <origin rpy="0 0 0" xyz="0 0 0.046"/>
    <parent link="index_proximal_link"/>
    <child link="index_middle_link"/>
    <axis xyz="1 0 0"/>
    <limit effort="100" lower="0.0" upper="1.57079632679" velocity="100"/>
    <dynamics damping="0.0" friction="0.0"/>
  </joint>
  <link name="index_middle_link">
    <visual>
      <geometry>
        <mesh filename="meshes/index_middle.stl" scale="0.001 0.001 .001"/>
      </geometry>
      <material name="HumanHand/Skin"/>
    </visual>
<!--     <collision>
      <origin rpy="0 0 0" xyz="0 0 0"/>
      <geometry>
        <mesh filename="meshes/index_middle.stl"/>
      </geometry>
    </collision> -->
  </link>
  <!-- DISTAL PHALANGE -->
  <joint name="index_distal_joint" type="revolute">
    <origin rpy="0 0 0" xyz="0 0 0.027"/>
    <parent link="index_middle_link"/>
    <child link="index_distal_link"/>
    <axis xyz="1 0 0"/>
    <limit effort="100" lower="0.0" upper="1.57079632679" velocity="100"/>
    <dynamics damping="0.0" friction="0.0"/>
  </joint>
  <link name="index_distal_link">
    <visual>
      <geometry>
        <mesh filename="meshes/index_distal.stl" scale="0.001 0.001 .001"/>
      </geometry>
      <material name="HumanHand/Skin"/>
    </visual>
<!--     <collision>
      <origin rpy="0 0 0" xyz="0 0 0"/>
      <geometry>
        <mesh filename="meshes/index_distal.stl"/>
      </geometry>
    </collision> -->
  </link>
  <!-- KNUCKLE -->
  <joint name="middle_abduction_joint" type="revolute">
    <origin rpy="0 0 0" xyz="-0.002 0.0015 0.0955"/>
    <parent link="palm_link"/>
    <child link="middle_knuckle_link"/>
    <axis xyz="0 -1 0"/>
    <limit effort="100" lower="-0.523598775598" upper="0.523598775598" velocity="100"/>
    <dynamics damping="0.0" friction="0.0"/>
  </joint>
  <link name="middle_knuckle_link">
  </link>
  <!-- PROXIMAL PHALANGE -->
  <joint name="middle_proximal_joint" type="revolute">
    <origin rpy="0 0 0" xyz="0 0 0"/>
    <parent link="middle_knuckle_link"/>
    <child link="middle_proximal_link"/>
    <axis xyz="1 0 0"/>
    <limit effort="100" lower="0.0" upper="1.57079632679" velocity="100"/>
    <dynamics damping="0.0" friction="0.0"/>
  </joint>
  <link name="middle_proximal_link">
    <visual>
      <geometry>
        <mesh filename="meshes/middle_proximal.stl" scale="0.001 0.001 .001"/>
      </geometry>
      <material name="HumanHand/Skin"/>
    </visual>
<!--     <collision>
      <origin rpy="0 0 0" xyz="0 0 0"/>
      <geometry>
        <mesh filename="meshes/middle_proximal.stl"/>
      </geometry>
    </collision> -->
  </link>
  <!-- MIDDLE PHALANGE -->
  <joint name="middle_middle_joint" type="revolute">
    <origin rpy="0 0 0" xyz="0 0 0.0495"/>
    <parent link="middle_proximal_link"/>
    <child link="middle_middle_link"/>
    <axis xyz="1 0 0"/>
    <limit effort="100" lower="0.0" upper="1.57079632679" velocity="100"/>
    <dynamics damping="0.0" friction="0.0"/>
  </joint>
  <link name="middle_middle_link">
    <visual>
      <geometry>
        <mesh filename="meshes/middle_middle.stl" scale="0.001 0.001 .001"/>
      </geometry>
      <material name="HumanHand/Skin"/>
    </visual>
<!--     <collision>
      <origin rpy="0 0 0" xyz="0 0 0"/>
      <geometry>
        <mesh filename="meshes/middle_middle.stl"/>
      </geometry>
    </collision> -->
  </link>
  <!-- DISTAL PHALANGE -->
  <joint name="middle_distal_joint" type="revolute">
    <origin rpy="0 0 0" xyz="0 0 0.033"/>
    <parent link="middle_middle_link"/>
    <child link="middle_distal_link"/>
    <axis xyz="1 0 0"/>
    <limit effort="100" lower="0.0" upper="1.57079632679" velocity="100"/>
    <dynamics damping="0.0" friction="0.0"/>
  </joint>
  <link name="middle_distal_link">
    <visual>
      <geometry>
        <mesh filename="meshes/middle_distal.stl" scale="0.001 0.001 .001"/>
      </geometry>
      <material name="HumanHand/Skin"/>
    </visual>
<!--     <collision>
      <origin rpy="0 0 0" xyz="0 0 0"/>
      <geometry>
        <mesh filename="meshes/middle_distal.stl"/>
      </geometry>
    </collision> -->
  </link>
  <!-- KNUCKLE -->
  <joint name="ring_abduction_joint" type="revolute">
    <origin rpy="0 0 0" xyz="-0.02225 0.0010 0.090"/>
    <parent link="palm_link"/>
    <child link="ring_knuckle_link"/>
    <axis xyz="0 -1 0"/>
    <limit effort="100" lower="-0.523598775598" upper="0.523598775598" velocity="100"/>
    <dynamics damping="0.0" friction="0.0"/>
  </joint>
  <link name="ring_knuckle_link">
  </link>
  <!-- PROXIMAL PHALANGE -->
  <joint name="ring_proximal_joint" type="revolute">
    <origin rpy="0 0 0" xyz="0 0 0"/>
    <parent link="ring_knuckle_link"/>
    <child link="ring_proximal_link"/>
    <axis xyz="1 0 0"/>
    <limit effort="100" lower="0.0" upper="1.57079632679" velocity="100"/>
    <dynamics damping="0.0" friction="0.0"/>
  </joint>
  <link name="ring_proximal_link">
    <visual>
      <geometry>
        <mesh filename="meshes/ring_proximal.stl" scale="0.001 0.001 .001"/>
      </geometry>
      <material name="HumanHand/Skin"/>
    </visual>
<!--     <collision>
      <origin rpy="0 0 0" xyz="0 0 0"/>
      <geometry>
        <mesh filename="meshes/ring_proximal.stl"/>
      </geometry>
    </collision> -->
  </link>
  <!-- MIDDLE PHALANGE -->
  <joint name="ring_middle_joint" type="revolute">
    <origin rpy="0 0 0" xyz="0 0 0.048"/>
    <parent link="ring_proximal_link"/>
    <child link="ring_middle_link"/>
    <axis xyz="1 0 0"/>
    <limit effort="100" lower="0.0" upper="1.57079632679" velocity="100"/>
    <dynamics damping="0.0" friction="0.0"/>
  </joint>
  <link name="ring_middle_link">
    <visual>
      <geometry>
        <mesh filename="meshes/ring_middle.stl" scale="0.001 0.001 .001"/>
      </geometry>
      <material name="HumanHand/Skin"/>
    </visual>
<!--     <collision>
      <origin rpy="0 0 0" xyz="0 0 0"/>
      <geometry>
        <mesh filename="meshes/ring_middle.stl"/>
      </geometry>
    </collision> -->
  </link>
  <!-- DISTAL PHALANGE -->
  <joint name="ring_distal_joint" type="revolute">
    <origin rpy="0 0 0" xyz="0 0 0.033"/>
    <parent link="ring_middle_link"/>
    <child link="ring_distal_link"/>
    <axis xyz="1 0 0"/>
    <limit effort="100" lower="0.0" upper="1.57079632679" velocity="100"/>
    <dynamics damping="0.0" friction="0.0"/>
  </joint>
  <link name="ring_distal_link">
    <visual>
      <geometry>
        <mesh filename="meshes/ring_distal.stl" scale="0.001 0.001 .001"/>
      </geometry>
      <material name="HumanHand/Skin"/>
    </visual>
<!--     <collision>
      <origin rpy="0 0 0" xyz="0 0 0"/>
      <geometry>
        <mesh filename="meshes/ring_distal.stl"/>
      </geometry>
    </collision> -->
  </link>
  <!-- KNUCKLE -->
  <joint name="little_abduction_joint" type="revolute">
    <origin rpy="0 0 0" xyz="-0.04175 -0.003 0.079"/>
    <parent link="palm_link"/>
    <child link="little_knuckle_link"/>
    <axis xyz="0 -1 0"/>
    <limit effort="100" lower="-0.523598775598" upper="0.523598775598" velocity="100"/>
    <dynamics damping="0.0" friction="0.0"/>
  </joint>
  <link name="little_knuckle_link">
  </link>
  <!-- PROXIMAL PHALANGE -->
  <joint name="little_proximal_joint" type="revolute">
    <origin rpy="0 0 0" xyz="0 0 0"/>
    <parent link="little_knuckle_link"/>
    <child link="little_proximal_link"/>
    <axis xyz="1 0 0"/>
    <limit effort="100" lower="0.0" upper="1.57079632679" velocity="100"/>
    <dynamics damping="0.0" friction="0.0"/>
  </joint>
  <link name="little_proximal_link">
    <visual>
      <geometry>
        <mesh filename="meshes/little_proximal.stl" scale="0.001 0.001 .001"/>
      </geometry>
      <material name="HumanHand/Skin"/>
    </visual>
<!--     <collision>
      <origin rpy="0 0 0" xyz="0 0 0"/>
      <geometry>
        <mesh filename="meshes/little_proximal.stl"/>
      </geometry>
    </collision> -->
  </link>
  <!-- MIDDLE PHALANGE -->
  <joint name="little_middle_joint" type="revolute">
    <origin rpy="0 0 0" xyz="0 0 0.037"/>
    <parent link="little_proximal_link"/>
    <child link="little_middle_link"/>
    <axis xyz="1 0 0"/>
    <limit effort="100" lower="0.0" upper="1.57079632679" velocity="100"/>
    <dynamics damping="0.0" friction="0.0"/>
  </joint>
  <link name="little_middle_link">
    <visual>
      <geometry>
        <mesh filename="meshes/little_middle.stl" scale="0.001 0.001 .001"/>
      </geometry>
      <material name="HumanHand/Skin"/>
    </visual>
<!--     <collision>
      <origin rpy="0 0 0" xyz="0 0 0"/>
      <geometry>
        <mesh filename="meshes/little_middle.stl"/>
      </geometry>
    </collision> -->
  </link>
  <!-- DISTAL PHALANGE -->
  <joint name="little_distal_joint" type="revolute">
    <origin rpy="0 0 0" xyz="0 0 0.0215"/>
    <parent link="little_middle_link"/>
    <child link="little_distal_link"/>
    <axis xyz="1 0 0"/>
    <limit effort="100" lower="0.0" upper="1.57079632679" velocity="100"/>
    <dynamics damping="0.0" friction="0.0"/>
  </joint>
  <link name="little_distal_link">
    <visual>
      <geometry>
        <mesh filename="meshes/little_distal.stl" scale="0.001 0.001 .001"/>
      </geometry>
      <material name="HumanHand/Skin"/>
    </visual>
<!--     <collision>
      <origin rpy="0 0 0" xyz="0 0 0"/>
      <geometry>
        <mesh filename="meshes/little_distal.stl"/>
      </geometry>
    </collision> -->
  </link>
  <!-- TACTILE MARKERS -->
  <!--
  <tactile data="data[6]" link="index_distal_link" ns="index" topic="TactileGlove" xs="0 4095">
    <geometry>
      <mesh filename="./meshes/taxels/L1/idd.stl" scale="0.00101 0.00101 0.00101"/>
    </geometry>
    <origin xyz="0 0 1e-3"/>
  </tactile>
  <tactile data="data[9]" link="index_distal_link" ns="index" topic="TactileGlove" xs="0 4095">
    <geometry>
      <mesh filename="./meshes/taxels/L1/ido.stl" scale="0.00101 0.00101 0.00101"/>
    </geometry>
    <origin xyz="-0.001 0 0"/>
  </tactile>
  <tactile data="data[8]" link="index_distal_link" ns="index" topic="TactileGlove" xs="0 4095">
    <geometry>
      <mesh filename="./meshes/taxels/L1/idm.stl" scale="0.00101 0.00101 0.00101"/>
    </geometry>
    <origin xyz="0 -1e-3 0"/>
  </tactile>
  <tactile data="data[7]" link="index_distal_link" ns="index" topic="TactileGlove" xs="0 4095">
    <geometry>
      <mesh filename="./meshes/taxels/L1/idi.stl" scale="0.00101 0.00101 0.00101"/>
    </geometry>
    <origin xyz="0.001 0 0"/>
  </tactile>
  <tactile data="data[12]" link="index_middle_link" ns="index" topic="TactileGlove" xs="0 4095">
    <geometry>
      <mesh filename="./meshes/taxels/L1/imo.stl" scale="0.00101 0.00101 0.00101"/>
    </geometry>
    <origin xyz="-0.001 0 0"/>
  </tactile>
  <tactile data="data[11]" link="index_middle_link" ns="index" topic="TactileGlove" xs="0 4095">
    <geometry>
      <mesh filename="./meshes/taxels/L1/imm.stl" scale="0.00101 0.00101 0.00101"/>
    </geometry>
    <origin xyz="0 -1e-3 0"/>
  </tactile>
  <tactile data="data[10]" link="index_middle_link" ns="index" topic="TactileGlove" xs="0 4095">
    <geometry>
      <mesh filename="./meshes/taxels/L1/imi.stl" scale="0.00101 0.00101 0.00101"/>
    </geometry>
    <origin xyz="0.001 0 0"/>
  </tactile>
  <tactile data="data[14]" link="index_proximal_link" ns="index" topic="TactileGlove" xs="0 4095">
    <geometry>
      <mesh filename="./meshes/taxels/L1/ip.stl" scale="0.00101 0.00101 0.00101"/>
    </geometry>
    <origin xyz="0 -1e-3 0"/>
  </tactile>
  <tactile data="data[13]" link="index_proximal_link" ns="index" topic="TactileGlove" xs="0 4095">
    <geometry>
      <mesh filename="./meshes/taxels/L1/ipi.stl" scale="0.00101 0.00101 0.00101"/>
    </geometry>
    <origin xyz="0.001 0 0"/>
  </tactile>
  <tactile data="data[22]" link="middle_proximal_link" ns="middle" topic="TactileGlove" xs="0 4095">
    <geometry>
      <mesh filename="./meshes/taxels/L1/mp.stl" scale="0.00101 0.00101 0.00101"/>
    </geometry>
    <origin xyz="0 -1e-3 0"/>
  </tactile>
  <tactile data="data[30]" link="ring_proximal_link" ns="ring" topic="TactileGlove" xs="0 4095">
    <geometry>
      <mesh filename="./meshes/taxels/L1/rp.stl" scale="0.00101 0.00101 0.00101"/>
    </geometry>
    <origin xyz="0 -1e-3 0"/>
  </tactile>
  <tactile data="data[34]" link="little_distal_link" ns="little" topic="TactileGlove" xs="0 4095">
    <geometry>
      <mesh filename="./meshes/taxels/L1/ldo.stl" scale="0.00101 0.00101 0.00101"/>
    </geometry>
    <origin xyz="-0.001 0 0"/>
  </tactile>
  <tactile data="data[32]" link="little_distal_link" ns="little" topic="TactileGlove" xs="0 4095">
    <geometry>
      <mesh filename="./meshes/taxels/L1/ldi.stl" scale="0.00101 0.00101 0.00101"/>
    </geometry>
    <origin xyz="0.001 0 0"/>
  </tactile>
  <tactile data="data[37]" link="little_middle_link" ns="little" topic="TactileGlove" xs="0 4095">
    <geometry>
      <mesh filename="./meshes/taxels/L1/lmo.stl" scale="0.00101 0.00101 0.00101"/>
    </geometry>
    <origin xyz="-0.001 0 0"/>
  </tactile>
  <tactile data="data[36]" link="little_middle_link" ns="little" topic="TactileGlove" xs="0 4095">
    <geometry>
      <mesh filename="./meshes/taxels/L1/lmm.stl" scale="0.00101 0.00101 0.00101"/>
    </geometry>
    <origin xyz="0 -1e-3 0"/>
  </tactile>
  <tactile data="data[35]" link="little_middle_link" ns="little" topic="TactileGlove" xs="0 4095">
    <geometry>
      <mesh filename="./meshes/taxels/L1/lmi.stl" scale="0.00101 0.00101 0.00101"/>
    </geometry>
    <origin xyz="0.001 0 0"/>
  </tactile>
  <tactile data="data[39]" link="little_proximal_link" ns="little" topic="TactileGlove" xs="0 4095">
    <geometry>
      <mesh filename="./meshes/taxels/L1/lpo.stl" scale="0.00101 0.00101 0.00101"/>
    </geometry>
    <origin xyz="-0.001 0 0"/>
  </tactile>
  <tactile data="data[38]" link="little_proximal_link" ns="little" topic="TactileGlove" xs="0 4095">
    <geometry>
      <mesh filename="./meshes/taxels/L1/lp.stl" scale="0.00101 0.00101 0.00101"/>
    </geometry>
    <origin xyz="0 -1e-3 0"/>
  </tactile>
  <tactile data="data[53]" link="palm_link" ns="palm" topic="TactileGlove" xs="0 4095">
    <geometry>
      <mesh filename="./meshes/taxels/L1/pdlo.stl" scale="0.00101 0.00101 0.00101"/>
    </geometry>
    <origin xyz="0 -1e-3 0"/>
  </tactile>
  <tactile data="data[43]" link="palm_link" ns="palm" topic="TactileGlove" xs="0 4095">
    <geometry>
      <mesh filename="./meshes/taxels/L1/pdl.stl" scale="0.00101 0.00101 0.00101"/>
    </geometry>
    <origin xyz="0 -1e-3 0"/>
  </tactile>
  <tactile data="data[41]" link="palm_link" ns="palm" topic="TactileGlove" xs="0 4095">
    <geometry>
      <mesh filename="./meshes/taxels/L1/pdm.stl" scale="0.00101 0.00101 0.00101"/>
    </geometry>
    <origin xyz="0 -1e-3 0"/>
  </tactile>
  <tactile data="data[40]" link="palm_link" ns="palm" topic="TactileGlove" xs="0 4095">
    <geometry>
      <mesh filename="./meshes/taxels/L1/pdi.stl" scale="0.00101 0.00101 0.00101"/>
    </geometry>
    <origin xyz="0 -1e-3 0"/>
  </tactile>
  <tactile data="data[53]" link="palm_link" ns="palm" topic="TactileGlove" xs="0 4095">
    <geometry>
      <mesh filename="./meshes/taxels/L1/pco.stl" scale="0.00101 0.00101 0.00101"/>
    </geometry>
    <origin xyz="0 -1e-3 0"/>
  </tactile>
  <tactile data="data[52]" link="palm_link" ns="palm" topic="TactileGlove" xs="0 4095">
    <geometry>
      <mesh filename="./meshes/taxels/L1/pcmp.stl" scale="0.00101 0.00101 0.00101"/>
    </geometry>
    <origin xyz="0 -1e-3 0"/>
  </tactile>
  <tactile data="data[50]" link="palm_link" ns="palm" topic="TactileGlove" xs="0 4095">
    <geometry>
      <mesh filename="./meshes/taxels/L1/pcmd.stl" scale="0.00101 0.00101 0.00101"/>
    </geometry>
    <origin xyz="0 -1e-3 0"/>
  </tactile>
  <tactile data="data[51]" link="palm_link" ns="palm" topic="TactileGlove" xs="0 4095">
    <geometry>
      <mesh filename="./meshes/taxels/L1/pcip.stl" scale="0.00101 0.00101 0.00101"/>
    </geometry>
    <origin xyz="0 -1e-3 0"/>
  </tactile>
  <tactile data="data[49]" link="palm_link" ns="palm" topic="TactileGlove" xs="0 4095">
    <geometry>
      <mesh filename="./meshes/taxels/L1/pcim.stl" scale="0.00101 0.00101 0.00101"/>
    </geometry>
    <origin xyz="0 -1e-3 0"/>
  </tactile>
  <tactile data="data[48]" link="palm_link" ns="palm" topic="TactileGlove" xs="0 4095">
    <geometry>
      <mesh filename="./meshes/taxels/L1/pcid.stl" scale="0.00101 0.00101 0.00101"/>
    </geometry>
    <origin xyz="0 -1e-3 0"/>
  </tactile>
  <tactile data="data[47]" link="palm_link" ns="palm" topic="TactileGlove" xs="0 4095">
    <geometry>
      <mesh filename="./meshes/taxels/L1/ptop.stl" scale="0.00101 0.00101 0.00101"/>
    </geometry>
    <origin xyz="0 -1e-3 0"/>
  </tactile>
  <tactile data="data[45]" link="palm_link" ns="palm" topic="TactileGlove" xs="0 4095">
    <geometry>
      <mesh filename="./meshes/taxels/L1/ptod.stl" scale="0.00101 0.00101 0.00101"/>
    </geometry>
    <origin xyz="0 -1e-3 0"/>
  </tactile>
  <tactile data="data[47]" link="palm_link" ns="palm" topic="TactileGlove" xs="0 4095">
    <geometry>
      <mesh filename="./meshes/taxels/L1/ptmp.stl" scale="0.00101 0.00101 0.00101"/>
    </geometry>
    <origin xyz="0 -1e-3 0"/>
  </tactile>
  <tactile data="data[45]" link="palm_link" ns="palm" topic="TactileGlove" xs="0 4095">
    <geometry>
      <mesh filename="./meshes/taxels/L1/ptmd.stl" scale="0.00101 0.00101 0.00101"/>
    </geometry>
    <origin xyz="0 -1e-3 0"/>
  </tactile>
  <tactile data="data[46]" link="palm_link" ns="palm" topic="TactileGlove" xs="0 4095">
    <geometry>
      <mesh filename="./meshes/taxels/L1/ptip.stl" scale="0.00101 0.00101 0.00101"/>
    </geometry>
    <origin xyz="0 -1e-3 0"/>
  </tactile>
  <tactile data="data[44]" link="palm_link" ns="palm" topic="TactileGlove" xs="0 4095">
    <geometry>
      <mesh filename="./meshes/taxels/L1/ptid.stl" scale="0.00101 0.00101 0.00101"/>
    </geometry>
    <origin xyz="0 -1e-3 0"/>
  </tactile>
  <tactile data="data[47]" link="thumb_proximal_link" ns="thumb" topic="TactileGlove" xs="0 4095">
    <geometry>
      <mesh filename="./meshes/taxels/L1/ptmp2.stl" scale="0.00101 0.00101 0.00101"/>
    </geometry>
    <origin xyz="0 -1e-3 0"/>
  </tactile>
  <tactile data="data[45]" link="thumb_proximal_link" ns="thumb" topic="TactileGlove" xs="0 4095">
    <geometry>
      <mesh filename="./meshes/taxels/L1/ptmd2.stl" scale="0.00101 0.00101 0.00101"/>
    </geometry>
    <origin xyz="0 -1e-3 0"/>
  </tactile>
  <tactile data="data[46]" link="thumb_proximal_link" ns="thumb" topic="TactileGlove" xs="0 4095">
    <geometry>
      <mesh filename="./meshes/taxels/L1/ptip2.stl" scale="0.00101 0.00101 0.00101"/>
    </geometry>
    <origin xyz="0 -1e-3 0"/>
  </tactile>
  <tactile data="data[44]" link="thumb_proximal_link" ns="thumb" topic="TactileGlove" xs="0 4095">
    <geometry>
      <mesh filename="./meshes/taxels/L1/ptid2.stl" scale="0.00101 0.00101 0.00101"/>
    </geometry>
    <origin xyz="0 -1e-3 0"/>
  </tactile>
  <tactile data="data[0]" link="thumb_distal_link" ns="thumb" topic="TactileGlove" xs="0 4095">
    <geometry>
      <mesh filename="./meshes/taxels/L1/tdd.stl" scale="0.00101 0.00101 0.00101"/>
    </geometry>
    <origin xyz="0 0 1e-3"/>
  </tactile>
  <tactile data="data[3]" link="thumb_distal_link" ns="thumb" topic="TactileGlove" xs="0 4095">
    <geometry>
      <mesh filename="./meshes/taxels/L1/tdo.stl" scale="0.00101 0.00101 0.00101"/>
    </geometry>
    <origin xyz="0 1e-3 0"/>
  </tactile>
  <tactile data="data[2]" link="thumb_distal_link" ns="thumb" topic="TactileGlove" xs="0 4095">
    <geometry>
      <mesh filename="./meshes/taxels/L1/tdm.stl" scale="0.00101 0.00101 0.00101"/>
    </geometry>
    <origin xyz="-0.001 0 0"/>
  </tactile>
  <tactile data="data[1]" link="thumb_distal_link" ns="thumb" topic="TactileGlove" xs="0 4095">
    <geometry>
      <mesh filename="./meshes/taxels/L1/tdi.stl" scale="0.00101 0.00101 0.00101"/>
    </geometry>
    <origin xyz="0 -1e-3 0"/>
  </tactile> 
-->
</robot>

