<mujoco model="four_link_planar_arm">
	<compiler 	inertiafromgeom="true"
				angle="radian"/>
			
	<size 	nuser_jnt="1"
			nuser_geom="1"/>

	<option	timestep="0.001"
			gravity="0 0 0"
			viscosity="0"
			iterations="20"/>
	
	<asset>
		<material name="MatGnd" specular=".3" shininess=".3" reflectance="0.3" rgba=".5 .55 .5 1"/>
	</asset>
	
	<default>
		<joint limited="true" damping="1" stiffness="0" armature=".1" user="0"/>
		<geom solref="0.008 1" solimp="0.95 0.95 0.01" margin="0.001" user="0"/>
		<motor ctrllimited="true" ctrlrange="-1 1"/>
		<position ctrllimited="true"/>
		
		<default class='0'>
			<geom friction="1 0.005 0.001" rgba=".75 .6 .5 1" contype="1" conaffinity="0"/>
		</default>

		<default class='1'>
			<geom friction="1 0.005 0.001" rgba=".7 .6 .55 1" contype="1" conaffinity="0"/>
		</default>
		
		<default class='arm'>
			<joint damping="5"/>
		</default>
	</default>

<worldbody>
		<light directional="true" cutoff="40" exponent="10" diffuse=".4 .4 .4" specular=".7 .7 .7" pos="0 0 1.5" dir="0 0 -1"/>
		<geom name="tableTop" material="MatGnd" type="plane" pos="0.15 0 0" size="0.4 0.6 0.5" rgba=".6 .6 .5 1" contype="1" conaffinity="1"/>
	    
		<!--  ================= ARM ================= /-->
		<body name="base" pos="0.15 0 0.01">
			<geom class="arm" name="fixture" type="sphere" size="0.012" rgba="0. 0. 0. 1" pos="0. 0. 0.01" />
			<joint class='arm' name="rBL1Jnt" type="hinge" pos="0 0 0" axis="0 0 1" range="-3 3" user="001"/>
			<geom class="arm" name="base" type="sphere" size="0.02" rgba="0.5 0.5 0.5 1" pos="0. 0. 0." />
		
			<body name="link1" pos="0.0 0. 0.01">
				<geom class="arm" type="capsule" fromto="0 0 0 0.05 0 0" rgba="0.5 0.5 0.5 1" size="0.01"/>
				<joint class='arm' name="rL1L2Jnt" type="hinge" pos="0 0 0" axis="0 0 1" range="-3 3" user="001"/>
				
				<body name="link2" pos="0.05 0. 0.">
					<geom class="arm" name="jnt2" type="sphere" size="0.012" rgba="0. 0. 0. 1" pos="0. 0. 0.0" />
					<geom class="arm" type="capsule" fromto="0 0 0 0.05 0 0" rgba="0.5 0.5 0.5 1" size="0.01"/>
					<joint class='arm' name="rL2L3Jnt" type="hinge" pos="0 0 0" axis="0 0 1" range="-3 3" user="001"/>

					<body name="link3" pos="0.05 0. 0.">
						<geom class="arm" name="jnt3" type="sphere" size="0.012" rgba="0. 0. 0. 1" pos="0. 0. 0.0" />
						<geom class="arm" type="capsule" fromto="0 0 0 0.05 0 0" rgba="0.5 0.5 0.5 1" size="0.01"/>
						<joint class='arm' name="rL3L4Jnt" type="hinge" pos="0 0 0" axis="0 0 1" range="-3 3" user="001"/>

						<body name="link4" pos="0.05 0. 0.">
							<geom class="arm" name="jnt4" type="sphere" size="0.012" rgba="0. 0. 0. 1" pos="0. 0. 0.0" />
							<geom class="arm" type="capsule" fromto="0 0 0 0.05 0 0" rgba="0.5 0.5 0.5 1" size="0.01"/>

							<body name="end_effector" pos="0.05 0. 0.">
								<site type="sphere" name="ee_site" size="0.003" pos="0. 0 0" rgba="0.5 0.6 0.8 0.3" />
								<geom class="arm" type="capsule" fromto="0.0 -0.025 0  0.0   0.025 0" rgba="0.5 0.5 0.5 1"  size="0.01"/>
								<geom class="arm" type="capsule" fromto="0.0 -0.025 0  0.03 -0.025 0" rgba="0.5 0.5 0.5 1"  size="0.01"/>
								<geom class="arm" type="capsule" fromto="0.0  0.025 0  0.03  0.025 0" rgba="0.5 0.5 0.5 1"  size="0.01"/>
							</body>
						</body>
					</body>
				</body>	
			</body>
		</body>

		<!--  ================= OBJECTS ================= /-->
         <body name="red_object" pos="0.41 0. 0.011">
         	<site name="target" pos="0 0 0" size="0.01" />
            <geom type="box" name="r_obj" size="0.01 0.01 0.01" pos="0. 0. 0." rgba="1 0. 0. 1" user="1" contype="1" conaffinity="1"/>
            <!--<joint name="r_fr" type="free" limited='false' damping="0" armature="0" user="010"/>-->
        </body>

    <!--
        <body name="green_object" pos="0.41 -0.07 0.011">
            <geom type="box" name="g_obj" size="0.01 0.01 0.01" pos="0. 0. 0." rgba="0 1. 0. 1" user="1" contype="1" conaffinity="1"/>
            <joint name="g_fr" type="free" limited='false' damping="0" armature="0" user="010"/>
        </body>

        <body name="blue_object" pos="0.41 0.07 0.011">
            <geom type="box" name="b_obj" size="0.01 0.01 0.01" pos="0. 0. 0." rgba="0 0. 1. 1" user="1" contype="1" conaffinity="1"/>
            <joint name="b_fr" type="free" limited='false' damping="0" armature="0" user="010"/>
        </body>

        <body name="black_object" pos="0.31 0.07 0.011">
            <geom type="box" name="bl_obj" size="0.01 0.01 0.01" pos="0. 0. 0." rgba="0 0. 0. 1" user="1" contype="1" conaffinity="1"/>
            <joint name="bl_fr" type="free" limited='false' damping="0" armature="0" user="010"/>
        </body>
    -->

	</worldbody>
	
	<actuator>


		<!--  ================= Position actuators ================= /-->

	<!--
		<position joint='rBL1Jnt' 	name='As_jnt1'  kp="100" ctrlrange='-1 1'/>
		<position joint='rL1L2Jnt' 	name='As_jnt2' 	kp="100" ctrlrange='-1 1'/>
		<position joint='rL2L3Jnt' 	name='As_jnt3' 	kp="100" ctrlrange='-1 1'/>
		<position joint='rL3L4Jnt' 	name='As_jnt4' 	kp="100" ctrlrange='-1 1'/>

	-->

		<!--  ================= Torque actuators ================= /-->
		<motor ctrllimited="true" name='As_jnt1' ctrlrange="-1.0 1.0" gear="200.0" joint="rBL1Jnt"/>
		<motor ctrllimited="true" name='As_jnt2' ctrlrange="-1.0 1.0" gear="200.0" joint="rL1L2Jnt"/>
		<motor ctrllimited="true" name='As_jnt3' ctrlrange="-1.0 1.0" gear="200.0" joint="rL2L3Jnt"/>
		<motor ctrllimited="true" name='As_jnt4' ctrlrange="-1.0 1.0" gear="200.0" joint="rL3L4Jnt"/>
	</actuator>

</mujoco>