<?xml version="1.0" ?>
<!-- =================================================================================== -->
<!-- |    This document was autogenerated by xacro from hand.urdf.xacro                | -->
<!-- |    EDITING THIS FILE BY HAND IS NOT RECOMMENDED                                 | -->
<!-- =================================================================================== -->
<robot name="soft_hand" xmlns:xacro="http://www.ros.org/wiki/xacro">
  <material name="SoftHand/LightGrey">
    <color rgba="0.7 0.7 0.7 1.0"/>
  </material>
  <material name="SoftHand/DarkGrey">
    <color rgba="0.4 0.4 0.4 1.0"/>
  </material>
  <material name="SoftHand/Black">
    <color rgba="0.0 0.0 0.0 1.0"/>
  </material>
  <material name="SoftHand/DarkGolden">
    <color rgba="0.4 0.4 0.3 1.0"/>
  </material>
  <material name="SoftHand/Blue">
    <color rgba="0.0 0.0 0.8 0.9"/>
  </material>
  <material name="SoftHand/LightBlue">
    <color rgba="0.0 0.4 1.0 0.5"/>
  </material>
  <!-- <xacro:insert_block name="gazebo_friction_properties"/> -->
  <!-- <xacro:insert_block name="gazebo_other_properties"/> -->
  <!-- NOTE: inertia values are approximated using meshlab and only using the significant elements -->
  <!-- from http://answers.ros.org/question/11350/is-there-any-way-to-calculate-inertial-property-of-a-robot-to-simulate-it-in-gazebo/s
    One general rule of thumb I use for checking my inertia tensors is: If total mass of the rigid body is m, and the dimension of the corresponding body is d, then check to see if ixx, iyy, izz are near m*(d/2)^2.

    This is by no means correct, but a sanity check to make sure the moment of inertia are the right order of magnitudes, so the model behaves somewhat physically realistically.
    -->
  <!--<link name="right_hand"/>-->
  <!-- PACMAN VERION ALREADY INCLUDES THE COUPLER, CLAMP AND BASE -->


<!--<link name="right_soft_hand_adapter">-->
    <!--<visual>-->
      <!--<origin rpy="1.5707 0. 3.14" xyz="0. 0. 0."/>-->
      <!--<geometry>-->
        <!--<mesh filename="package://soft_hand_description/meshes/peg_description/pisa_hand_adapter.STL" scale="0.001 0.001 0.001" />-->
      <!--</geometry>-->
    <!--</visual>-->
    <!--<collision>-->
      <!--<origin rpy="1.5707 0. 3.14" xyz="0. 0. 0."/>-->
      <!--<geometry>-->
        <!--<mesh filename="package://soft_hand_description/meshes/peg_description/pisa_hand_adapter.STL" scale="0.001 0.001 0.001" />-->
      <!--</geometry>-->
    <!--</collision>-->
    <!--<inertial>-->
      <!--<origin rpy="0 0 0" xyz="-0.05 0.04 0."/>-->
      <!--<mass value="0.0001"/>-->
      <!--<inertia ixx="1e-08" ixy="0" ixz="0" iyy="1e-08" iyz="0" izz="1e-08"/>-->
    <!--</inertial>-->
  <!--</link>-->

  <!--<joint name="right_gripper_soft_hand_adapter" type="fixed">-->
    <!--<origin rpy="0 0. 0" xyz="0.05 -0.04 -0.01"/>-->
    <!--<parent link="right_hand"/>-->
    <!--<child link="right_soft_hand_adapter"/>-->
  <!--</joint>-->




  <joint name="hand_soft_hand_kuka_coupler_joint" type="fixed">
    <origin rpy="0 0 -1.570796327" xyz="0.007 0.0 0.0035"/>
    <parent link="right_hand"/>
    <child link="soft_hand_kuka_coupler_bottom"/>
  </joint>
  <link name="soft_hand_kuka_coupler_bottom">
    <visual>
      <origin rpy="0 0 0" xyz="0 0 0.0115"/>
      <geometry>
        <!-- mesh filename="package://soft_hand_description/meshes/accesories/kuka_coupler.stl"/-->
        <cylinder length="0.023" radius="0.033"/>
      </geometry>
      <material name="SoftHand/Blue"/>
    </visual>
    <collision>
      <origin rpy="0 0 0" xyz="0 0 0.031"/>
      <geometry>
        <cylinder length="0.023" radius="0.033"/>
      </geometry>
    </collision>
  </link>
  <joint name="hand_soft_hand_kuka_coupler_base_joint" type="fixed">
    <origin rpy="0 0 0" xyz="0 0 0.023"/>
    <parent link="soft_hand_kuka_coupler_bottom"/>
    <child link="soft_hand_kuka_coupler"/>
  </joint>
  <link name="soft_hand_kuka_coupler"/>
  <joint name="soft_hand_kuka_coupler_soft_hand_clamp_joint" type="fixed">
    <origin rpy="0 0 0" xyz="0 0 0.01"/>
    <parent link="soft_hand_kuka_coupler"/>
    <child link="soft_hand_clamp"/>
  </joint>
  <link name="soft_hand_clamp">
    <visual>
      <origin rpy="0 0 0" xyz="0 0 0"/>
      <geometry>
        <mesh filename="package://soft_hand_description/meshes/accesories/clamp.stl"/>
      </geometry>
      <material name="SoftHand/Blue"/>
    </visual>
    <collision>
      <origin rpy="0 0 0" xyz="0 0 0"/>
      <geometry>
        <box size="0.066 0.0725 0.0256"/>
      </geometry>
    </collision>
  </link>
  <joint name="soft_hand_clamp_soft_hand_softhand_base_joint" type="fixed">
    <origin rpy="0 0 0" xyz="0 0 0.004"/>
    <parent link="soft_hand_clamp"/>
    <child link="soft_hand_softhand_base"/>
  </joint>
  <link name="soft_hand_softhand_base">
    <visual>
      <origin rpy="0 0 0" xyz="0 0 0"/>
      <geometry>
        <mesh filename="package://soft_hand_description/meshes/accesories/softhand_base_right.stl"/>
      </geometry>
      <material name="SoftHand/Blue"/>
    </visual>
    <collision>
      <origin rpy="0 0 0" xyz="0 0 0.031"/>
      <geometry>
        <box size="0.066 0.066 0.062"/>
      </geometry>
    </collision>
  </link>
  <!-- PALM -->
  <joint name="soft_hand_palm_joint" type="fixed">
    <origin rpy="0 0 0" xyz="0.002 0.00695 0.0535"/>
    <parent link="soft_hand_softhand_base"/>
    <child link="soft_hand_palm_link"/>
  </joint>
  <link name="soft_hand_palm_link">
    <inertial>
      <origin xyz="-0.004568758 -0.006808116 0.027653328"/>
      <mass value="0.0"/>
      <inertia ixx="0.0" ixy="0.0" ixz="0.0" iyy="0.0" iyz="0.0" izz="0.0"/>
<!--       <mass value="2.28"/>
      <inertia ixx="1.6302" ixy="0.0228" ixz="0.0228" iyy="0.9462" iyz="0.0456" izz="1.1058"/> -->
    </inertial>
    <visual>
      <geometry>
        <mesh filename="package://soft_hand_description/meshes/palm_right.stl" scale=" .001 .001 .001"/>
      </geometry>
      <material name="SoftHand/DarkGrey"/>
    </visual>
    <collision>
      <geometry>
        <mesh filename="package://soft_hand_description/meshes/palm_right_collision.stl" scale=" .001 .001 .001"/>
      </geometry>
    </collision>
  </link>
  <!-- MOTOR JOINT -->
  <joint name="soft_hand_synergy_joint" type="revolute">
    <parent link="soft_hand_palm_link"/>
    <child link="soft_hand_invisible_wire_link"/>
    <axis xyz="0 0 1"/>
    <limit effort="100" lower="0.0" upper="1.0" velocity="100000"/>
    <dynamics damping="0.0" friction="0.0"/>
  </joint>
  <link name="soft_hand_invisible_wire_link">
    <inertial>
      <origin xyz="0 0 0"/>
      <mass value="0.0"/>
      <inertia ixx="0.0" ixy="0.0" ixz="0.0" iyy="0.0" iyz="0.0" izz="0.0"/>
<!--       <mass value="0.1"/>
      <inertia ixx="0.001" ixy="0.0" ixz="0.0" iyy="0.001" iyz="0.0" izz="0.001"/> -->
    </inertial>
  </link>
  <!-- KNUCKLE -->
  <joint name="soft_hand_thumb_abd_joint" type="revolute">
    <origin rpy="0.0 -0.38397275793662144 1.5707963267948966" xyz="0.00566972 0.0296160 0.0553140"/>
    <parent link="soft_hand_palm_link"/>
    <child link="soft_hand_thumb_knuckle_link"/>
    <axis xyz="0 0 -1"/>
    <limit effort="100" lower="0.0" upper="1.57079632679" velocity="100"/>
    <dynamics damping="0.0" friction="0.0"/>
  </joint>
  <link name="soft_hand_thumb_knuckle_link">
    <inertial>
      <origin xyz="0.013608098 -0.000532174 -0.000216691"/>
      <mass value="0.0"/>
      <inertia ixx="0.0" ixy="0.0" ixz="0.0" iyy="0.0" iyz="0.0" izz="0.0"/>
      <!-- <mass value="0.09"/>
      <inertia ixx="0.00315" ixy="0.00027" ixz="-0.00054" iyy="0.009" iyz="0.00018" izz="0.009"/> -->
    </inertial>
    <visual>
      <geometry>
        <mesh filename="package://soft_hand_description/meshes/thumb_knuckle_right.stl" scale=" .001 .001 .001"/>
      </geometry>
      <material name="SoftHand/DarkGrey"/>
    </visual>
    <collision>
      <geometry>
        <mesh filename="package://soft_hand_description/meshes/thumb_knuckle_right_collision.stl" scale=" .001 .001 .001"/>
      </geometry>
    </collision>
  </link>
  <!-- PROXIMAL PHALANGE -->
  <joint name="soft_hand_thumb_inner_joint" type="revolute">
    <!-- <origin xyz="0.022500000 -0.003300000 0.0" rpy="0.42662757656587236 0.0 0.18131960430075023" /> -->
    <origin rpy="0.42662757656587236 0.0 0.0" xyz="0.022500000 -0.003300000 0.0"/>
    <parent link="soft_hand_thumb_knuckle_link"/>
    <child link="soft_hand_thumb_fake_link1"/>
    <axis xyz="0 -1 0"/>
    <limit effort="100" lower="0.0" upper="0.785398163397" velocity="100"/>
    <dynamics damping="0.0" friction="0.0"/>
  </joint>
  <link name="soft_hand_thumb_fake_link1">
    <inertial>
      <origin xyz="0 0 0"/>
      <mass value="0.0"/>
      <inertia ixx="0.0" ixy="0.0" ixz="0.0" iyy="0.0" iyz="0.0" izz="0.0"/>
<!--       <mass value="0.1"/>
      <inertia ixx="0.001" ixy="0.0" ixz="0.0" iyy="0.001" iyz="0.0" izz="0.001"/> -->
    </inertial>
  </link>
  <joint name="soft_hand_thumb_inner_joint_mimic" type="revolute">
    <origin rpy="0 0 0" xyz="0.013 0 0"/>
    <parent link="soft_hand_thumb_fake_link1"/>
    <child link="soft_hand_thumb_proximal_link"/>
    <axis xyz="0 -1 0"/>
    <limit effort="100" lower="0.0" upper="0.785398163397" velocity="100"/>
    <dynamics damping="0.0" friction="0.0"/>
  </joint>
  <link name="soft_hand_thumb_proximal_link">
    <inertial>
      <origin xyz="0.005074337 -4.524e-06 -0.000262953"/>
      <mass value="0.0"/>
      <inertia ixx="0.0" ixy="0.0" ixz="0.0" iyy="0.0" iyz="0.0" izz="0.0"/>
<!--       <mass value="0.05"/>
      <inertia ixx="0.00175" ixy="0.0" ixz="0.0001" iyy="0.00275" iyz="0.0" izz="0.00275"/> -->
    </inertial>
    <visual>
      <geometry>
        <mesh filename="package://soft_hand_description/meshes/phalanx.stl" scale=" .001 .001 .001"/>
      </geometry>
      <material name="SoftHand/DarkGrey"/>
    </visual>
    <collision>
      <geometry>
        <mesh filename="package://soft_hand_description/meshes/phalanx_collision.stl" scale=" .001 .001 .001"/>
      </geometry>
    </collision>
  </link>
  <!-- DISTAL PHALANGE -->
  <joint name="soft_hand_thumb_outer_joint" type="revolute">
    <origin rpy="0 0 0" xyz="0.009 0 0.0"/>
    <parent link="soft_hand_thumb_proximal_link"/>
    <child link="soft_hand_thumb_fake_link3"/>
    <axis xyz="0 -1 0"/>
    <limit effort="100" lower="0.0" upper="0.785398163397" velocity="100"/>
    <dynamics damping="0.0" friction="0.0"/>
  </joint>
  <link name="soft_hand_thumb_fake_link3">
    <inertial>
      <origin xyz="0 0 0"/>
      <mass value="0.0"/>
      <inertia ixx="0.0" ixy="0.0" ixz="0.0" iyy="0.0" iyz="0.0" izz="0.0"/>
<!--       <mass value="0.1"/>
      <inertia ixx="0.001" ixy="0.0" ixz="0.0" iyy="0.001" iyz="0.0" izz="0.001"/> -->
    </inertial>
  </link>
  <joint name="soft_hand_thumb_outer_joint_mimic" type="revolute">
    <origin rpy="0 0 0" xyz="0.013 0 0"/>
    <parent link="soft_hand_thumb_fake_link3"/>
    <child link="soft_hand_thumb_distal_link"/>
    <axis xyz="0 -1 0"/>
    <limit effort="100" lower="0.0" upper="0.785398163397" velocity="100"/>
    <dynamics damping="0.0" friction="0.0"/>
  </joint>
  <link name="soft_hand_thumb_distal_link">
    <inertial>
      <origin xyz="0.009849094 5.6e-07 0.000820286"/>
      <mass value="0.0"/>
      <inertia ixx="0.0" ixy="0.0" ixz="0.0" iyy="0.0" iyz="0.0" izz="0.0"/>
<!--       <mass value="0.1"/>
      <inertia ixx="0.0035" ixy="0.0" ixz="0.0002" iyy="0.008" iyz="0.0" izz="0.0076"/> -->
    </inertial>
    <visual>
      <geometry>
        <mesh filename="package://soft_hand_description/meshes/fingertip.stl" scale=" .001 .001 .001"/>
      </geometry>
      <material name="SoftHand/DarkGrey"/>
    </visual>
    <collision>
      <geometry>
        <mesh filename="package://soft_hand_description/meshes/fingertip_collision.stl" scale=" .001 .001 .001"/>
      </geometry>
    </collision>
  </link>
  <!-- KNUCKLE -->
  <joint name="soft_hand_index_abd_joint" type="revolute">
    <origin rpy="1.5707963267948966 -1.4835299330931884 1.5707963267948966" xyz="-0.0033 0.0195 0.0936994"/>
    <parent link="soft_hand_palm_link"/>
    <child link="soft_hand_index_knuckle_link"/>
    <axis xyz="0 0 1"/>
    <limit effort="100" lower="-0.523598775598" upper="0.523598775598" velocity="100"/>
    <dynamics damping="0.0" friction="0.0"/>
  </joint>
  <link name="soft_hand_index_knuckle_link">
    <inertial>
      <origin xyz="0.001285644 -9.58e-07 0.000425011"/>
      <mass value="0.0"/>
      <inertia ixx="0.0" ixy="0.0" ixz="0.0" iyy="0.0" iyz="0.0" izz="0.0"/>
<!--       <mass value="0.09"/>
      <inertia ixx="0.00405" ixy="0.0" ixz="0.00045" iyy="0.0081" iyz="0.0" izz="0.0063"/> -->
    </inertial>
    <visual>
      <geometry>
        <mesh filename="package://soft_hand_description/meshes/knuckle.stl" scale=" .001 .001 .001"/>
      </geometry>
      <material name="SoftHand/DarkGrey"/>
    </visual>
    <collision>
      <geometry>
        <mesh filename="package://soft_hand_description/meshes/knuckle_collision.stl" scale=" .001 .001 .001"/>
      </geometry>
    </collision>
  </link>
  <!-- PROXIMAL PHALANGE -->
  <joint name="soft_hand_index_inner_joint" type="revolute">
    <origin rpy="0 0 0" xyz="0.009 0 0"/>
    <parent link="soft_hand_index_knuckle_link"/>
    <child link="soft_hand_index_fake_link1"/>
    <axis xyz="0 -1 0"/>
    <limit effort="100" lower="0.0" upper="0.785398163397" velocity="100"/>
    <dynamics damping="0.0" friction="0.0"/>
  </joint>
  <link name="soft_hand_index_fake_link1">
    <inertial>
      <origin xyz="0 0 0"/>
      <mass value="0.0"/>
      <inertia ixx="0.0" ixy="0.0" ixz="0.0" iyy="0.0" iyz="0.0" izz="0.0"/>
<!--       <mass value="0.1"/>
      <inertia ixx="0.001" ixy="0.0" ixz="0.0" iyy="0.001" iyz="0.0" izz="0.001"/> -->
    </inertial>
  </link>
  <joint name="soft_hand_index_inner_joint_mimic" type="revolute">
    <origin rpy="0 0 0" xyz="0.013 0 0"/>
    <parent link="soft_hand_index_fake_link1"/>
    <child link="soft_hand_index_proximal_link"/>
    <axis xyz="0 -1 0"/>
    <limit effort="100" lower="0.0" upper="0.785398163397" velocity="100"/>
    <dynamics damping="0.0" friction="0.0"/>
  </joint>
  <link name="soft_hand_index_proximal_link">
    <inertial>
      <origin xyz="0.005074337 -4.524e-06 -0.000262953"/>
      <mass value="0.0"/>
      <inertia ixx="0.0" ixy="0.0" ixz="0.0" iyy="0.0" iyz="0.0" izz="0.0"/>
<!--       <mass value="0.05"/>
      <inertia ixx="0.00175" ixy="0.0" ixz="0.0001" iyy="0.00275" iyz="0.0" izz="0.00275"/> -->
    </inertial>
    <visual>
      <geometry>
        <mesh filename="package://soft_hand_description/meshes/phalanx.stl" scale=" .001 .001 .001"/>
      </geometry>
      <material name="SoftHand/DarkGrey"/>
    </visual>
    <collision>
      <geometry>
        <mesh filename="package://soft_hand_description/meshes/phalanx_collision.stl" scale=" .001 .001 .001"/>
      </geometry>
    </collision>
  </link>
  <!-- MIDDLE PHALANGE -->
  <joint name="soft_hand_index_middle_joint" type="revolute">
    <origin rpy="0 0 0" xyz="0.009 0 0"/>
    <parent link="soft_hand_index_proximal_link"/>
    <child link="soft_hand_index_fake_link2"/>
    <axis xyz="0 -1 0"/>
    <limit effort="100" lower="0.0" upper="0.785398163397" velocity="100"/>
    <dynamics damping="0.0" friction="0.0"/>
  </joint>
  <link name="soft_hand_index_fake_link2">
    <inertial>
      <origin xyz="0 0 0"/>
      <mass value="0.0"/>
      <inertia ixx="0.0" ixy="0.0" ixz="0.0" iyy="0.0" iyz="0.0" izz="0.0"/>
<!--       <mass value="0.1"/>
      <inertia ixx="0.001" ixy="0.0" ixz="0.0" iyy="0.001" iyz="0.0" izz="0.001"/> -->
    </inertial>
  </link>
  <joint name="soft_hand_index_middle_joint_mimic" type="revolute">
    <origin rpy="0 0 0" xyz="0.013 0 0"/>
    <parent link="soft_hand_index_fake_link2"/>
    <child link="soft_hand_index_middle_link"/>
    <axis xyz="0 -1 0"/>
    <limit effort="100" lower="0.0" upper="0.785398163397" velocity="100"/>
    <dynamics damping="0.0" friction="0.0"/>
  </joint>
  <link name="soft_hand_index_middle_link">
    <inertial>
      <origin xyz="0.005074337 -4.524e-06 -0.000262953"/>
      <mass value="0.0"/>
      <inertia ixx="0.0" ixy="0.0" ixz="0.0" iyy="0.0" iyz="0.0" izz="0.0"/>
<!--       <mass value="0.05"/>
      <inertia ixx="0.00175" ixy="0.0" ixz="0.0001" iyy="0.00275" iyz="0.0" izz="0.00275"/> -->
    </inertial>
    <visual>
      <geometry>
        <mesh filename="package://soft_hand_description/meshes/phalanx.stl" scale=" .001 .001 .001"/>
      </geometry>
      <material name="SoftHand/DarkGrey"/>
    </visual>
    <collision>
      <geometry>
        <mesh filename="package://soft_hand_description/meshes/phalanx_collision.stl" scale=" .001 .001 .001"/>
      </geometry>
    </collision>
  </link>
  <!-- DISTAL PHALANGE -->
  <joint name="soft_hand_index_outer_joint" type="revolute">
    <origin rpy="0 0 0" xyz="0.009 0 0"/>
    <parent link="soft_hand_index_middle_link"/>
    <child link="soft_hand_index_fake_link3"/>
    <axis xyz="0 -1 0"/>
    <limit effort="100" lower="0.0" upper="0.785398163397" velocity="100"/>
    <dynamics damping="0.0" friction="0.0"/>
  </joint>
  <link name="soft_hand_index_fake_link3">
    <inertial>
      <origin xyz="0 0 0"/>
      <mass value="0.0"/>
      <inertia ixx="0.0" ixy="0.0" ixz="0.0" iyy="0.0" iyz="0.0" izz="0.0"/>
<!--       <mass value="0.1"/>
      <inertia ixx="0.001" ixy="0.0" ixz="0.0" iyy="0.001" iyz="0.0" izz="0.001"/> -->
    </inertial>
  </link>
  <joint name="soft_hand_index_outer_joint_mimic" type="revolute">
    <origin rpy="0 0 0" xyz="0.013 0 0"/>
    <parent link="soft_hand_index_fake_link3"/>
    <child link="soft_hand_index_distal_link"/>
    <axis xyz="0 -1 0"/>
    <limit effort="100" lower="0.0" upper="0.785398163397" velocity="100"/>
    <dynamics damping="0.0" friction="0.0"/>
  </joint>
  <link name="soft_hand_index_distal_link">
    <inertial>
      <origin xyz="0.009849094 5.6e-07 0.000820286"/>
      <mass value="0.0"/>
      <inertia ixx="0.0" ixy="0.0" ixz="0.0" iyy="0.0" iyz="0.0" izz="0.0"/>
<!--       <mass value="0.1"/>
      <inertia ixx="0.0035" ixy="0.0" ixz="0.0002" iyy="0.008" iyz="0.0" izz="0.0076"/> -->
    </inertial>
    <visual>
      <geometry>
        <mesh filename="package://soft_hand_description/meshes/fingertip.stl" scale=" .001 .001 .001"/>
      </geometry>
      <material name="SoftHand/DarkGrey"/>
    </visual>
    <collision>
      <geometry>
        <mesh filename="package://soft_hand_description/meshes/fingertip_collision.stl" scale=" .001 .001 .001"/>
      </geometry>
    </collision>
  </link>
  <!-- KNUCKLE -->
  <joint name="soft_hand_middle_abd_joint" type="revolute">
    <origin rpy="3.141592 -1.5707963267948966 0.0" xyz="-0.003300000 0.0 0.100699"/>
    <parent link="soft_hand_palm_link"/>
    <child link="soft_hand_middle_knuckle_link"/>
    <axis xyz="0 0 1"/>
    <limit effort="100" lower="-0.523598775598" upper="0.523598775598" velocity="100"/>
    <dynamics damping="0.0" friction="0.0"/>
  </joint>
  <link name="soft_hand_middle_knuckle_link">
    <inertial>
      <origin xyz="0.001285644 -9.58e-07 0.000425011"/>
      <mass value="0.0"/>
      <inertia ixx="0.0" ixy="0.0" ixz="0.0" iyy="0.0" iyz="0.0" izz="0.0"/>
<!--       <mass value="0.09"/>
      <inertia ixx="0.00405" ixy="0.0" ixz="0.00045" iyy="0.0081" iyz="0.0" izz="0.0063"/> -->
    </inertial>
    <visual>
      <geometry>
        <mesh filename="package://soft_hand_description/meshes/knuckle.stl" scale=" .001 .001 .001"/>
      </geometry>
      <material name="SoftHand/DarkGrey"/>
    </visual>
    <collision>
      <geometry>
        <mesh filename="package://soft_hand_description/meshes/knuckle_collision.stl" scale=" .001 .001 .001"/>
      </geometry>
    </collision>
  </link>
  <!-- PROXIMAL PHALANGE -->
  <joint name="soft_hand_middle_inner_joint" type="revolute">
    <origin rpy="0 0 0" xyz="0.009 0 0"/>
    <parent link="soft_hand_middle_knuckle_link"/>
    <child link="soft_hand_middle_fake_link1"/>
    <axis xyz="0 -1 0"/>
    <limit effort="100" lower="0.0" upper="0.785398163397" velocity="100"/>
    <dynamics damping="0.0" friction="0.0"/>
  </joint>
  <link name="soft_hand_middle_fake_link1">
    <inertial>
      <origin xyz="0 0 0"/>
      <mass value="0.0"/>
      <inertia ixx="0.0" ixy="0.0" ixz="0.0" iyy="0.0" iyz="0.0" izz="0.0"/>
<!--       <mass value="0.1"/>
      <inertia ixx="0.001" ixy="0.0" ixz="0.0" iyy="0.001" iyz="0.0" izz="0.001"/> -->
    </inertial>
  </link>
  <joint name="soft_hand_middle_inner_joint_mimic" type="revolute">
    <origin rpy="0 0 0" xyz="0.013 0 0"/>
    <parent link="soft_hand_middle_fake_link1"/>
    <child link="soft_hand_middle_proximal_link"/>
    <axis xyz="0 -1 0"/>
    <limit effort="100" lower="0.0" upper="0.785398163397" velocity="100"/>
    <dynamics damping="0.0" friction="0.0"/>
  </joint>
  <link name="soft_hand_middle_proximal_link">
    <inertial>
      <origin xyz="0.005074337 -4.524e-06 -0.000262953"/>
      <mass value="0.0"/>
      <inertia ixx="0.0" ixy="0.0" ixz="0.0" iyy="0.0" iyz="0.0" izz="0.0"/>
<!--       <mass value="0.05"/>
      <inertia ixx="0.00175" ixy="0.0" ixz="0.0001" iyy="0.00275" iyz="0.0" izz="0.00275"/> -->
    </inertial>
    <visual>
      <geometry>
        <mesh filename="package://soft_hand_description/meshes/phalanx.stl" scale=" .001 .001 .001"/>
      </geometry>
      <material name="SoftHand/DarkGrey"/>
    </visual>
    <collision>
      <geometry>
        <mesh filename="package://soft_hand_description/meshes/phalanx_collision.stl" scale=" .001 .001 .001"/>
      </geometry>
    </collision>
  </link>
  <!-- MIDDLE PHALANGE -->
  <joint name="soft_hand_middle_middle_joint" type="revolute">
    <origin rpy="0 0 0" xyz="0.009 0 0"/>
    <parent link="soft_hand_middle_proximal_link"/>
    <child link="soft_hand_middle_fake_link2"/>
    <axis xyz="0 -1 0"/>
    <limit effort="100" lower="0.0" upper="0.785398163397" velocity="100"/>
    <dynamics damping="0.0" friction="0.0"/>
  </joint>
  <link name="soft_hand_middle_fake_link2">
    <inertial>
      <origin xyz="0 0 0"/>
      <mass value="0.0"/>
      <inertia ixx="0.0" ixy="0.0" ixz="0.0" iyy="0.0" iyz="0.0" izz="0.0"/>
<!--       <mass value="0.1"/>
      <inertia ixx="0.001" ixy="0.0" ixz="0.0" iyy="0.001" iyz="0.0" izz="0.001"/> -->
    </inertial>
  </link>
  <joint name="soft_hand_middle_middle_joint_mimic" type="revolute">
    <origin rpy="0 0 0" xyz="0.013 0 0"/>
    <parent link="soft_hand_middle_fake_link2"/>
    <child link="soft_hand_middle_middle_link"/>
    <axis xyz="0 -1 0"/>
    <limit effort="100" lower="0.0" upper="0.785398163397" velocity="100"/>
    <dynamics damping="0.0" friction="0.0"/>
  </joint>
  <link name="soft_hand_middle_middle_link">
    <inertial>
      <origin xyz="0.005074337 -4.524e-06 -0.000262953"/>
      <mass value="0.0"/>
      <inertia ixx="0.0" ixy="0.0" ixz="0.0" iyy="0.0" iyz="0.0" izz="0.0"/>
<!--       <mass value="0.05"/>
      <inertia ixx="0.00175" ixy="0.0" ixz="0.0001" iyy="0.00275" iyz="0.0" izz="0.00275"/> -->
    </inertial>
    <visual>
      <geometry>
        <mesh filename="package://soft_hand_description/meshes/phalanx.stl" scale=" .001 .001 .001"/>
      </geometry>
      <material name="SoftHand/DarkGrey"/>
    </visual>
    <collision>
      <geometry>
        <mesh filename="package://soft_hand_description/meshes/phalanx_collision.stl" scale=" .001 .001 .001"/>
      </geometry>
    </collision>
  </link>
  <!-- DISTAL PHALANGE -->
  <joint name="soft_hand_middle_outer_joint" type="revolute">
    <origin rpy="0 0 0" xyz="0.009 0 0"/>
    <parent link="soft_hand_middle_middle_link"/>
    <child link="soft_hand_middle_fake_link3"/>
    <axis xyz="0 -1 0"/>
    <limit effort="100" lower="0.0" upper="0.785398163397" velocity="100"/>
    <dynamics damping="0.0" friction="0.0"/>
  </joint>
  <link name="soft_hand_middle_fake_link3">
    <inertial>
      <origin xyz="0 0 0"/>
      <mass value="0.0"/>
      <inertia ixx="0.0" ixy="0.0" ixz="0.0" iyy="0.0" iyz="0.0" izz="0.0"/>
<!--       <mass value="0.1"/>
      <inertia ixx="0.001" ixy="0.0" ixz="0.0" iyy="0.001" iyz="0.0" izz="0.001"/> -->
    </inertial>
  </link>
  <joint name="soft_hand_middle_outer_joint_mimic" type="revolute">
    <origin rpy="0 0 0" xyz="0.013 0 0"/>
    <parent link="soft_hand_middle_fake_link3"/>
    <child link="soft_hand_middle_distal_link"/>
    <axis xyz="0 -1 0"/>
    <limit effort="100" lower="0.0" upper="0.785398163397" velocity="100"/>
    <dynamics damping="0.0" friction="0.0"/>
  </joint>
  <link name="soft_hand_middle_distal_link">
    <inertial>
      <origin xyz="0.009849094 5.6e-07 0.000820286"/>
      <mass value="0.0"/>
      <inertia ixx="0.0" ixy="0.0" ixz="0.0" iyy="0.0" iyz="0.0" izz="0.0"/>
<!--       <mass value="0.1"/>
      <inertia ixx="0.0035" ixy="0.0" ixz="0.0002" iyy="0.008" iyz="0.0" izz="0.0076"/> -->
    </inertial>
    <visual>
      <geometry>
        <mesh filename="package://soft_hand_description/meshes/fingertip.stl" scale=" .001 .001 .001"/>
      </geometry>
      <material name="SoftHand/DarkGrey"/>
    </visual>
    <collision>
      <geometry>
        <mesh filename="package://soft_hand_description/meshes/fingertip_collision.stl" scale=" .001 .001 .001"/>
      </geometry>
    </collision>
  </link>
  <!-- KNUCKLE -->
  <joint name="soft_hand_ring_abd_joint" type="revolute">
    <origin rpy="-1.5707963267948966 -1.5184364298870514 -1.5707963267948966 " xyz="-0.0033 -0.0195 0.0936994"/>
    <parent link="soft_hand_palm_link"/>
    <child link="soft_hand_ring_knuckle_link"/>
    <axis xyz="0 0 1"/>
    <limit effort="100" lower="-0.523598775598" upper="0.523598775598" velocity="100"/>
    <dynamics damping="0.0" friction="0.0"/>
  </joint>
  <link name="soft_hand_ring_knuckle_link">
    <inertial>
      <origin xyz="0.001285644 -9.58e-07 0.000425011"/>
      <mass value="0.0"/>
      <inertia ixx="0.0" ixy="0.0" ixz="0.0" iyy="0.0" iyz="0.0" izz="0.0"/>
<!--       <mass value="0.09"/>
      <inertia ixx="0.00405" ixy="0.0" ixz="0.00045" iyy="0.0081" iyz="0.0" izz="0.0063"/> -->
    </inertial>
    <visual>
      <geometry>
        <mesh filename="package://soft_hand_description/meshes/knuckle.stl" scale=" .001 .001 .001"/>
      </geometry>
      <material name="SoftHand/DarkGrey"/>
    </visual>
    <collision>
      <geometry>
        <mesh filename="package://soft_hand_description/meshes/knuckle_collision.stl" scale=" .001 .001 .001"/>
      </geometry>
    </collision>
  </link>
  <!-- PROXIMAL PHALANGE -->
  <joint name="soft_hand_ring_inner_joint" type="revolute">
    <origin rpy="0 0 0" xyz="0.009 0 0"/>
    <parent link="soft_hand_ring_knuckle_link"/>
    <child link="soft_hand_ring_fake_link1"/>
    <axis xyz="0 -1 0"/>
    <limit effort="100" lower="0.0" upper="0.785398163397" velocity="100"/>
    <dynamics damping="0.0" friction="0.0"/>
  </joint>
  <link name="soft_hand_ring_fake_link1">
    <inertial>
      <origin xyz="0 0 0"/>
      <mass value="0.0"/>
      <inertia ixx="0.0" ixy="0.0" ixz="0.0" iyy="0.0" iyz="0.0" izz="0.0"/>
<!--       <mass value="0.1"/>
      <inertia ixx="0.001" ixy="0.0" ixz="0.0" iyy="0.001" iyz="0.0" izz="0.001"/> -->
    </inertial>
  </link>
  <joint name="soft_hand_ring_inner_joint_mimic" type="revolute">
    <origin rpy="0 0 0" xyz="0.013 0 0"/>
    <parent link="soft_hand_ring_fake_link1"/>
    <child link="soft_hand_ring_proximal_link"/>
    <axis xyz="0 -1 0"/>
    <limit effort="100" lower="0.0" upper="0.785398163397" velocity="100"/>
    <dynamics damping="0.0" friction="0.0"/>
  </joint>
  <link name="soft_hand_ring_proximal_link">
    <inertial>
      <origin xyz="0.005074337 -4.524e-06 -0.000262953"/>
      <mass value="0.0"/>
      <inertia ixx="0.0" ixy="0.0" ixz="0.0" iyy="0.0" iyz="0.0" izz="0.0"/>
<!--       <mass value="0.05"/>
      <inertia ixx="0.00175" ixy="0.0" ixz="0.0001" iyy="0.00275" iyz="0.0" izz="0.00275"/> -->
    </inertial>
    <visual>
      <geometry>
        <mesh filename="package://soft_hand_description/meshes/phalanx.stl" scale=" .001 .001 .001"/>
      </geometry>
      <material name="SoftHand/DarkGrey"/>
    </visual>
    <collision>
      <geometry>
        <mesh filename="package://soft_hand_description/meshes/phalanx_collision.stl" scale=" .001 .001 .001"/>
      </geometry>
    </collision>
  </link>
  <!-- MIDDLE PHALANGE -->
  <joint name="soft_hand_ring_middle_joint" type="revolute">
    <origin rpy="0 0 0" xyz="0.009 0 0"/>
    <parent link="soft_hand_ring_proximal_link"/>
    <child link="soft_hand_ring_fake_link2"/>
    <axis xyz="0 -1 0"/>
    <limit effort="100" lower="0.0" upper="0.785398163397" velocity="100"/>
    <dynamics damping="0.0" friction="0.0"/>
  </joint>
  <link name="soft_hand_ring_fake_link2">
    <inertial>
      <origin xyz="0 0 0"/>
      <mass value="0.0"/>
      <inertia ixx="0.0" ixy="0.0" ixz="0.0" iyy="0.0" iyz="0.0" izz="0.0"/>
<!--       <mass value="0.1"/>
      <inertia ixx="0.001" ixy="0.0" ixz="0.0" iyy="0.001" iyz="0.0" izz="0.001"/> -->
    </inertial>
  </link>
  <joint name="soft_hand_ring_middle_joint_mimic" type="revolute">
    <origin rpy="0 0 0" xyz="0.013 0 0"/>
    <parent link="soft_hand_ring_fake_link2"/>
    <child link="soft_hand_ring_middle_link"/>
    <axis xyz="0 -1 0"/>
    <limit effort="100" lower="0.0" upper="0.785398163397" velocity="100"/>
    <dynamics damping="0.0" friction="0.0"/>
  </joint>
  <link name="soft_hand_ring_middle_link">
    <inertial>
      <origin xyz="0.005074337 -4.524e-06 -0.000262953"/>
      <mass value="0.0"/>
      <inertia ixx="0.0" ixy="0.0" ixz="0.0" iyy="0.0" iyz="0.0" izz="0.0"/>
<!--       <mass value="0.05"/>
      <inertia ixx="0.00175" ixy="0.0" ixz="0.0001" iyy="0.00275" iyz="0.0" izz="0.00275"/> -->
    </inertial>
    <visual>
      <geometry>
        <mesh filename="package://soft_hand_description/meshes/phalanx.stl" scale=" .001 .001 .001"/>
      </geometry>
      <material name="SoftHand/DarkGrey"/>
    </visual>
    <collision>
      <geometry>
        <mesh filename="package://soft_hand_description/meshes/phalanx_collision.stl" scale=" .001 .001 .001"/>
      </geometry>
    </collision>
  </link>
  <!-- DISTAL PHALANGE -->
  <joint name="soft_hand_ring_outer_joint" type="revolute">
    <origin rpy="0 0 0" xyz="0.009 0 0"/>
    <parent link="soft_hand_ring_middle_link"/>
    <child link="soft_hand_ring_fake_link3"/>
    <axis xyz="0 -1 0"/>
    <limit effort="100" lower="0.0" upper="0.785398163397" velocity="100"/>
    <dynamics damping="0.0" friction="0.0"/>
  </joint>
  <link name="soft_hand_ring_fake_link3">
    <inertial>
      <origin xyz="0 0 0"/>
      <mass value="0.0"/>
      <inertia ixx="0.0" ixy="0.0" ixz="0.0" iyy="0.0" iyz="0.0" izz="0.0"/>
<!--       <mass value="0.1"/>
      <inertia ixx="0.001" ixy="0.0" ixz="0.0" iyy="0.001" iyz="0.0" izz="0.001"/> -->
    </inertial>
  </link>
  <joint name="soft_hand_ring_outer_joint_mimic" type="revolute">
    <origin rpy="0 0 0" xyz="0.013 0 0"/>
    <parent link="soft_hand_ring_fake_link3"/>
    <child link="soft_hand_ring_distal_link"/>
    <axis xyz="0 -1 0"/>
    <limit effort="100" lower="0.0" upper="0.785398163397" velocity="100"/>
    <dynamics damping="0.0" friction="0.0"/>
  </joint>
  <link name="soft_hand_ring_distal_link">
    <inertial>
      <origin xyz="0.009849094 5.6e-07 0.000820286"/>
      <mass value="0.0"/>
      <inertia ixx="0.0" ixy="0.0" ixz="0.0" iyy="0.0" iyz="0.0" izz="0.0"/>
<!--       <mass value="0.1"/>
      <inertia ixx="0.0035" ixy="0.0" ixz="0.0002" iyy="0.008" iyz="0.0" izz="0.0076"/> -->
    </inertial>
    <visual>
      <geometry>
        <mesh filename="package://soft_hand_description/meshes/fingertip.stl" scale=" .001 .001 .001"/>
      </geometry>
      <material name="SoftHand/DarkGrey"/>
    </visual>
    <collision>
      <geometry>
        <mesh filename="package://soft_hand_description/meshes/fingertip_collision.stl" scale=" .001 .001 .001"/>
      </geometry>
    </collision>
  </link>
  <!-- KNUCKLE -->
  <joint name="soft_hand_little_abd_joint" type="revolute">
    <origin rpy="-1.5707963267948966 -1.4835299330931884 -1.5707963267948966" xyz="-0.0033 -0.039 0.0836994"/>
    <parent link="soft_hand_palm_link"/>
    <child link="soft_hand_little_knuckle_link"/>
    <axis xyz="0 0 1"/>
    <limit effort="100" lower="-0.523598775598" upper="0.523598775598" velocity="100"/>
    <dynamics damping="0.0" friction="0.0"/>
  </joint>
  <link name="soft_hand_little_knuckle_link">
    <inertial>
      <origin xyz="0.001285644 -9.58e-07 0.000425011"/>
      <mass value="0.0"/>
      <inertia ixx="0.0" ixy="0.0" ixz="0.0" iyy="0.0" iyz="0.0" izz="0.0"/>
<!--       <mass value="0.09"/>
      <inertia ixx="0.00405" ixy="0.0" ixz="0.00045" iyy="0.0081" iyz="0.0" izz="0.0063"/> -->
    </inertial>
    <visual>
      <geometry>
        <mesh filename="package://soft_hand_description/meshes/knuckle.stl" scale=" .001 .001 .001"/>
      </geometry>
      <material name="SoftHand/DarkGrey"/>
    </visual>
    <collision>
      <geometry>
        <mesh filename="package://soft_hand_description/meshes/knuckle_collision.stl" scale=" .001 .001 .001"/>
      </geometry>
    </collision>
  </link>
  <!-- PROXIMAL PHALANGE -->
  <joint name="soft_hand_little_inner_joint" type="revolute">
    <origin rpy="0 0 0" xyz="0.009 0 0"/>
    <parent link="soft_hand_little_knuckle_link"/>
    <child link="soft_hand_little_fake_link1"/>
    <axis xyz="0 -1 0"/>
    <limit effort="100" lower="0.0" upper="0.785398163397" velocity="100"/>
    <dynamics damping="0.0" friction="0.0"/>
  </joint>
  <link name="soft_hand_little_fake_link1">
    <inertial>
      <origin xyz="0 0 0"/>
      <mass value="0.0"/>
      <inertia ixx="0.0" ixy="0.0" ixz="0.0" iyy="0.0" iyz="0.0" izz="0.0"/>
<!--       <mass value="0.1"/>
      <inertia ixx="0.001" ixy="0.0" ixz="0.0" iyy="0.001" iyz="0.0" izz="0.001"/> -->
    </inertial>
  </link>
  <joint name="soft_hand_little_inner_joint_mimic" type="revolute">
    <origin rpy="0 0 0" xyz="0.013 0 0"/>
    <parent link="soft_hand_little_fake_link1"/>
    <child link="soft_hand_little_proximal_link"/>
    <axis xyz="0 -1 0"/>
    <limit effort="100" lower="0.0" upper="0.785398163397" velocity="100"/>
    <dynamics damping="0.0" friction="0.0"/>
  </joint>
  <link name="soft_hand_little_proximal_link">
    <inertial>
      <origin xyz="0.005074337 -4.524e-06 -0.000262953"/>
      <mass value="0.0"/>
      <inertia ixx="0.0" ixy="0.0" ixz="0.0" iyy="0.0" iyz="0.0" izz="0.0"/>
<!--       <mass value="0.05"/>
      <inertia ixx="0.00175" ixy="0.0" ixz="0.0001" iyy="0.00275" iyz="0.0" izz="0.00275"/> -->
    </inertial>
    <visual>
      <geometry>
        <mesh filename="package://soft_hand_description/meshes/phalanx.stl" scale=" .001 .001 .001"/>
      </geometry>
      <material name="SoftHand/DarkGrey"/>
    </visual>
    <collision>
      <geometry>
        <mesh filename="package://soft_hand_description/meshes/phalanx_collision.stl" scale=" .001 .001 .001"/>
      </geometry>
    </collision>
  </link>
  <!-- MIDDLE PHALANGE -->
  <joint name="soft_hand_little_middle_joint" type="revolute">
    <origin rpy="0 0 0" xyz="0.009 0 0"/>
    <parent link="soft_hand_little_proximal_link"/>
    <child link="soft_hand_little_fake_link2"/>
    <axis xyz="0 -1 0"/>
    <limit effort="100" lower="0.0" upper="0.785398163397" velocity="100"/>
    <dynamics damping="0.0" friction="0.0"/>
  </joint>
  <link name="soft_hand_little_fake_link2">
    <inertial>
      <origin xyz="0 0 0"/>
      <mass value="0.0"/>
      <inertia ixx="0.0" ixy="0.0" ixz="0.0" iyy="0.0" iyz="0.0" izz="0.0"/>
<!--       <mass value="0.1"/>
      <inertia ixx="0.001" ixy="0.0" ixz="0.0" iyy="0.001" iyz="0.0" izz="0.001"/> -->
    </inertial>
  </link>
  <joint name="soft_hand_little_middle_joint_mimic" type="revolute">
    <origin rpy="0 0 0" xyz="0.013 0 0"/>
    <parent link="soft_hand_little_fake_link2"/>
    <child link="soft_hand_little_middle_link"/>
    <axis xyz="0 -1 0"/>
    <limit effort="100" lower="0.0" upper="0.785398163397" velocity="100"/>
    <dynamics damping="0.0" friction="0.0"/>
  </joint>
  <link name="soft_hand_little_middle_link">
    <inertial>
      <origin xyz="0.005074337 -4.524e-06 -0.000262953"/>
      <mass value="0.0"/>
      <inertia ixx="0.0" ixy="0.0" ixz="0.0" iyy="0.0" iyz="0.0" izz="0.0"/>
<!--       <mass value="0.05"/>
      <inertia ixx="0.00175" ixy="0.0" ixz="0.0001" iyy="0.00275" iyz="0.0" izz="0.00275"/> -->
    </inertial>
    <visual>
      <geometry>
        <mesh filename="package://soft_hand_description/meshes/phalanx.stl" scale=" .001 .001 .001"/>
      </geometry>
      <material name="SoftHand/DarkGrey"/>
    </visual>
    <collision>
      <geometry>
        <mesh filename="package://soft_hand_description/meshes/phalanx_collision.stl" scale=" .001 .001 .001"/>
      </geometry>
    </collision>
  </link>
  <!-- DISTAL PHALANGE -->
  <joint name="soft_hand_little_outer_joint" type="revolute">
    <origin rpy="0 0 0" xyz="0.009 0 0"/>
    <parent link="soft_hand_little_middle_link"/>
    <child link="soft_hand_little_fake_link3"/>
    <axis xyz="0 -1 0"/>
    <limit effort="100" lower="0.0" upper="0.785398163397" velocity="100"/>
    <dynamics damping="0.0" friction="0.0"/>
  </joint>
  <link name="soft_hand_little_fake_link3">
    <inertial>
      <origin xyz="0 0 0"/>
      <mass value="0.0"/>
      <inertia ixx="0.0" ixy="0.0" ixz="0.0" iyy="0.0" iyz="0.0" izz="0.0"/>
<!--       <mass value="0.1"/>
      <inertia ixx="0.001" ixy="0.0" ixz="0.0" iyy="0.001" iyz="0.0" izz="0.001"/> -->
    </inertial>
  </link>
  <joint name="soft_hand_little_outer_joint_mimic" type="revolute">
    <origin rpy="0 0 0" xyz="0.013 0 0"/>
    <parent link="soft_hand_little_fake_link3"/>
    <child link="soft_hand_little_distal_link"/>
    <axis xyz="0 -1 0"/>
    <limit effort="100" lower="0.0" upper="0.785398163397" velocity="100"/>
    <dynamics damping="0.0" friction="0.0"/>
  </joint>
  <link name="soft_hand_little_distal_link">
    <inertial>
      <origin xyz="0.009849094 5.6e-07 0.000820286"/>
      <mass value="0.0"/>
      <inertia ixx="0.0" ixy="0.0" ixz="0.0" iyy="0.0" iyz="0.0" izz="0.0"/>
<!--       <mass value="0.1"/>
      <inertia ixx="0.0035" ixy="0.0" ixz="0.0002" iyy="0.008" iyz="0.0" izz="0.0076"/> -->
    </inertial>
    <visual>
      <geometry>
        <mesh filename="package://soft_hand_description/meshes/fingertip.stl" scale=" .001 .001 .001"/>
      </geometry>
      <material name="SoftHand/DarkGrey"/>
    </visual>
    <collision>
      <geometry>
        <mesh filename="package://soft_hand_description/meshes/fingertip_collision.stl" scale=" .001 .001 .001"/>
      </geometry>
    </collision>
  </link>
  <!-- work in progress -->

  
</robot>

