<robot name="cuboid_on_pin.urdf">
  <link name="base_link"/>

  <link name="cuboid">
    <contact>
      <lateral_friction value="1.0"/>
      <rolling_friction value="0.0"/>
      <contact_cfm value="0.0"/>
      <contact_erp value="1.0"/>
    </contact>
    <inertial>
      <origin rpy="0 0 0" xyz="0 0 0."/>
       <mass value="1.0"/>
       <inertia ixx="1" ixy="0" ixz="0" iyy="1" iyz="0" izz="1"/>
    </inertial>
    <visual>
      <origin rpy="0 0 0" xyz="0 0 0."/>
      <geometry>
				<box size="0.6 0.4 0.15"/>
      </geometry>
       <material name="black">
        <color rgba="0 0 0 1"/>
      </material>
    </visual>
    <collision>
      <origin rpy="0 0 0" xyz="0 0 0"/>
      <geometry>
    	 	<box size="0.6 0.4 0.15"/>
      </geometry>
    </collision>
  </link>

  <joint name="joint1" type="continuous">
    <parent link="base_link"/>
    <child link="cuboid"/>
    <origin xyz="0 0 0" rpy="0 0 0" />
    <axis xyz = "0 0 1" />
  </joint>

</robot>

