<robot name="robot">
<link name="base_link"/>

   <link name="capsuleobject">
    <visual>
      <geometry>
        <cylinder length="0.65" radius="0.30"/>
      </geometry>
      <material name="black">
        <color rgba="0. 0 0 1"/>
      </material>
      <origin rpy="0 0 0" xyz="0. 0 0"/>
    </visual>
    <collision>
      <geometry>
        <cylinder length="0.65" radius="0.30"/>
      </geometry>
      <origin rpy="0 0 0" xyz="0. 0 0"/>
    </collision>
    <inertial>
      <mass value="1"/>
      <inertia ixx="1" ixy="0.0" ixz="0.0" iyy="1" iyz="0.0" izz="1"/>
    </inertial>
  </link>

  <link name="capsuleobject2">
    <visual>
      <geometry>
        <cylinder length="0.4" radius="0.01"/>
      </geometry>
      <material name="yellow">
        <color rgba="0.5 0.5 0 1"/>
      </material>
      <origin rpy="0 1.57 0" xyz="0. 0 0.32"/>
    </visual>
    <inertial>
      <mass value="0.001"/>
      <inertia ixx="0.001" ixy="0.0" ixz="0.0" iyy="0.001" iyz="0.0" izz="0.001"/>
    </inertial>
  </link>

  <joint name="joint1" type="continuous">
    <parent link="base_link"/>
    <child link="capsuleobject"/>
    <origin xyz="0 0 0" rpy="0 0 0" />
    <axis xyz = "0 0 1" />
  </joint>

  <joint name="joint2" type="fixed">
    <parent link="capsuleobject"/>
    <child link="capsuleobject2"/>
  </joint>

</robot>